[2024-01-31T12:33:30.048+0000] {scheduler_job_runner.py:781} ERROR - Executor reports task instance <TaskInstance: hola_mundo.print_hello_task scheduled__2024-01-26T00:00:00+00:00 [queued]> finished (failed) although the task says it's queued. (Info: None) Was the task killed externally?
