[2024-02-16T08:29:04.851+0000] {scheduler_job_runner.py:781} ERROR - Executor reports task instance <TaskInstance: hola_mundo.branch_task scheduled__2024-02-01T00:00:00+00:00 [queued]> finished (failed) although the task says it's queued. (Info: None) Was the task killed externally?
