[2024-01-30T11:45:00.910+0000] {scheduler_job_runner.py:1586} WARNING - Marking task instance <TaskInstance: example_bash_operator.also_run_this manual__2024-01-30T11:29:55+00:00 [queued]> stuck in queued as failed. If the task instance has available retries, it will be retried.
[2024-01-30T11:45:02.756+0000] {scheduler_job_runner.py:781} ERROR - Executor reports task instance <TaskInstance: example_bash_operator.also_run_this manual__2024-01-30T11:29:55+00:00 [queued]> finished (failed) although the task says it's queued. (Info: None) Was the task killed externally?
