[2024-02-26T08:45:42.711+0000] {scheduler_job_runner.py:1586} WARNING - Marking task instance <TaskInstance: hola_mundo.branch_b scheduled__2024-02-13T00:00:00+00:00 [queued]> stuck in queued as failed. If the task instance has available retries, it will be retried.
[2024-02-26T08:45:44.075+0000] {scheduler_job_runner.py:781} ERROR - Executor reports task instance <TaskInstance: hola_mundo.branch_b scheduled__2024-02-13T00:00:00+00:00 [queued]> finished (failed) although the task says it's queued. (Info: None) Was the task killed externally?
