[2024-01-30T11:32:02.748+0000] {scheduler_job_runner.py:781} ERROR - Executor reports task instance <TaskInstance: example_bash_operator.also_run_this scheduled__2024-01-29T00:00:00+00:00 [queued]> finished (failed) although the task says it's queued. (Info: None) Was the task killed externally?
