[2024-02-26T08:32:46.320+0000] {scheduler_job_runner.py:1586} WARNING - Marking task instance <TaskInstance: hola_mundo.print_hello_task scheduled__2024-02-15T00:00:00+00:00 [queued]> stuck in queued as failed. If the task instance has available retries, it will be retried.
[2024-02-26T08:33:38.141+0000] {scheduler_job_runner.py:781} ERROR - Executor reports task instance <TaskInstance: hola_mundo.print_hello_task scheduled__2024-02-15T00:00:00+00:00 [queued]> finished (failed) although the task says it's queued. (Info: None) Was the task killed externally?
