[2024-03-04T12:02:03.707+0000] {processor.py:161} INFO - Started process (PID=25555) to work on /opt/airflow/dags/generarUsuarios.py
[2024-03-04T12:02:03.710+0000] {processor.py:830} INFO - Processing file /opt/airflow/dags/generarUsuarios.py for tasks to queue
[2024-03-04T12:02:03.715+0000] {logging_mixin.py:188} INFO - [2024-03-04T12:02:03.714+0000] {dagbag.py:538} INFO - Filling up the DagBag from /opt/airflow/dags/generarUsuarios.py
[2024-03-04T12:02:03.739+0000] {logging_mixin.py:188} INFO - [2024-03-04T12:02:03.725+0000] {dagbag.py:348} ERROR - Failed to import: /opt/airflow/dags/generarUsuarios.py
Traceback (most recent call last):
  File "/home/airflow/.local/lib/python3.8/site-packages/airflow/models/dagbag.py", line 344, in parse
    loader.exec_module(new_module)
  File "<frozen importlib._bootstrap_external>", line 843, in exec_module
  File "<frozen importlib._bootstrap>", line 219, in _call_with_frames_removed
  File "/opt/airflow/dags/generarUsuarios.py", line 13, in <module>
    'retry_delay': timedelta(minutes=1),
NameError: name 'timedelta' is not defined
[2024-03-04T12:02:03.741+0000] {processor.py:842} WARNING - No viable dags retrieved from /opt/airflow/dags/generarUsuarios.py
[2024-03-04T12:02:03.814+0000] {processor.py:183} INFO - Processing /opt/airflow/dags/generarUsuarios.py took 0.118 seconds
[2024-03-04T12:02:33.895+0000] {processor.py:161} INFO - Started process (PID=25613) to work on /opt/airflow/dags/generarUsuarios.py
[2024-03-04T12:02:33.897+0000] {processor.py:830} INFO - Processing file /opt/airflow/dags/generarUsuarios.py for tasks to queue
[2024-03-04T12:02:33.907+0000] {logging_mixin.py:188} INFO - [2024-03-04T12:02:33.901+0000] {dagbag.py:538} INFO - Filling up the DagBag from /opt/airflow/dags/generarUsuarios.py
[2024-03-04T12:02:33.918+0000] {logging_mixin.py:188} INFO - [2024-03-04T12:02:33.915+0000] {dagbag.py:348} ERROR - Failed to import: /opt/airflow/dags/generarUsuarios.py
Traceback (most recent call last):
  File "/home/airflow/.local/lib/python3.8/site-packages/airflow/models/dagbag.py", line 344, in parse
    loader.exec_module(new_module)
  File "<frozen importlib._bootstrap_external>", line 843, in exec_module
  File "<frozen importlib._bootstrap>", line 219, in _call_with_frames_removed
  File "/opt/airflow/dags/generarUsuarios.py", line 13, in <module>
    'retry_delay': timedelta(minutes=1),
NameError: name 'timedelta' is not defined
[2024-03-04T12:02:33.919+0000] {processor.py:842} WARNING - No viable dags retrieved from /opt/airflow/dags/generarUsuarios.py
[2024-03-04T12:02:33.976+0000] {processor.py:183} INFO - Processing /opt/airflow/dags/generarUsuarios.py took 0.092 seconds
[2024-03-04T12:03:04.149+0000] {processor.py:161} INFO - Started process (PID=25671) to work on /opt/airflow/dags/generarUsuarios.py
[2024-03-04T12:03:04.153+0000] {processor.py:830} INFO - Processing file /opt/airflow/dags/generarUsuarios.py for tasks to queue
[2024-03-04T12:03:04.161+0000] {logging_mixin.py:188} INFO - [2024-03-04T12:03:04.158+0000] {dagbag.py:538} INFO - Filling up the DagBag from /opt/airflow/dags/generarUsuarios.py
[2024-03-04T12:03:04.171+0000] {logging_mixin.py:188} INFO - [2024-03-04T12:03:04.168+0000] {dagbag.py:348} ERROR - Failed to import: /opt/airflow/dags/generarUsuarios.py
Traceback (most recent call last):
  File "/home/airflow/.local/lib/python3.8/site-packages/airflow/models/dagbag.py", line 344, in parse
    loader.exec_module(new_module)
  File "<frozen importlib._bootstrap_external>", line 843, in exec_module
  File "<frozen importlib._bootstrap>", line 219, in _call_with_frames_removed
  File "/opt/airflow/dags/generarUsuarios.py", line 13, in <module>
    'retry_delay': timedelta(minutes=1),
NameError: name 'timedelta' is not defined
[2024-03-04T12:03:04.172+0000] {processor.py:842} WARNING - No viable dags retrieved from /opt/airflow/dags/generarUsuarios.py
[2024-03-04T12:03:04.250+0000] {processor.py:183} INFO - Processing /opt/airflow/dags/generarUsuarios.py took 0.110 seconds
[2024-03-04T12:03:34.864+0000] {processor.py:161} INFO - Started process (PID=25729) to work on /opt/airflow/dags/generarUsuarios.py
[2024-03-04T12:03:34.866+0000] {processor.py:830} INFO - Processing file /opt/airflow/dags/generarUsuarios.py for tasks to queue
[2024-03-04T12:03:34.883+0000] {logging_mixin.py:188} INFO - [2024-03-04T12:03:34.881+0000] {dagbag.py:538} INFO - Filling up the DagBag from /opt/airflow/dags/generarUsuarios.py
[2024-03-04T12:03:34.906+0000] {logging_mixin.py:188} INFO - [2024-03-04T12:03:34.902+0000] {dagbag.py:348} ERROR - Failed to import: /opt/airflow/dags/generarUsuarios.py
Traceback (most recent call last):
  File "/home/airflow/.local/lib/python3.8/site-packages/airflow/models/dagbag.py", line 344, in parse
    loader.exec_module(new_module)
  File "<frozen importlib._bootstrap_external>", line 843, in exec_module
  File "<frozen importlib._bootstrap>", line 219, in _call_with_frames_removed
  File "/opt/airflow/dags/generarUsuarios.py", line 18, in <module>
    'retry_delay': timedelta(minutes=1),
NameError: name 'timedelta' is not defined
[2024-03-04T12:03:34.914+0000] {processor.py:842} WARNING - No viable dags retrieved from /opt/airflow/dags/generarUsuarios.py
[2024-03-04T12:03:35.020+0000] {processor.py:183} INFO - Processing /opt/airflow/dags/generarUsuarios.py took 0.189 seconds
[2024-03-04T12:04:05.493+0000] {processor.py:161} INFO - Started process (PID=25787) to work on /opt/airflow/dags/generarUsuarios.py
[2024-03-04T12:04:05.495+0000] {processor.py:830} INFO - Processing file /opt/airflow/dags/generarUsuarios.py for tasks to queue
[2024-03-04T12:04:05.498+0000] {logging_mixin.py:188} INFO - [2024-03-04T12:04:05.498+0000] {dagbag.py:538} INFO - Filling up the DagBag from /opt/airflow/dags/generarUsuarios.py
[2024-03-04T12:04:05.504+0000] {logging_mixin.py:188} INFO - [2024-03-04T12:04:05.503+0000] {dagbag.py:348} ERROR - Failed to import: /opt/airflow/dags/generarUsuarios.py
Traceback (most recent call last):
  File "/home/airflow/.local/lib/python3.8/site-packages/airflow/models/dagbag.py", line 344, in parse
    loader.exec_module(new_module)
  File "<frozen importlib._bootstrap_external>", line 843, in exec_module
  File "<frozen importlib._bootstrap>", line 219, in _call_with_frames_removed
  File "/opt/airflow/dags/generarUsuarios.py", line 18, in <module>
    'retry_delay': timedelta(minutes=1),
NameError: name 'timedelta' is not defined
[2024-03-04T12:04:05.505+0000] {processor.py:842} WARNING - No viable dags retrieved from /opt/airflow/dags/generarUsuarios.py
[2024-03-04T12:04:05.542+0000] {processor.py:183} INFO - Processing /opt/airflow/dags/generarUsuarios.py took 0.064 seconds
[2024-03-04T12:04:35.698+0000] {processor.py:161} INFO - Started process (PID=25846) to work on /opt/airflow/dags/generarUsuarios.py
[2024-03-04T12:04:35.707+0000] {processor.py:830} INFO - Processing file /opt/airflow/dags/generarUsuarios.py for tasks to queue
[2024-03-04T12:04:35.711+0000] {logging_mixin.py:188} INFO - [2024-03-04T12:04:35.710+0000] {dagbag.py:538} INFO - Filling up the DagBag from /opt/airflow/dags/generarUsuarios.py
[2024-03-04T12:04:35.720+0000] {logging_mixin.py:188} INFO - [2024-03-04T12:04:35.717+0000] {dagbag.py:348} ERROR - Failed to import: /opt/airflow/dags/generarUsuarios.py
Traceback (most recent call last):
  File "/home/airflow/.local/lib/python3.8/site-packages/airflow/models/dagbag.py", line 344, in parse
    loader.exec_module(new_module)
  File "<frozen importlib._bootstrap_external>", line 843, in exec_module
  File "<frozen importlib._bootstrap>", line 219, in _call_with_frames_removed
  File "/opt/airflow/dags/generarUsuarios.py", line 18, in <module>
    'retry_delay': timedelta(minutes=1),
NameError: name 'timedelta' is not defined
[2024-03-04T12:04:35.721+0000] {processor.py:842} WARNING - No viable dags retrieved from /opt/airflow/dags/generarUsuarios.py
[2024-03-04T12:04:35.773+0000] {processor.py:183} INFO - Processing /opt/airflow/dags/generarUsuarios.py took 0.092 seconds
[2024-03-04T12:05:06.025+0000] {processor.py:161} INFO - Started process (PID=25902) to work on /opt/airflow/dags/generarUsuarios.py
[2024-03-04T12:05:06.073+0000] {processor.py:830} INFO - Processing file /opt/airflow/dags/generarUsuarios.py for tasks to queue
[2024-03-04T12:05:06.089+0000] {logging_mixin.py:188} INFO - [2024-03-04T12:05:06.088+0000] {dagbag.py:538} INFO - Filling up the DagBag from /opt/airflow/dags/generarUsuarios.py
[2024-03-04T12:05:06.111+0000] {logging_mixin.py:188} INFO - [2024-03-04T12:05:06.097+0000] {dagbag.py:348} ERROR - Failed to import: /opt/airflow/dags/generarUsuarios.py
Traceback (most recent call last):
  File "/home/airflow/.local/lib/python3.8/site-packages/airflow/models/dagbag.py", line 344, in parse
    loader.exec_module(new_module)
  File "<frozen importlib._bootstrap_external>", line 843, in exec_module
  File "<frozen importlib._bootstrap>", line 219, in _call_with_frames_removed
  File "/opt/airflow/dags/generarUsuarios.py", line 18, in <module>
    'retry_delay': timedelta(minutes=1),
NameError: name 'timedelta' is not defined
[2024-03-04T12:05:06.112+0000] {processor.py:842} WARNING - No viable dags retrieved from /opt/airflow/dags/generarUsuarios.py
[2024-03-04T12:05:06.196+0000] {processor.py:183} INFO - Processing /opt/airflow/dags/generarUsuarios.py took 0.192 seconds
[2024-03-04T12:05:36.631+0000] {processor.py:161} INFO - Started process (PID=25960) to work on /opt/airflow/dags/generarUsuarios.py
[2024-03-04T12:05:36.635+0000] {processor.py:830} INFO - Processing file /opt/airflow/dags/generarUsuarios.py for tasks to queue
[2024-03-04T12:05:36.640+0000] {logging_mixin.py:188} INFO - [2024-03-04T12:05:36.639+0000] {dagbag.py:538} INFO - Filling up the DagBag from /opt/airflow/dags/generarUsuarios.py
[2024-03-04T12:05:36.654+0000] {logging_mixin.py:188} INFO - [2024-03-04T12:05:36.650+0000] {dagbag.py:348} ERROR - Failed to import: /opt/airflow/dags/generarUsuarios.py
Traceback (most recent call last):
  File "/home/airflow/.local/lib/python3.8/site-packages/airflow/models/dagbag.py", line 344, in parse
    loader.exec_module(new_module)
  File "<frozen importlib._bootstrap_external>", line 843, in exec_module
  File "<frozen importlib._bootstrap>", line 219, in _call_with_frames_removed
  File "/opt/airflow/dags/generarUsuarios.py", line 18, in <module>
    'retry_delay': timedelta(minutes=1),
NameError: name 'timedelta' is not defined
[2024-03-04T12:05:36.655+0000] {processor.py:842} WARNING - No viable dags retrieved from /opt/airflow/dags/generarUsuarios.py
[2024-03-04T12:05:36.758+0000] {processor.py:183} INFO - Processing /opt/airflow/dags/generarUsuarios.py took 0.140 seconds
[2024-03-04T12:06:06.881+0000] {processor.py:161} INFO - Started process (PID=26018) to work on /opt/airflow/dags/generarUsuarios.py
[2024-03-04T12:06:06.884+0000] {processor.py:830} INFO - Processing file /opt/airflow/dags/generarUsuarios.py for tasks to queue
[2024-03-04T12:06:06.899+0000] {logging_mixin.py:188} INFO - [2024-03-04T12:06:06.898+0000] {dagbag.py:538} INFO - Filling up the DagBag from /opt/airflow/dags/generarUsuarios.py
[2024-03-04T12:06:06.929+0000] {logging_mixin.py:188} INFO - [2024-03-04T12:06:06.916+0000] {dagbag.py:348} ERROR - Failed to import: /opt/airflow/dags/generarUsuarios.py
Traceback (most recent call last):
  File "/home/airflow/.local/lib/python3.8/site-packages/airflow/models/dagbag.py", line 344, in parse
    loader.exec_module(new_module)
  File "<frozen importlib._bootstrap_external>", line 843, in exec_module
  File "<frozen importlib._bootstrap>", line 219, in _call_with_frames_removed
  File "/opt/airflow/dags/generarUsuarios.py", line 18, in <module>
    'retry_delay': timedelta(minutes=1),
NameError: name 'timedelta' is not defined
[2024-03-04T12:06:06.930+0000] {processor.py:842} WARNING - No viable dags retrieved from /opt/airflow/dags/generarUsuarios.py
[2024-03-04T12:06:07.038+0000] {processor.py:183} INFO - Processing /opt/airflow/dags/generarUsuarios.py took 0.185 seconds
[2024-03-04T12:06:37.203+0000] {processor.py:161} INFO - Started process (PID=26075) to work on /opt/airflow/dags/generarUsuarios.py
[2024-03-04T12:06:37.205+0000] {processor.py:830} INFO - Processing file /opt/airflow/dags/generarUsuarios.py for tasks to queue
[2024-03-04T12:06:37.210+0000] {logging_mixin.py:188} INFO - [2024-03-04T12:06:37.209+0000] {dagbag.py:538} INFO - Filling up the DagBag from /opt/airflow/dags/generarUsuarios.py
[2024-03-04T12:06:37.218+0000] {logging_mixin.py:188} INFO - [2024-03-04T12:06:37.215+0000] {dagbag.py:348} ERROR - Failed to import: /opt/airflow/dags/generarUsuarios.py
Traceback (most recent call last):
  File "/home/airflow/.local/lib/python3.8/site-packages/airflow/models/dagbag.py", line 344, in parse
    loader.exec_module(new_module)
  File "<frozen importlib._bootstrap_external>", line 843, in exec_module
  File "<frozen importlib._bootstrap>", line 219, in _call_with_frames_removed
  File "/opt/airflow/dags/generarUsuarios.py", line 18, in <module>
    'retry_delay': timedelta(minutes=1),
NameError: name 'timedelta' is not defined
[2024-03-04T12:06:37.219+0000] {processor.py:842} WARNING - No viable dags retrieved from /opt/airflow/dags/generarUsuarios.py
[2024-03-04T12:06:37.313+0000] {processor.py:183} INFO - Processing /opt/airflow/dags/generarUsuarios.py took 0.118 seconds
[2024-03-04T12:07:07.473+0000] {processor.py:161} INFO - Started process (PID=26133) to work on /opt/airflow/dags/generarUsuarios.py
[2024-03-04T12:07:07.474+0000] {processor.py:830} INFO - Processing file /opt/airflow/dags/generarUsuarios.py for tasks to queue
[2024-03-04T12:07:07.479+0000] {logging_mixin.py:188} INFO - [2024-03-04T12:07:07.478+0000] {dagbag.py:538} INFO - Filling up the DagBag from /opt/airflow/dags/generarUsuarios.py
[2024-03-04T12:07:07.487+0000] {logging_mixin.py:188} INFO - [2024-03-04T12:07:07.484+0000] {dagbag.py:348} ERROR - Failed to import: /opt/airflow/dags/generarUsuarios.py
Traceback (most recent call last):
  File "/home/airflow/.local/lib/python3.8/site-packages/airflow/models/dagbag.py", line 344, in parse
    loader.exec_module(new_module)
  File "<frozen importlib._bootstrap_external>", line 843, in exec_module
  File "<frozen importlib._bootstrap>", line 219, in _call_with_frames_removed
  File "/opt/airflow/dags/generarUsuarios.py", line 18, in <module>
    'retry_delay': timedelta(minutes=1),
NameError: name 'timedelta' is not defined
[2024-03-04T12:07:07.488+0000] {processor.py:842} WARNING - No viable dags retrieved from /opt/airflow/dags/generarUsuarios.py
[2024-03-04T12:07:07.524+0000] {processor.py:183} INFO - Processing /opt/airflow/dags/generarUsuarios.py took 0.058 seconds
[2024-03-04T12:07:37.806+0000] {processor.py:161} INFO - Started process (PID=26191) to work on /opt/airflow/dags/generarUsuarios.py
[2024-03-04T12:07:37.809+0000] {processor.py:830} INFO - Processing file /opt/airflow/dags/generarUsuarios.py for tasks to queue
[2024-03-04T12:07:37.814+0000] {logging_mixin.py:188} INFO - [2024-03-04T12:07:37.813+0000] {dagbag.py:538} INFO - Filling up the DagBag from /opt/airflow/dags/generarUsuarios.py
[2024-03-04T12:07:37.820+0000] {logging_mixin.py:188} INFO - [2024-03-04T12:07:37.819+0000] {dagbag.py:348} ERROR - Failed to import: /opt/airflow/dags/generarUsuarios.py
Traceback (most recent call last):
  File "/home/airflow/.local/lib/python3.8/site-packages/airflow/models/dagbag.py", line 344, in parse
    loader.exec_module(new_module)
  File "<frozen importlib._bootstrap_external>", line 843, in exec_module
  File "<frozen importlib._bootstrap>", line 219, in _call_with_frames_removed
  File "/opt/airflow/dags/generarUsuarios.py", line 18, in <module>
    'retry_delay': timedelta(minutes=1),
NameError: name 'timedelta' is not defined
[2024-03-04T12:07:37.821+0000] {processor.py:842} WARNING - No viable dags retrieved from /opt/airflow/dags/generarUsuarios.py
[2024-03-04T12:07:37.862+0000] {processor.py:183} INFO - Processing /opt/airflow/dags/generarUsuarios.py took 0.063 seconds
[2024-03-04T12:08:08.372+0000] {processor.py:161} INFO - Started process (PID=26248) to work on /opt/airflow/dags/generarUsuarios.py
[2024-03-04T12:08:08.376+0000] {processor.py:830} INFO - Processing file /opt/airflow/dags/generarUsuarios.py for tasks to queue
[2024-03-04T12:08:08.380+0000] {logging_mixin.py:188} INFO - [2024-03-04T12:08:08.379+0000] {dagbag.py:538} INFO - Filling up the DagBag from /opt/airflow/dags/generarUsuarios.py
[2024-03-04T12:08:08.387+0000] {logging_mixin.py:188} INFO - [2024-03-04T12:08:08.385+0000] {dagbag.py:348} ERROR - Failed to import: /opt/airflow/dags/generarUsuarios.py
Traceback (most recent call last):
  File "/home/airflow/.local/lib/python3.8/site-packages/airflow/models/dagbag.py", line 344, in parse
    loader.exec_module(new_module)
  File "<frozen importlib._bootstrap_external>", line 843, in exec_module
  File "<frozen importlib._bootstrap>", line 219, in _call_with_frames_removed
  File "/opt/airflow/dags/generarUsuarios.py", line 18, in <module>
    'retry_delay': timedelta(minutes=1),
NameError: name 'timedelta' is not defined
[2024-03-04T12:08:08.387+0000] {processor.py:842} WARNING - No viable dags retrieved from /opt/airflow/dags/generarUsuarios.py
[2024-03-04T12:08:08.438+0000] {processor.py:183} INFO - Processing /opt/airflow/dags/generarUsuarios.py took 0.074 seconds
[2024-03-04T12:08:38.746+0000] {processor.py:161} INFO - Started process (PID=26306) to work on /opt/airflow/dags/generarUsuarios.py
[2024-03-04T12:08:38.749+0000] {processor.py:830} INFO - Processing file /opt/airflow/dags/generarUsuarios.py for tasks to queue
[2024-03-04T12:08:38.754+0000] {logging_mixin.py:188} INFO - [2024-03-04T12:08:38.753+0000] {dagbag.py:538} INFO - Filling up the DagBag from /opt/airflow/dags/generarUsuarios.py
[2024-03-04T12:08:38.760+0000] {logging_mixin.py:188} INFO - [2024-03-04T12:08:38.759+0000] {dagbag.py:348} ERROR - Failed to import: /opt/airflow/dags/generarUsuarios.py
Traceback (most recent call last):
  File "/home/airflow/.local/lib/python3.8/site-packages/airflow/models/dagbag.py", line 344, in parse
    loader.exec_module(new_module)
  File "<frozen importlib._bootstrap_external>", line 843, in exec_module
  File "<frozen importlib._bootstrap>", line 219, in _call_with_frames_removed
  File "/opt/airflow/dags/generarUsuarios.py", line 18, in <module>
    'retry_delay': timedelta(minutes=1),
NameError: name 'timedelta' is not defined
[2024-03-04T12:08:38.761+0000] {processor.py:842} WARNING - No viable dags retrieved from /opt/airflow/dags/generarUsuarios.py
[2024-03-04T12:08:38.833+0000] {processor.py:183} INFO - Processing /opt/airflow/dags/generarUsuarios.py took 0.097 seconds
[2024-03-04T12:09:09.662+0000] {processor.py:161} INFO - Started process (PID=26364) to work on /opt/airflow/dags/generarUsuarios.py
[2024-03-04T12:09:09.676+0000] {processor.py:830} INFO - Processing file /opt/airflow/dags/generarUsuarios.py for tasks to queue
[2024-03-04T12:09:09.684+0000] {logging_mixin.py:188} INFO - [2024-03-04T12:09:09.682+0000] {dagbag.py:538} INFO - Filling up the DagBag from /opt/airflow/dags/generarUsuarios.py
[2024-03-04T12:09:09.695+0000] {logging_mixin.py:188} INFO - [2024-03-04T12:09:09.690+0000] {dagbag.py:348} ERROR - Failed to import: /opt/airflow/dags/generarUsuarios.py
Traceback (most recent call last):
  File "/home/airflow/.local/lib/python3.8/site-packages/airflow/models/dagbag.py", line 344, in parse
    loader.exec_module(new_module)
  File "<frozen importlib._bootstrap_external>", line 843, in exec_module
  File "<frozen importlib._bootstrap>", line 219, in _call_with_frames_removed
  File "/opt/airflow/dags/generarUsuarios.py", line 18, in <module>
    'retry_delay': timedelta(minutes=1),
NameError: name 'timedelta' is not defined
[2024-03-04T12:09:09.696+0000] {processor.py:842} WARNING - No viable dags retrieved from /opt/airflow/dags/generarUsuarios.py
[2024-03-04T12:09:09.758+0000] {processor.py:183} INFO - Processing /opt/airflow/dags/generarUsuarios.py took 0.105 seconds
[2024-03-04T12:09:40.193+0000] {processor.py:161} INFO - Started process (PID=26422) to work on /opt/airflow/dags/generarUsuarios.py
[2024-03-04T12:09:40.195+0000] {processor.py:830} INFO - Processing file /opt/airflow/dags/generarUsuarios.py for tasks to queue
[2024-03-04T12:09:40.200+0000] {logging_mixin.py:188} INFO - [2024-03-04T12:09:40.199+0000] {dagbag.py:538} INFO - Filling up the DagBag from /opt/airflow/dags/generarUsuarios.py
[2024-03-04T12:09:40.208+0000] {logging_mixin.py:188} INFO - [2024-03-04T12:09:40.205+0000] {dagbag.py:348} ERROR - Failed to import: /opt/airflow/dags/generarUsuarios.py
Traceback (most recent call last):
  File "/home/airflow/.local/lib/python3.8/site-packages/airflow/models/dagbag.py", line 344, in parse
    loader.exec_module(new_module)
  File "<frozen importlib._bootstrap_external>", line 843, in exec_module
  File "<frozen importlib._bootstrap>", line 219, in _call_with_frames_removed
  File "/opt/airflow/dags/generarUsuarios.py", line 18, in <module>
    'retry_delay': timedelta(minutes=1),
NameError: name 'timedelta' is not defined
[2024-03-04T12:09:40.209+0000] {processor.py:842} WARNING - No viable dags retrieved from /opt/airflow/dags/generarUsuarios.py
[2024-03-04T12:09:40.260+0000] {processor.py:183} INFO - Processing /opt/airflow/dags/generarUsuarios.py took 0.074 seconds
[2024-03-04T12:10:10.497+0000] {processor.py:161} INFO - Started process (PID=26480) to work on /opt/airflow/dags/generarUsuarios.py
[2024-03-04T12:10:10.499+0000] {processor.py:830} INFO - Processing file /opt/airflow/dags/generarUsuarios.py for tasks to queue
[2024-03-04T12:10:10.503+0000] {logging_mixin.py:188} INFO - [2024-03-04T12:10:10.503+0000] {dagbag.py:538} INFO - Filling up the DagBag from /opt/airflow/dags/generarUsuarios.py
[2024-03-04T12:10:10.510+0000] {logging_mixin.py:188} INFO - [2024-03-04T12:10:10.508+0000] {dagbag.py:348} ERROR - Failed to import: /opt/airflow/dags/generarUsuarios.py
Traceback (most recent call last):
  File "/home/airflow/.local/lib/python3.8/site-packages/airflow/models/dagbag.py", line 344, in parse
    loader.exec_module(new_module)
  File "<frozen importlib._bootstrap_external>", line 843, in exec_module
  File "<frozen importlib._bootstrap>", line 219, in _call_with_frames_removed
  File "/opt/airflow/dags/generarUsuarios.py", line 18, in <module>
    'retry_delay': timedelta(minutes=1),
NameError: name 'timedelta' is not defined
[2024-03-04T12:10:10.510+0000] {processor.py:842} WARNING - No viable dags retrieved from /opt/airflow/dags/generarUsuarios.py
[2024-03-04T12:10:10.550+0000] {processor.py:183} INFO - Processing /opt/airflow/dags/generarUsuarios.py took 0.063 seconds
[2024-03-04T12:10:41.260+0000] {processor.py:161} INFO - Started process (PID=26538) to work on /opt/airflow/dags/generarUsuarios.py
[2024-03-04T12:10:41.263+0000] {processor.py:830} INFO - Processing file /opt/airflow/dags/generarUsuarios.py for tasks to queue
[2024-03-04T12:10:41.267+0000] {logging_mixin.py:188} INFO - [2024-03-04T12:10:41.267+0000] {dagbag.py:538} INFO - Filling up the DagBag from /opt/airflow/dags/generarUsuarios.py
[2024-03-04T12:10:41.274+0000] {logging_mixin.py:188} INFO - [2024-03-04T12:10:41.273+0000] {dagbag.py:348} ERROR - Failed to import: /opt/airflow/dags/generarUsuarios.py
Traceback (most recent call last):
  File "/home/airflow/.local/lib/python3.8/site-packages/airflow/models/dagbag.py", line 344, in parse
    loader.exec_module(new_module)
  File "<frozen importlib._bootstrap_external>", line 843, in exec_module
  File "<frozen importlib._bootstrap>", line 219, in _call_with_frames_removed
  File "/opt/airflow/dags/generarUsuarios.py", line 18, in <module>
    'retry_delay': timedelta(minutes=1),
NameError: name 'timedelta' is not defined
[2024-03-04T12:10:41.275+0000] {processor.py:842} WARNING - No viable dags retrieved from /opt/airflow/dags/generarUsuarios.py
[2024-03-04T12:10:41.311+0000] {processor.py:183} INFO - Processing /opt/airflow/dags/generarUsuarios.py took 0.058 seconds
[2024-03-04T12:11:11.845+0000] {processor.py:161} INFO - Started process (PID=26596) to work on /opt/airflow/dags/generarUsuarios.py
[2024-03-04T12:11:11.847+0000] {processor.py:830} INFO - Processing file /opt/airflow/dags/generarUsuarios.py for tasks to queue
[2024-03-04T12:11:11.851+0000] {logging_mixin.py:188} INFO - [2024-03-04T12:11:11.850+0000] {dagbag.py:538} INFO - Filling up the DagBag from /opt/airflow/dags/generarUsuarios.py
[2024-03-04T12:11:11.858+0000] {logging_mixin.py:188} INFO - [2024-03-04T12:11:11.856+0000] {dagbag.py:348} ERROR - Failed to import: /opt/airflow/dags/generarUsuarios.py
Traceback (most recent call last):
  File "/home/airflow/.local/lib/python3.8/site-packages/airflow/models/dagbag.py", line 344, in parse
    loader.exec_module(new_module)
  File "<frozen importlib._bootstrap_external>", line 843, in exec_module
  File "<frozen importlib._bootstrap>", line 219, in _call_with_frames_removed
  File "/opt/airflow/dags/generarUsuarios.py", line 18, in <module>
    'retry_delay': timedelta(minutes=1),
NameError: name 'timedelta' is not defined
[2024-03-04T12:11:11.859+0000] {processor.py:842} WARNING - No viable dags retrieved from /opt/airflow/dags/generarUsuarios.py
[2024-03-04T12:11:11.904+0000] {processor.py:183} INFO - Processing /opt/airflow/dags/generarUsuarios.py took 0.068 seconds
[2024-03-04T12:11:42.497+0000] {processor.py:161} INFO - Started process (PID=26655) to work on /opt/airflow/dags/generarUsuarios.py
[2024-03-04T12:11:42.507+0000] {processor.py:830} INFO - Processing file /opt/airflow/dags/generarUsuarios.py for tasks to queue
[2024-03-04T12:11:42.517+0000] {logging_mixin.py:188} INFO - [2024-03-04T12:11:42.516+0000] {dagbag.py:538} INFO - Filling up the DagBag from /opt/airflow/dags/generarUsuarios.py
[2024-03-04T12:11:42.525+0000] {logging_mixin.py:188} INFO - [2024-03-04T12:11:42.523+0000] {dagbag.py:348} ERROR - Failed to import: /opt/airflow/dags/generarUsuarios.py
Traceback (most recent call last):
  File "/home/airflow/.local/lib/python3.8/site-packages/airflow/models/dagbag.py", line 344, in parse
    loader.exec_module(new_module)
  File "<frozen importlib._bootstrap_external>", line 843, in exec_module
  File "<frozen importlib._bootstrap>", line 219, in _call_with_frames_removed
  File "/opt/airflow/dags/generarUsuarios.py", line 18, in <module>
    'retry_delay': timedelta(minutes=1),
NameError: name 'timedelta' is not defined
[2024-03-04T12:11:42.527+0000] {processor.py:842} WARNING - No viable dags retrieved from /opt/airflow/dags/generarUsuarios.py
[2024-03-04T12:11:42.625+0000] {processor.py:183} INFO - Processing /opt/airflow/dags/generarUsuarios.py took 0.151 seconds
[2024-03-04T12:12:13.054+0000] {processor.py:161} INFO - Started process (PID=26715) to work on /opt/airflow/dags/generarUsuarios.py
[2024-03-04T12:12:13.056+0000] {processor.py:830} INFO - Processing file /opt/airflow/dags/generarUsuarios.py for tasks to queue
[2024-03-04T12:12:13.059+0000] {logging_mixin.py:188} INFO - [2024-03-04T12:12:13.059+0000] {dagbag.py:538} INFO - Filling up the DagBag from /opt/airflow/dags/generarUsuarios.py
[2024-03-04T12:12:13.065+0000] {logging_mixin.py:188} INFO - [2024-03-04T12:12:13.063+0000] {dagbag.py:348} ERROR - Failed to import: /opt/airflow/dags/generarUsuarios.py
Traceback (most recent call last):
  File "/home/airflow/.local/lib/python3.8/site-packages/airflow/models/dagbag.py", line 344, in parse
    loader.exec_module(new_module)
  File "<frozen importlib._bootstrap_external>", line 843, in exec_module
  File "<frozen importlib._bootstrap>", line 219, in _call_with_frames_removed
  File "/opt/airflow/dags/generarUsuarios.py", line 18, in <module>
    'retry_delay': timedelta(minutes=1),
NameError: name 'timedelta' is not defined
[2024-03-04T12:12:13.065+0000] {processor.py:842} WARNING - No viable dags retrieved from /opt/airflow/dags/generarUsuarios.py
[2024-03-04T12:12:13.101+0000] {processor.py:183} INFO - Processing /opt/airflow/dags/generarUsuarios.py took 0.055 seconds
[2024-03-04T12:12:43.302+0000] {processor.py:161} INFO - Started process (PID=26774) to work on /opt/airflow/dags/generarUsuarios.py
[2024-03-04T12:12:43.318+0000] {processor.py:830} INFO - Processing file /opt/airflow/dags/generarUsuarios.py for tasks to queue
[2024-03-04T12:12:43.382+0000] {logging_mixin.py:188} INFO - [2024-03-04T12:12:43.380+0000] {dagbag.py:538} INFO - Filling up the DagBag from /opt/airflow/dags/generarUsuarios.py
[2024-03-04T12:12:43.427+0000] {logging_mixin.py:188} INFO - [2024-03-04T12:12:43.413+0000] {dagbag.py:348} ERROR - Failed to import: /opt/airflow/dags/generarUsuarios.py
Traceback (most recent call last):
  File "/home/airflow/.local/lib/python3.8/site-packages/airflow/models/dagbag.py", line 344, in parse
    loader.exec_module(new_module)
  File "<frozen importlib._bootstrap_external>", line 843, in exec_module
  File "<frozen importlib._bootstrap>", line 219, in _call_with_frames_removed
  File "/opt/airflow/dags/generarUsuarios.py", line 18, in <module>
    'retry_delay': timedelta(minutes=1),
NameError: name 'timedelta' is not defined
[2024-03-04T12:12:43.428+0000] {processor.py:842} WARNING - No viable dags retrieved from /opt/airflow/dags/generarUsuarios.py
[2024-03-04T12:12:43.594+0000] {processor.py:183} INFO - Processing /opt/airflow/dags/generarUsuarios.py took 0.354 seconds
[2024-03-04T12:13:14.452+0000] {processor.py:161} INFO - Started process (PID=26832) to work on /opt/airflow/dags/generarUsuarios.py
[2024-03-04T12:13:14.466+0000] {processor.py:830} INFO - Processing file /opt/airflow/dags/generarUsuarios.py for tasks to queue
[2024-03-04T12:13:14.471+0000] {logging_mixin.py:188} INFO - [2024-03-04T12:13:14.470+0000] {dagbag.py:538} INFO - Filling up the DagBag from /opt/airflow/dags/generarUsuarios.py
[2024-03-04T12:13:14.478+0000] {logging_mixin.py:188} INFO - [2024-03-04T12:13:14.476+0000] {dagbag.py:348} ERROR - Failed to import: /opt/airflow/dags/generarUsuarios.py
Traceback (most recent call last):
  File "/home/airflow/.local/lib/python3.8/site-packages/airflow/models/dagbag.py", line 344, in parse
    loader.exec_module(new_module)
  File "<frozen importlib._bootstrap_external>", line 843, in exec_module
  File "<frozen importlib._bootstrap>", line 219, in _call_with_frames_removed
  File "/opt/airflow/dags/generarUsuarios.py", line 18, in <module>
    'retry_delay': timedelta(minutes=1),
NameError: name 'timedelta' is not defined
[2024-03-04T12:13:14.479+0000] {processor.py:842} WARNING - No viable dags retrieved from /opt/airflow/dags/generarUsuarios.py
[2024-03-04T12:13:14.541+0000] {processor.py:183} INFO - Processing /opt/airflow/dags/generarUsuarios.py took 0.099 seconds
[2024-03-04T12:13:44.792+0000] {processor.py:161} INFO - Started process (PID=26897) to work on /opt/airflow/dags/generarUsuarios.py
[2024-03-04T12:13:44.795+0000] {processor.py:830} INFO - Processing file /opt/airflow/dags/generarUsuarios.py for tasks to queue
[2024-03-04T12:13:44.799+0000] {logging_mixin.py:188} INFO - [2024-03-04T12:13:44.798+0000] {dagbag.py:538} INFO - Filling up the DagBag from /opt/airflow/dags/generarUsuarios.py
[2024-03-04T12:13:44.806+0000] {logging_mixin.py:188} INFO - [2024-03-04T12:13:44.804+0000] {dagbag.py:348} ERROR - Failed to import: /opt/airflow/dags/generarUsuarios.py
Traceback (most recent call last):
  File "/home/airflow/.local/lib/python3.8/site-packages/airflow/models/dagbag.py", line 344, in parse
    loader.exec_module(new_module)
  File "<frozen importlib._bootstrap_external>", line 843, in exec_module
  File "<frozen importlib._bootstrap>", line 219, in _call_with_frames_removed
  File "/opt/airflow/dags/generarUsuarios.py", line 18, in <module>
    'retry_delay': timedelta(minutes=1),
NameError: name 'timedelta' is not defined
[2024-03-04T12:13:44.807+0000] {processor.py:842} WARNING - No viable dags retrieved from /opt/airflow/dags/generarUsuarios.py
[2024-03-04T12:13:44.845+0000] {processor.py:183} INFO - Processing /opt/airflow/dags/generarUsuarios.py took 0.060 seconds
[2024-03-04T12:14:15.080+0000] {processor.py:161} INFO - Started process (PID=26955) to work on /opt/airflow/dags/generarUsuarios.py
[2024-03-04T12:14:15.083+0000] {processor.py:830} INFO - Processing file /opt/airflow/dags/generarUsuarios.py for tasks to queue
[2024-03-04T12:14:15.086+0000] {logging_mixin.py:188} INFO - [2024-03-04T12:14:15.086+0000] {dagbag.py:538} INFO - Filling up the DagBag from /opt/airflow/dags/generarUsuarios.py
[2024-03-04T12:14:15.094+0000] {logging_mixin.py:188} INFO - [2024-03-04T12:14:15.092+0000] {dagbag.py:348} ERROR - Failed to import: /opt/airflow/dags/generarUsuarios.py
Traceback (most recent call last):
  File "/home/airflow/.local/lib/python3.8/site-packages/airflow/models/dagbag.py", line 344, in parse
    loader.exec_module(new_module)
  File "<frozen importlib._bootstrap_external>", line 843, in exec_module
  File "<frozen importlib._bootstrap>", line 219, in _call_with_frames_removed
  File "/opt/airflow/dags/generarUsuarios.py", line 18, in <module>
    'retry_delay': timedelta(minutes=1),
NameError: name 'timedelta' is not defined
[2024-03-04T12:14:15.095+0000] {processor.py:842} WARNING - No viable dags retrieved from /opt/airflow/dags/generarUsuarios.py
[2024-03-04T12:14:15.208+0000] {processor.py:183} INFO - Processing /opt/airflow/dags/generarUsuarios.py took 0.137 seconds
[2024-03-04T12:14:45.318+0000] {processor.py:161} INFO - Started process (PID=27014) to work on /opt/airflow/dags/generarUsuarios.py
[2024-03-04T12:14:45.321+0000] {processor.py:830} INFO - Processing file /opt/airflow/dags/generarUsuarios.py for tasks to queue
[2024-03-04T12:14:45.323+0000] {logging_mixin.py:188} INFO - [2024-03-04T12:14:45.322+0000] {dagbag.py:538} INFO - Filling up the DagBag from /opt/airflow/dags/generarUsuarios.py
[2024-03-04T12:14:45.331+0000] {logging_mixin.py:188} INFO - [2024-03-04T12:14:45.329+0000] {dagbag.py:348} ERROR - Failed to import: /opt/airflow/dags/generarUsuarios.py
Traceback (most recent call last):
  File "/home/airflow/.local/lib/python3.8/site-packages/airflow/models/dagbag.py", line 344, in parse
    loader.exec_module(new_module)
  File "<frozen importlib._bootstrap_external>", line 843, in exec_module
  File "<frozen importlib._bootstrap>", line 219, in _call_with_frames_removed
  File "/opt/airflow/dags/generarUsuarios.py", line 18, in <module>
    'retry_delay': timedelta(minutes=1),
NameError: name 'timedelta' is not defined
[2024-03-04T12:14:45.332+0000] {processor.py:842} WARNING - No viable dags retrieved from /opt/airflow/dags/generarUsuarios.py
[2024-03-04T12:14:45.434+0000] {processor.py:183} INFO - Processing /opt/airflow/dags/generarUsuarios.py took 0.125 seconds
[2024-03-04T12:15:15.866+0000] {processor.py:161} INFO - Started process (PID=27073) to work on /opt/airflow/dags/generarUsuarios.py
[2024-03-04T12:15:15.868+0000] {processor.py:830} INFO - Processing file /opt/airflow/dags/generarUsuarios.py for tasks to queue
[2024-03-04T12:15:15.871+0000] {logging_mixin.py:188} INFO - [2024-03-04T12:15:15.870+0000] {dagbag.py:538} INFO - Filling up the DagBag from /opt/airflow/dags/generarUsuarios.py
[2024-03-04T12:15:15.880+0000] {logging_mixin.py:188} INFO - [2024-03-04T12:15:15.876+0000] {dagbag.py:348} ERROR - Failed to import: /opt/airflow/dags/generarUsuarios.py
Traceback (most recent call last):
  File "/home/airflow/.local/lib/python3.8/site-packages/airflow/models/dagbag.py", line 344, in parse
    loader.exec_module(new_module)
  File "<frozen importlib._bootstrap_external>", line 843, in exec_module
  File "<frozen importlib._bootstrap>", line 219, in _call_with_frames_removed
  File "/opt/airflow/dags/generarUsuarios.py", line 18, in <module>
    'retry_delay': timedelta(minutes=1),
NameError: name 'timedelta' is not defined
[2024-03-04T12:15:15.881+0000] {processor.py:842} WARNING - No viable dags retrieved from /opt/airflow/dags/generarUsuarios.py
[2024-03-04T12:15:15.945+0000] {processor.py:183} INFO - Processing /opt/airflow/dags/generarUsuarios.py took 0.090 seconds
[2024-03-04T12:15:46.048+0000] {processor.py:161} INFO - Started process (PID=27129) to work on /opt/airflow/dags/generarUsuarios.py
[2024-03-04T12:15:46.062+0000] {processor.py:830} INFO - Processing file /opt/airflow/dags/generarUsuarios.py for tasks to queue
[2024-03-04T12:15:46.065+0000] {logging_mixin.py:188} INFO - [2024-03-04T12:15:46.063+0000] {dagbag.py:538} INFO - Filling up the DagBag from /opt/airflow/dags/generarUsuarios.py
[2024-03-04T12:15:46.085+0000] {logging_mixin.py:188} INFO - [2024-03-04T12:15:46.082+0000] {dagbag.py:348} ERROR - Failed to import: /opt/airflow/dags/generarUsuarios.py
Traceback (most recent call last):
  File "/home/airflow/.local/lib/python3.8/site-packages/airflow/models/dagbag.py", line 344, in parse
    loader.exec_module(new_module)
  File "<frozen importlib._bootstrap_external>", line 843, in exec_module
  File "<frozen importlib._bootstrap>", line 219, in _call_with_frames_removed
  File "/opt/airflow/dags/generarUsuarios.py", line 18, in <module>
    'retry_delay': timedelta(minutes=1),
NameError: name 'timedelta' is not defined
[2024-03-04T12:15:46.093+0000] {processor.py:842} WARNING - No viable dags retrieved from /opt/airflow/dags/generarUsuarios.py
[2024-03-04T12:15:46.186+0000] {processor.py:183} INFO - Processing /opt/airflow/dags/generarUsuarios.py took 0.147 seconds
[2024-03-04T12:16:16.991+0000] {processor.py:161} INFO - Started process (PID=27189) to work on /opt/airflow/dags/generarUsuarios.py
[2024-03-04T12:16:16.992+0000] {processor.py:830} INFO - Processing file /opt/airflow/dags/generarUsuarios.py for tasks to queue
[2024-03-04T12:16:16.994+0000] {logging_mixin.py:188} INFO - [2024-03-04T12:16:16.993+0000] {dagbag.py:538} INFO - Filling up the DagBag from /opt/airflow/dags/generarUsuarios.py
[2024-03-04T12:16:16.999+0000] {logging_mixin.py:188} INFO - [2024-03-04T12:16:16.998+0000] {dagbag.py:348} ERROR - Failed to import: /opt/airflow/dags/generarUsuarios.py
Traceback (most recent call last):
  File "/home/airflow/.local/lib/python3.8/site-packages/airflow/models/dagbag.py", line 344, in parse
    loader.exec_module(new_module)
  File "<frozen importlib._bootstrap_external>", line 843, in exec_module
  File "<frozen importlib._bootstrap>", line 219, in _call_with_frames_removed
  File "/opt/airflow/dags/generarUsuarios.py", line 18, in <module>
    'retry_delay': timedelta(minutes=1),
NameError: name 'timedelta' is not defined
[2024-03-04T12:16:17.000+0000] {processor.py:842} WARNING - No viable dags retrieved from /opt/airflow/dags/generarUsuarios.py
[2024-03-04T12:16:17.040+0000] {processor.py:183} INFO - Processing /opt/airflow/dags/generarUsuarios.py took 0.057 seconds
[2024-03-04T12:16:47.400+0000] {processor.py:161} INFO - Started process (PID=27244) to work on /opt/airflow/dags/generarUsuarios.py
[2024-03-04T12:16:47.409+0000] {processor.py:830} INFO - Processing file /opt/airflow/dags/generarUsuarios.py for tasks to queue
[2024-03-04T12:16:47.411+0000] {logging_mixin.py:188} INFO - [2024-03-04T12:16:47.410+0000] {dagbag.py:538} INFO - Filling up the DagBag from /opt/airflow/dags/generarUsuarios.py
[2024-03-04T12:16:47.427+0000] {logging_mixin.py:188} INFO - [2024-03-04T12:16:47.424+0000] {dagbag.py:348} ERROR - Failed to import: /opt/airflow/dags/generarUsuarios.py
Traceback (most recent call last):
  File "/home/airflow/.local/lib/python3.8/site-packages/airflow/models/dagbag.py", line 344, in parse
    loader.exec_module(new_module)
  File "<frozen importlib._bootstrap_external>", line 843, in exec_module
  File "<frozen importlib._bootstrap>", line 219, in _call_with_frames_removed
  File "/opt/airflow/dags/generarUsuarios.py", line 18, in <module>
    'retry_delay': timedelta(minutes=1),
NameError: name 'timedelta' is not defined
[2024-03-04T12:16:47.428+0000] {processor.py:842} WARNING - No viable dags retrieved from /opt/airflow/dags/generarUsuarios.py
[2024-03-04T12:16:47.497+0000] {processor.py:183} INFO - Processing /opt/airflow/dags/generarUsuarios.py took 0.111 seconds
[2024-03-04T12:17:17.793+0000] {processor.py:161} INFO - Started process (PID=27302) to work on /opt/airflow/dags/generarUsuarios.py
[2024-03-04T12:17:17.807+0000] {processor.py:830} INFO - Processing file /opt/airflow/dags/generarUsuarios.py for tasks to queue
[2024-03-04T12:17:17.809+0000] {logging_mixin.py:188} INFO - [2024-03-04T12:17:17.808+0000] {dagbag.py:538} INFO - Filling up the DagBag from /opt/airflow/dags/generarUsuarios.py
[2024-03-04T12:17:17.816+0000] {logging_mixin.py:188} INFO - [2024-03-04T12:17:17.814+0000] {dagbag.py:348} ERROR - Failed to import: /opt/airflow/dags/generarUsuarios.py
Traceback (most recent call last):
  File "/home/airflow/.local/lib/python3.8/site-packages/airflow/models/dagbag.py", line 344, in parse
    loader.exec_module(new_module)
  File "<frozen importlib._bootstrap_external>", line 843, in exec_module
  File "<frozen importlib._bootstrap>", line 219, in _call_with_frames_removed
  File "/opt/airflow/dags/generarUsuarios.py", line 18, in <module>
    'retry_delay': timedelta(minutes=1),
NameError: name 'timedelta' is not defined
[2024-03-04T12:17:17.817+0000] {processor.py:842} WARNING - No viable dags retrieved from /opt/airflow/dags/generarUsuarios.py
[2024-03-04T12:17:17.858+0000] {processor.py:183} INFO - Processing /opt/airflow/dags/generarUsuarios.py took 0.072 seconds
[2024-03-04T12:17:48.689+0000] {processor.py:161} INFO - Started process (PID=27360) to work on /opt/airflow/dags/generarUsuarios.py
[2024-03-04T12:17:48.694+0000] {processor.py:830} INFO - Processing file /opt/airflow/dags/generarUsuarios.py for tasks to queue
[2024-03-04T12:17:48.698+0000] {logging_mixin.py:188} INFO - [2024-03-04T12:17:48.697+0000] {dagbag.py:538} INFO - Filling up the DagBag from /opt/airflow/dags/generarUsuarios.py
[2024-03-04T12:17:48.709+0000] {logging_mixin.py:188} INFO - [2024-03-04T12:17:48.705+0000] {dagbag.py:348} ERROR - Failed to import: /opt/airflow/dags/generarUsuarios.py
Traceback (most recent call last):
  File "/home/airflow/.local/lib/python3.8/site-packages/airflow/models/dagbag.py", line 344, in parse
    loader.exec_module(new_module)
  File "<frozen importlib._bootstrap_external>", line 843, in exec_module
  File "<frozen importlib._bootstrap>", line 219, in _call_with_frames_removed
  File "/opt/airflow/dags/generarUsuarios.py", line 18, in <module>
    'retry_delay': timedelta(minutes=1),
NameError: name 'timedelta' is not defined
[2024-03-04T12:17:48.710+0000] {processor.py:842} WARNING - No viable dags retrieved from /opt/airflow/dags/generarUsuarios.py
[2024-03-04T12:17:48.763+0000] {processor.py:183} INFO - Processing /opt/airflow/dags/generarUsuarios.py took 0.085 seconds
[2024-03-04T12:18:18.855+0000] {processor.py:161} INFO - Started process (PID=27419) to work on /opt/airflow/dags/generarUsuarios.py
[2024-03-04T12:18:18.858+0000] {processor.py:830} INFO - Processing file /opt/airflow/dags/generarUsuarios.py for tasks to queue
[2024-03-04T12:18:18.860+0000] {logging_mixin.py:188} INFO - [2024-03-04T12:18:18.859+0000] {dagbag.py:538} INFO - Filling up the DagBag from /opt/airflow/dags/generarUsuarios.py
[2024-03-04T12:18:18.868+0000] {logging_mixin.py:188} INFO - [2024-03-04T12:18:18.865+0000] {dagbag.py:348} ERROR - Failed to import: /opt/airflow/dags/generarUsuarios.py
Traceback (most recent call last):
  File "/home/airflow/.local/lib/python3.8/site-packages/airflow/models/dagbag.py", line 344, in parse
    loader.exec_module(new_module)
  File "<frozen importlib._bootstrap_external>", line 843, in exec_module
  File "<frozen importlib._bootstrap>", line 219, in _call_with_frames_removed
  File "/opt/airflow/dags/generarUsuarios.py", line 18, in <module>
    'retry_delay': timedelta(minutes=1),
NameError: name 'timedelta' is not defined
[2024-03-04T12:18:18.869+0000] {processor.py:842} WARNING - No viable dags retrieved from /opt/airflow/dags/generarUsuarios.py
[2024-03-04T12:18:18.997+0000] {processor.py:183} INFO - Processing /opt/airflow/dags/generarUsuarios.py took 0.153 seconds
[2024-03-04T12:18:49.413+0000] {processor.py:161} INFO - Started process (PID=27474) to work on /opt/airflow/dags/generarUsuarios.py
[2024-03-04T12:18:49.418+0000] {processor.py:830} INFO - Processing file /opt/airflow/dags/generarUsuarios.py for tasks to queue
[2024-03-04T12:18:49.420+0000] {logging_mixin.py:188} INFO - [2024-03-04T12:18:49.420+0000] {dagbag.py:538} INFO - Filling up the DagBag from /opt/airflow/dags/generarUsuarios.py
[2024-03-04T12:18:49.427+0000] {logging_mixin.py:188} INFO - [2024-03-04T12:18:49.424+0000] {dagbag.py:348} ERROR - Failed to import: /opt/airflow/dags/generarUsuarios.py
Traceback (most recent call last):
  File "/home/airflow/.local/lib/python3.8/site-packages/airflow/models/dagbag.py", line 344, in parse
    loader.exec_module(new_module)
  File "<frozen importlib._bootstrap_external>", line 843, in exec_module
  File "<frozen importlib._bootstrap>", line 219, in _call_with_frames_removed
  File "/opt/airflow/dags/generarUsuarios.py", line 18, in <module>
    'retry_delay': timedelta(minutes=1),
NameError: name 'timedelta' is not defined
[2024-03-04T12:18:49.428+0000] {processor.py:842} WARNING - No viable dags retrieved from /opt/airflow/dags/generarUsuarios.py
[2024-03-04T12:18:49.474+0000] {processor.py:183} INFO - Processing /opt/airflow/dags/generarUsuarios.py took 0.077 seconds
[2024-03-04T12:19:19.661+0000] {processor.py:161} INFO - Started process (PID=27533) to work on /opt/airflow/dags/generarUsuarios.py
[2024-03-04T12:19:19.663+0000] {processor.py:830} INFO - Processing file /opt/airflow/dags/generarUsuarios.py for tasks to queue
[2024-03-04T12:19:19.665+0000] {logging_mixin.py:188} INFO - [2024-03-04T12:19:19.665+0000] {dagbag.py:538} INFO - Filling up the DagBag from /opt/airflow/dags/generarUsuarios.py
[2024-03-04T12:19:19.674+0000] {logging_mixin.py:188} INFO - [2024-03-04T12:19:19.671+0000] {dagbag.py:348} ERROR - Failed to import: /opt/airflow/dags/generarUsuarios.py
Traceback (most recent call last):
  File "/home/airflow/.local/lib/python3.8/site-packages/airflow/models/dagbag.py", line 344, in parse
    loader.exec_module(new_module)
  File "<frozen importlib._bootstrap_external>", line 843, in exec_module
  File "<frozen importlib._bootstrap>", line 219, in _call_with_frames_removed
  File "/opt/airflow/dags/generarUsuarios.py", line 18, in <module>
    'retry_delay': timedelta(minutes=1),
NameError: name 'timedelta' is not defined
[2024-03-04T12:19:19.675+0000] {processor.py:842} WARNING - No viable dags retrieved from /opt/airflow/dags/generarUsuarios.py
[2024-03-04T12:19:19.761+0000] {processor.py:183} INFO - Processing /opt/airflow/dags/generarUsuarios.py took 0.114 seconds
[2024-03-04T12:19:49.903+0000] {processor.py:161} INFO - Started process (PID=27589) to work on /opt/airflow/dags/generarUsuarios.py
[2024-03-04T12:19:49.909+0000] {processor.py:830} INFO - Processing file /opt/airflow/dags/generarUsuarios.py for tasks to queue
[2024-03-04T12:19:49.911+0000] {logging_mixin.py:188} INFO - [2024-03-04T12:19:49.911+0000] {dagbag.py:538} INFO - Filling up the DagBag from /opt/airflow/dags/generarUsuarios.py
[2024-03-04T12:19:49.923+0000] {logging_mixin.py:188} INFO - [2024-03-04T12:19:49.919+0000] {dagbag.py:348} ERROR - Failed to import: /opt/airflow/dags/generarUsuarios.py
Traceback (most recent call last):
  File "/home/airflow/.local/lib/python3.8/site-packages/airflow/models/dagbag.py", line 344, in parse
    loader.exec_module(new_module)
  File "<frozen importlib._bootstrap_external>", line 843, in exec_module
  File "<frozen importlib._bootstrap>", line 219, in _call_with_frames_removed
  File "/opt/airflow/dags/generarUsuarios.py", line 18, in <module>
    'retry_delay': timedelta(minutes=1),
NameError: name 'timedelta' is not defined
[2024-03-04T12:19:49.923+0000] {processor.py:842} WARNING - No viable dags retrieved from /opt/airflow/dags/generarUsuarios.py
[2024-03-04T12:19:49.967+0000] {processor.py:183} INFO - Processing /opt/airflow/dags/generarUsuarios.py took 0.072 seconds
[2024-03-04T12:20:20.608+0000] {processor.py:161} INFO - Started process (PID=27648) to work on /opt/airflow/dags/generarUsuarios.py
[2024-03-04T12:20:20.611+0000] {processor.py:830} INFO - Processing file /opt/airflow/dags/generarUsuarios.py for tasks to queue
[2024-03-04T12:20:20.614+0000] {logging_mixin.py:188} INFO - [2024-03-04T12:20:20.613+0000] {dagbag.py:538} INFO - Filling up the DagBag from /opt/airflow/dags/generarUsuarios.py
[2024-03-04T12:20:20.626+0000] {logging_mixin.py:188} INFO - [2024-03-04T12:20:20.624+0000] {dagbag.py:348} ERROR - Failed to import: /opt/airflow/dags/generarUsuarios.py
Traceback (most recent call last):
  File "/home/airflow/.local/lib/python3.8/site-packages/airflow/models/dagbag.py", line 344, in parse
    loader.exec_module(new_module)
  File "<frozen importlib._bootstrap_external>", line 843, in exec_module
  File "<frozen importlib._bootstrap>", line 219, in _call_with_frames_removed
  File "/opt/airflow/dags/generarUsuarios.py", line 18, in <module>
    'retry_delay': timedelta(minutes=1),
NameError: name 'timedelta' is not defined
[2024-03-04T12:20:20.627+0000] {processor.py:842} WARNING - No viable dags retrieved from /opt/airflow/dags/generarUsuarios.py
[2024-03-04T12:20:20.714+0000] {processor.py:183} INFO - Processing /opt/airflow/dags/generarUsuarios.py took 0.118 seconds
[2024-03-04T12:20:51.346+0000] {processor.py:161} INFO - Started process (PID=27705) to work on /opt/airflow/dags/generarUsuarios.py
[2024-03-04T12:20:51.348+0000] {processor.py:830} INFO - Processing file /opt/airflow/dags/generarUsuarios.py for tasks to queue
[2024-03-04T12:20:51.353+0000] {logging_mixin.py:188} INFO - [2024-03-04T12:20:51.352+0000] {dagbag.py:538} INFO - Filling up the DagBag from /opt/airflow/dags/generarUsuarios.py
[2024-03-04T12:20:51.362+0000] {logging_mixin.py:188} INFO - [2024-03-04T12:20:51.360+0000] {dagbag.py:348} ERROR - Failed to import: /opt/airflow/dags/generarUsuarios.py
Traceback (most recent call last):
  File "/home/airflow/.local/lib/python3.8/site-packages/airflow/models/dagbag.py", line 344, in parse
    loader.exec_module(new_module)
  File "<frozen importlib._bootstrap_external>", line 843, in exec_module
  File "<frozen importlib._bootstrap>", line 219, in _call_with_frames_removed
  File "/opt/airflow/dags/generarUsuarios.py", line 18, in <module>
    'retry_delay': timedelta(minutes=1),
NameError: name 'timedelta' is not defined
[2024-03-04T12:20:51.363+0000] {processor.py:842} WARNING - No viable dags retrieved from /opt/airflow/dags/generarUsuarios.py
[2024-03-04T12:20:51.419+0000] {processor.py:183} INFO - Processing /opt/airflow/dags/generarUsuarios.py took 0.087 seconds
[2024-03-04T12:21:21.628+0000] {processor.py:161} INFO - Started process (PID=27763) to work on /opt/airflow/dags/generarUsuarios.py
[2024-03-04T12:21:21.631+0000] {processor.py:830} INFO - Processing file /opt/airflow/dags/generarUsuarios.py for tasks to queue
[2024-03-04T12:21:21.634+0000] {logging_mixin.py:188} INFO - [2024-03-04T12:21:21.633+0000] {dagbag.py:538} INFO - Filling up the DagBag from /opt/airflow/dags/generarUsuarios.py
[2024-03-04T12:21:21.643+0000] {logging_mixin.py:188} INFO - [2024-03-04T12:21:21.640+0000] {dagbag.py:348} ERROR - Failed to import: /opt/airflow/dags/generarUsuarios.py
Traceback (most recent call last):
  File "/home/airflow/.local/lib/python3.8/site-packages/airflow/models/dagbag.py", line 344, in parse
    loader.exec_module(new_module)
  File "<frozen importlib._bootstrap_external>", line 843, in exec_module
  File "<frozen importlib._bootstrap>", line 219, in _call_with_frames_removed
  File "/opt/airflow/dags/generarUsuarios.py", line 18, in <module>
    'retry_delay': timedelta(minutes=1),
NameError: name 'timedelta' is not defined
[2024-03-04T12:21:21.645+0000] {processor.py:842} WARNING - No viable dags retrieved from /opt/airflow/dags/generarUsuarios.py
[2024-03-04T12:21:21.717+0000] {processor.py:183} INFO - Processing /opt/airflow/dags/generarUsuarios.py took 0.100 seconds
[2024-03-04T12:21:52.558+0000] {processor.py:161} INFO - Started process (PID=27820) to work on /opt/airflow/dags/generarUsuarios.py
[2024-03-04T12:21:52.561+0000] {processor.py:830} INFO - Processing file /opt/airflow/dags/generarUsuarios.py for tasks to queue
[2024-03-04T12:21:52.564+0000] {logging_mixin.py:188} INFO - [2024-03-04T12:21:52.563+0000] {dagbag.py:538} INFO - Filling up the DagBag from /opt/airflow/dags/generarUsuarios.py
[2024-03-04T12:21:52.581+0000] {logging_mixin.py:188} INFO - [2024-03-04T12:21:52.579+0000] {dagbag.py:348} ERROR - Failed to import: /opt/airflow/dags/generarUsuarios.py
Traceback (most recent call last):
  File "/home/airflow/.local/lib/python3.8/site-packages/airflow/models/dagbag.py", line 344, in parse
    loader.exec_module(new_module)
  File "<frozen importlib._bootstrap_external>", line 843, in exec_module
  File "<frozen importlib._bootstrap>", line 219, in _call_with_frames_removed
  File "/opt/airflow/dags/generarUsuarios.py", line 18, in <module>
    'retry_delay': timedelta(minutes=1),
NameError: name 'timedelta' is not defined
[2024-03-04T12:21:52.582+0000] {processor.py:842} WARNING - No viable dags retrieved from /opt/airflow/dags/generarUsuarios.py
[2024-03-04T12:21:52.709+0000] {processor.py:183} INFO - Processing /opt/airflow/dags/generarUsuarios.py took 0.166 seconds
[2024-03-04T12:22:23.298+0000] {processor.py:161} INFO - Started process (PID=27878) to work on /opt/airflow/dags/generarUsuarios.py
[2024-03-04T12:22:23.300+0000] {processor.py:830} INFO - Processing file /opt/airflow/dags/generarUsuarios.py for tasks to queue
[2024-03-04T12:22:23.303+0000] {logging_mixin.py:188} INFO - [2024-03-04T12:22:23.302+0000] {dagbag.py:538} INFO - Filling up the DagBag from /opt/airflow/dags/generarUsuarios.py
[2024-03-04T12:22:23.309+0000] {logging_mixin.py:188} INFO - [2024-03-04T12:22:23.308+0000] {dagbag.py:348} ERROR - Failed to import: /opt/airflow/dags/generarUsuarios.py
Traceback (most recent call last):
  File "/home/airflow/.local/lib/python3.8/site-packages/airflow/models/dagbag.py", line 344, in parse
    loader.exec_module(new_module)
  File "<frozen importlib._bootstrap_external>", line 843, in exec_module
  File "<frozen importlib._bootstrap>", line 219, in _call_with_frames_removed
  File "/opt/airflow/dags/generarUsuarios.py", line 18, in <module>
    'retry_delay': timedelta(minutes=1),
NameError: name 'timedelta' is not defined
[2024-03-04T12:22:23.310+0000] {processor.py:842} WARNING - No viable dags retrieved from /opt/airflow/dags/generarUsuarios.py
[2024-03-04T12:22:23.350+0000] {processor.py:183} INFO - Processing /opt/airflow/dags/generarUsuarios.py took 0.060 seconds
[2024-03-04T12:22:53.954+0000] {processor.py:161} INFO - Started process (PID=27937) to work on /opt/airflow/dags/generarUsuarios.py
[2024-03-04T12:22:53.956+0000] {processor.py:830} INFO - Processing file /opt/airflow/dags/generarUsuarios.py for tasks to queue
[2024-03-04T12:22:53.971+0000] {logging_mixin.py:188} INFO - [2024-03-04T12:22:53.970+0000] {dagbag.py:538} INFO - Filling up the DagBag from /opt/airflow/dags/generarUsuarios.py
[2024-03-04T12:22:54.004+0000] {logging_mixin.py:188} INFO - [2024-03-04T12:22:53.990+0000] {dagbag.py:348} ERROR - Failed to import: /opt/airflow/dags/generarUsuarios.py
Traceback (most recent call last):
  File "/home/airflow/.local/lib/python3.8/site-packages/airflow/models/dagbag.py", line 344, in parse
    loader.exec_module(new_module)
  File "<frozen importlib._bootstrap_external>", line 843, in exec_module
  File "<frozen importlib._bootstrap>", line 219, in _call_with_frames_removed
  File "/opt/airflow/dags/generarUsuarios.py", line 18, in <module>
    'retry_delay': timedelta(minutes=1),
NameError: name 'timedelta' is not defined
[2024-03-04T12:22:54.005+0000] {processor.py:842} WARNING - No viable dags retrieved from /opt/airflow/dags/generarUsuarios.py
[2024-03-04T12:22:54.157+0000] {processor.py:183} INFO - Processing /opt/airflow/dags/generarUsuarios.py took 0.235 seconds
[2024-03-04T12:23:24.562+0000] {processor.py:161} INFO - Started process (PID=27997) to work on /opt/airflow/dags/generarUsuarios.py
[2024-03-04T12:23:24.564+0000] {processor.py:830} INFO - Processing file /opt/airflow/dags/generarUsuarios.py for tasks to queue
[2024-03-04T12:23:24.566+0000] {logging_mixin.py:188} INFO - [2024-03-04T12:23:24.565+0000] {dagbag.py:538} INFO - Filling up the DagBag from /opt/airflow/dags/generarUsuarios.py
[2024-03-04T12:23:24.572+0000] {logging_mixin.py:188} INFO - [2024-03-04T12:23:24.571+0000] {dagbag.py:348} ERROR - Failed to import: /opt/airflow/dags/generarUsuarios.py
Traceback (most recent call last):
  File "/home/airflow/.local/lib/python3.8/site-packages/airflow/models/dagbag.py", line 344, in parse
    loader.exec_module(new_module)
  File "<frozen importlib._bootstrap_external>", line 843, in exec_module
  File "<frozen importlib._bootstrap>", line 219, in _call_with_frames_removed
  File "/opt/airflow/dags/generarUsuarios.py", line 18, in <module>
    'retry_delay': timedelta(minutes=1),
NameError: name 'timedelta' is not defined
[2024-03-04T12:23:24.573+0000] {processor.py:842} WARNING - No viable dags retrieved from /opt/airflow/dags/generarUsuarios.py
[2024-03-04T12:23:24.620+0000] {processor.py:183} INFO - Processing /opt/airflow/dags/generarUsuarios.py took 0.064 seconds
[2024-03-04T12:23:55.402+0000] {processor.py:161} INFO - Started process (PID=28056) to work on /opt/airflow/dags/generarUsuarios.py
[2024-03-04T12:23:55.406+0000] {processor.py:830} INFO - Processing file /opt/airflow/dags/generarUsuarios.py for tasks to queue
[2024-03-04T12:23:55.409+0000] {logging_mixin.py:188} INFO - [2024-03-04T12:23:55.408+0000] {dagbag.py:538} INFO - Filling up the DagBag from /opt/airflow/dags/generarUsuarios.py
[2024-03-04T12:23:55.427+0000] {logging_mixin.py:188} INFO - [2024-03-04T12:23:55.419+0000] {dagbag.py:348} ERROR - Failed to import: /opt/airflow/dags/generarUsuarios.py
Traceback (most recent call last):
  File "/home/airflow/.local/lib/python3.8/site-packages/airflow/models/dagbag.py", line 344, in parse
    loader.exec_module(new_module)
  File "<frozen importlib._bootstrap_external>", line 843, in exec_module
  File "<frozen importlib._bootstrap>", line 219, in _call_with_frames_removed
  File "/opt/airflow/dags/generarUsuarios.py", line 18, in <module>
    'retry_delay': timedelta(minutes=1),
NameError: name 'timedelta' is not defined
[2024-03-04T12:23:55.428+0000] {processor.py:842} WARNING - No viable dags retrieved from /opt/airflow/dags/generarUsuarios.py
[2024-03-04T12:23:55.587+0000] {processor.py:183} INFO - Processing /opt/airflow/dags/generarUsuarios.py took 0.215 seconds
[2024-03-04T12:24:25.883+0000] {processor.py:161} INFO - Started process (PID=28115) to work on /opt/airflow/dags/generarUsuarios.py
[2024-03-04T12:24:25.885+0000] {processor.py:830} INFO - Processing file /opt/airflow/dags/generarUsuarios.py for tasks to queue
[2024-03-04T12:24:25.887+0000] {logging_mixin.py:188} INFO - [2024-03-04T12:24:25.886+0000] {dagbag.py:538} INFO - Filling up the DagBag from /opt/airflow/dags/generarUsuarios.py
[2024-03-04T12:24:25.896+0000] {logging_mixin.py:188} INFO - [2024-03-04T12:24:25.893+0000] {dagbag.py:348} ERROR - Failed to import: /opt/airflow/dags/generarUsuarios.py
Traceback (most recent call last):
  File "/home/airflow/.local/lib/python3.8/site-packages/airflow/models/dagbag.py", line 344, in parse
    loader.exec_module(new_module)
  File "<frozen importlib._bootstrap_external>", line 843, in exec_module
  File "<frozen importlib._bootstrap>", line 219, in _call_with_frames_removed
  File "/opt/airflow/dags/generarUsuarios.py", line 18, in <module>
    'retry_delay': timedelta(minutes=1),
NameError: name 'timedelta' is not defined
[2024-03-04T12:24:25.897+0000] {processor.py:842} WARNING - No viable dags retrieved from /opt/airflow/dags/generarUsuarios.py
[2024-03-04T12:24:25.962+0000] {processor.py:183} INFO - Processing /opt/airflow/dags/generarUsuarios.py took 0.088 seconds
[2024-03-04T12:24:56.122+0000] {processor.py:161} INFO - Started process (PID=28170) to work on /opt/airflow/dags/generarUsuarios.py
[2024-03-04T12:24:56.127+0000] {processor.py:830} INFO - Processing file /opt/airflow/dags/generarUsuarios.py for tasks to queue
[2024-03-04T12:24:56.130+0000] {logging_mixin.py:188} INFO - [2024-03-04T12:24:56.129+0000] {dagbag.py:538} INFO - Filling up the DagBag from /opt/airflow/dags/generarUsuarios.py
[2024-03-04T12:24:56.142+0000] {logging_mixin.py:188} INFO - [2024-03-04T12:24:56.140+0000] {dagbag.py:348} ERROR - Failed to import: /opt/airflow/dags/generarUsuarios.py
Traceback (most recent call last):
  File "/home/airflow/.local/lib/python3.8/site-packages/airflow/models/dagbag.py", line 344, in parse
    loader.exec_module(new_module)
  File "<frozen importlib._bootstrap_external>", line 843, in exec_module
  File "<frozen importlib._bootstrap>", line 219, in _call_with_frames_removed
  File "/opt/airflow/dags/generarUsuarios.py", line 18, in <module>
    'retry_delay': timedelta(minutes=1),
NameError: name 'timedelta' is not defined
[2024-03-04T12:24:56.143+0000] {processor.py:842} WARNING - No viable dags retrieved from /opt/airflow/dags/generarUsuarios.py
[2024-03-04T12:24:56.222+0000] {processor.py:183} INFO - Processing /opt/airflow/dags/generarUsuarios.py took 0.114 seconds
[2024-03-04T12:25:26.444+0000] {processor.py:161} INFO - Started process (PID=28229) to work on /opt/airflow/dags/generarUsuarios.py
[2024-03-04T12:25:26.446+0000] {processor.py:830} INFO - Processing file /opt/airflow/dags/generarUsuarios.py for tasks to queue
[2024-03-04T12:25:26.448+0000] {logging_mixin.py:188} INFO - [2024-03-04T12:25:26.447+0000] {dagbag.py:538} INFO - Filling up the DagBag from /opt/airflow/dags/generarUsuarios.py
[2024-03-04T12:25:26.453+0000] {logging_mixin.py:188} INFO - [2024-03-04T12:25:26.452+0000] {dagbag.py:348} ERROR - Failed to import: /opt/airflow/dags/generarUsuarios.py
Traceback (most recent call last):
  File "/home/airflow/.local/lib/python3.8/site-packages/airflow/models/dagbag.py", line 344, in parse
    loader.exec_module(new_module)
  File "<frozen importlib._bootstrap_external>", line 843, in exec_module
  File "<frozen importlib._bootstrap>", line 219, in _call_with_frames_removed
  File "/opt/airflow/dags/generarUsuarios.py", line 18, in <module>
    'retry_delay': timedelta(minutes=1),
NameError: name 'timedelta' is not defined
[2024-03-04T12:25:26.454+0000] {processor.py:842} WARNING - No viable dags retrieved from /opt/airflow/dags/generarUsuarios.py
[2024-03-04T12:25:26.489+0000] {processor.py:183} INFO - Processing /opt/airflow/dags/generarUsuarios.py took 0.052 seconds
[2024-03-04T12:25:56.759+0000] {processor.py:161} INFO - Started process (PID=28288) to work on /opt/airflow/dags/generarUsuarios.py
[2024-03-04T12:25:56.787+0000] {processor.py:830} INFO - Processing file /opt/airflow/dags/generarUsuarios.py for tasks to queue
[2024-03-04T12:25:56.790+0000] {logging_mixin.py:188} INFO - [2024-03-04T12:25:56.789+0000] {dagbag.py:538} INFO - Filling up the DagBag from /opt/airflow/dags/generarUsuarios.py
[2024-03-04T12:25:56.809+0000] {logging_mixin.py:188} INFO - [2024-03-04T12:25:56.807+0000] {dagbag.py:348} ERROR - Failed to import: /opt/airflow/dags/generarUsuarios.py
Traceback (most recent call last):
  File "/home/airflow/.local/lib/python3.8/site-packages/airflow/models/dagbag.py", line 344, in parse
    loader.exec_module(new_module)
  File "<frozen importlib._bootstrap_external>", line 843, in exec_module
  File "<frozen importlib._bootstrap>", line 219, in _call_with_frames_removed
  File "/opt/airflow/dags/generarUsuarios.py", line 18, in <module>
    'retry_delay': timedelta(minutes=1),
NameError: name 'timedelta' is not defined
[2024-03-04T12:25:56.811+0000] {processor.py:842} WARNING - No viable dags retrieved from /opt/airflow/dags/generarUsuarios.py
[2024-03-04T12:25:57.001+0000] {processor.py:183} INFO - Processing /opt/airflow/dags/generarUsuarios.py took 0.279 seconds
[2024-03-04T12:26:27.281+0000] {processor.py:161} INFO - Started process (PID=28346) to work on /opt/airflow/dags/generarUsuarios.py
[2024-03-04T12:26:27.290+0000] {processor.py:830} INFO - Processing file /opt/airflow/dags/generarUsuarios.py for tasks to queue
[2024-03-04T12:26:27.293+0000] {logging_mixin.py:188} INFO - [2024-03-04T12:26:27.292+0000] {dagbag.py:538} INFO - Filling up the DagBag from /opt/airflow/dags/generarUsuarios.py
[2024-03-04T12:26:27.302+0000] {logging_mixin.py:188} INFO - [2024-03-04T12:26:27.299+0000] {dagbag.py:348} ERROR - Failed to import: /opt/airflow/dags/generarUsuarios.py
Traceback (most recent call last):
  File "/home/airflow/.local/lib/python3.8/site-packages/airflow/models/dagbag.py", line 344, in parse
    loader.exec_module(new_module)
  File "<frozen importlib._bootstrap_external>", line 843, in exec_module
  File "<frozen importlib._bootstrap>", line 219, in _call_with_frames_removed
  File "/opt/airflow/dags/generarUsuarios.py", line 18, in <module>
    'retry_delay': timedelta(minutes=1),
NameError: name 'timedelta' is not defined
[2024-03-04T12:26:27.310+0000] {processor.py:842} WARNING - No viable dags retrieved from /opt/airflow/dags/generarUsuarios.py
[2024-03-04T12:26:27.376+0000] {processor.py:183} INFO - Processing /opt/airflow/dags/generarUsuarios.py took 0.106 seconds
[2024-03-04T12:26:57.863+0000] {processor.py:161} INFO - Started process (PID=28405) to work on /opt/airflow/dags/generarUsuarios.py
[2024-03-04T12:26:57.864+0000] {processor.py:830} INFO - Processing file /opt/airflow/dags/generarUsuarios.py for tasks to queue
[2024-03-04T12:26:57.866+0000] {logging_mixin.py:188} INFO - [2024-03-04T12:26:57.865+0000] {dagbag.py:538} INFO - Filling up the DagBag from /opt/airflow/dags/generarUsuarios.py
[2024-03-04T12:26:57.872+0000] {logging_mixin.py:188} INFO - [2024-03-04T12:26:57.870+0000] {dagbag.py:348} ERROR - Failed to import: /opt/airflow/dags/generarUsuarios.py
Traceback (most recent call last):
  File "/home/airflow/.local/lib/python3.8/site-packages/airflow/models/dagbag.py", line 344, in parse
    loader.exec_module(new_module)
  File "<frozen importlib._bootstrap_external>", line 843, in exec_module
  File "<frozen importlib._bootstrap>", line 219, in _call_with_frames_removed
  File "/opt/airflow/dags/generarUsuarios.py", line 18, in <module>
    'retry_delay': timedelta(minutes=1),
NameError: name 'timedelta' is not defined
[2024-03-04T12:26:57.872+0000] {processor.py:842} WARNING - No viable dags retrieved from /opt/airflow/dags/generarUsuarios.py
[2024-03-04T12:26:57.916+0000] {processor.py:183} INFO - Processing /opt/airflow/dags/generarUsuarios.py took 0.060 seconds
[2024-03-04T12:27:28.745+0000] {processor.py:161} INFO - Started process (PID=28464) to work on /opt/airflow/dags/generarUsuarios.py
[2024-03-04T12:27:28.752+0000] {processor.py:830} INFO - Processing file /opt/airflow/dags/generarUsuarios.py for tasks to queue
[2024-03-04T12:27:28.754+0000] {logging_mixin.py:188} INFO - [2024-03-04T12:27:28.753+0000] {dagbag.py:538} INFO - Filling up the DagBag from /opt/airflow/dags/generarUsuarios.py
[2024-03-04T12:27:28.761+0000] {logging_mixin.py:188} INFO - [2024-03-04T12:27:28.759+0000] {dagbag.py:348} ERROR - Failed to import: /opt/airflow/dags/generarUsuarios.py
Traceback (most recent call last):
  File "/home/airflow/.local/lib/python3.8/site-packages/airflow/models/dagbag.py", line 344, in parse
    loader.exec_module(new_module)
  File "<frozen importlib._bootstrap_external>", line 843, in exec_module
  File "<frozen importlib._bootstrap>", line 219, in _call_with_frames_removed
  File "/opt/airflow/dags/generarUsuarios.py", line 18, in <module>
    'retry_delay': timedelta(minutes=1),
NameError: name 'timedelta' is not defined
[2024-03-04T12:27:28.761+0000] {processor.py:842} WARNING - No viable dags retrieved from /opt/airflow/dags/generarUsuarios.py
[2024-03-04T12:27:28.805+0000] {processor.py:183} INFO - Processing /opt/airflow/dags/generarUsuarios.py took 0.067 seconds
[2024-03-04T12:27:59.071+0000] {processor.py:161} INFO - Started process (PID=28523) to work on /opt/airflow/dags/generarUsuarios.py
[2024-03-04T12:27:59.075+0000] {processor.py:830} INFO - Processing file /opt/airflow/dags/generarUsuarios.py for tasks to queue
[2024-03-04T12:27:59.078+0000] {logging_mixin.py:188} INFO - [2024-03-04T12:27:59.077+0000] {dagbag.py:538} INFO - Filling up the DagBag from /opt/airflow/dags/generarUsuarios.py
[2024-03-04T12:27:59.086+0000] {logging_mixin.py:188} INFO - [2024-03-04T12:27:59.084+0000] {dagbag.py:348} ERROR - Failed to import: /opt/airflow/dags/generarUsuarios.py
Traceback (most recent call last):
  File "/home/airflow/.local/lib/python3.8/site-packages/airflow/models/dagbag.py", line 344, in parse
    loader.exec_module(new_module)
  File "<frozen importlib._bootstrap_external>", line 843, in exec_module
  File "<frozen importlib._bootstrap>", line 219, in _call_with_frames_removed
  File "/opt/airflow/dags/generarUsuarios.py", line 18, in <module>
    'retry_delay': timedelta(minutes=1),
NameError: name 'timedelta' is not defined
[2024-03-04T12:27:59.087+0000] {processor.py:842} WARNING - No viable dags retrieved from /opt/airflow/dags/generarUsuarios.py
[2024-03-04T12:27:59.145+0000] {processor.py:183} INFO - Processing /opt/airflow/dags/generarUsuarios.py took 0.082 seconds
[2024-03-04T12:28:29.775+0000] {processor.py:161} INFO - Started process (PID=28582) to work on /opt/airflow/dags/generarUsuarios.py
[2024-03-04T12:28:29.778+0000] {processor.py:830} INFO - Processing file /opt/airflow/dags/generarUsuarios.py for tasks to queue
[2024-03-04T12:28:29.781+0000] {logging_mixin.py:188} INFO - [2024-03-04T12:28:29.780+0000] {dagbag.py:538} INFO - Filling up the DagBag from /opt/airflow/dags/generarUsuarios.py
[2024-03-04T12:28:29.789+0000] {logging_mixin.py:188} INFO - [2024-03-04T12:28:29.786+0000] {dagbag.py:348} ERROR - Failed to import: /opt/airflow/dags/generarUsuarios.py
Traceback (most recent call last):
  File "/home/airflow/.local/lib/python3.8/site-packages/airflow/models/dagbag.py", line 344, in parse
    loader.exec_module(new_module)
  File "<frozen importlib._bootstrap_external>", line 843, in exec_module
  File "<frozen importlib._bootstrap>", line 219, in _call_with_frames_removed
  File "/opt/airflow/dags/generarUsuarios.py", line 18, in <module>
    'retry_delay': timedelta(minutes=1),
NameError: name 'timedelta' is not defined
[2024-03-04T12:28:29.790+0000] {processor.py:842} WARNING - No viable dags retrieved from /opt/airflow/dags/generarUsuarios.py
[2024-03-04T12:28:29.850+0000] {processor.py:183} INFO - Processing /opt/airflow/dags/generarUsuarios.py took 0.084 seconds
[2024-03-04T12:29:00.324+0000] {processor.py:161} INFO - Started process (PID=28641) to work on /opt/airflow/dags/generarUsuarios.py
[2024-03-04T12:29:00.326+0000] {processor.py:830} INFO - Processing file /opt/airflow/dags/generarUsuarios.py for tasks to queue
[2024-03-04T12:29:00.328+0000] {logging_mixin.py:188} INFO - [2024-03-04T12:29:00.327+0000] {dagbag.py:538} INFO - Filling up the DagBag from /opt/airflow/dags/generarUsuarios.py
[2024-03-04T12:29:00.335+0000] {logging_mixin.py:188} INFO - [2024-03-04T12:29:00.333+0000] {dagbag.py:348} ERROR - Failed to import: /opt/airflow/dags/generarUsuarios.py
Traceback (most recent call last):
  File "/home/airflow/.local/lib/python3.8/site-packages/airflow/models/dagbag.py", line 344, in parse
    loader.exec_module(new_module)
  File "<frozen importlib._bootstrap_external>", line 843, in exec_module
  File "<frozen importlib._bootstrap>", line 219, in _call_with_frames_removed
  File "/opt/airflow/dags/generarUsuarios.py", line 18, in <module>
    'retry_delay': timedelta(minutes=1),
NameError: name 'timedelta' is not defined
[2024-03-04T12:29:00.336+0000] {processor.py:842} WARNING - No viable dags retrieved from /opt/airflow/dags/generarUsuarios.py
[2024-03-04T12:29:00.379+0000] {processor.py:183} INFO - Processing /opt/airflow/dags/generarUsuarios.py took 0.067 seconds
[2024-03-04T12:29:31.139+0000] {processor.py:161} INFO - Started process (PID=28700) to work on /opt/airflow/dags/generarUsuarios.py
[2024-03-04T12:29:31.141+0000] {processor.py:830} INFO - Processing file /opt/airflow/dags/generarUsuarios.py for tasks to queue
[2024-03-04T12:29:31.143+0000] {logging_mixin.py:188} INFO - [2024-03-04T12:29:31.142+0000] {dagbag.py:538} INFO - Filling up the DagBag from /opt/airflow/dags/generarUsuarios.py
[2024-03-04T12:29:31.149+0000] {logging_mixin.py:188} INFO - [2024-03-04T12:29:31.147+0000] {dagbag.py:348} ERROR - Failed to import: /opt/airflow/dags/generarUsuarios.py
Traceback (most recent call last):
  File "/home/airflow/.local/lib/python3.8/site-packages/airflow/models/dagbag.py", line 344, in parse
    loader.exec_module(new_module)
  File "<frozen importlib._bootstrap_external>", line 843, in exec_module
  File "<frozen importlib._bootstrap>", line 219, in _call_with_frames_removed
  File "/opt/airflow/dags/generarUsuarios.py", line 18, in <module>
    'retry_delay': timedelta(minutes=1),
NameError: name 'timedelta' is not defined
[2024-03-04T12:29:31.149+0000] {processor.py:842} WARNING - No viable dags retrieved from /opt/airflow/dags/generarUsuarios.py
[2024-03-04T12:29:31.198+0000] {processor.py:183} INFO - Processing /opt/airflow/dags/generarUsuarios.py took 0.068 seconds
[2024-03-04T12:30:01.579+0000] {processor.py:161} INFO - Started process (PID=28759) to work on /opt/airflow/dags/generarUsuarios.py
[2024-03-04T12:30:01.581+0000] {processor.py:830} INFO - Processing file /opt/airflow/dags/generarUsuarios.py for tasks to queue
[2024-03-04T12:30:01.583+0000] {logging_mixin.py:188} INFO - [2024-03-04T12:30:01.582+0000] {dagbag.py:538} INFO - Filling up the DagBag from /opt/airflow/dags/generarUsuarios.py
[2024-03-04T12:30:01.588+0000] {logging_mixin.py:188} INFO - [2024-03-04T12:30:01.587+0000] {dagbag.py:348} ERROR - Failed to import: /opt/airflow/dags/generarUsuarios.py
Traceback (most recent call last):
  File "/home/airflow/.local/lib/python3.8/site-packages/airflow/models/dagbag.py", line 344, in parse
    loader.exec_module(new_module)
  File "<frozen importlib._bootstrap_external>", line 843, in exec_module
  File "<frozen importlib._bootstrap>", line 219, in _call_with_frames_removed
  File "/opt/airflow/dags/generarUsuarios.py", line 18, in <module>
    'retry_delay': timedelta(minutes=1),
NameError: name 'timedelta' is not defined
[2024-03-04T12:30:01.589+0000] {processor.py:842} WARNING - No viable dags retrieved from /opt/airflow/dags/generarUsuarios.py
[2024-03-04T12:30:01.641+0000] {processor.py:183} INFO - Processing /opt/airflow/dags/generarUsuarios.py took 0.070 seconds
[2024-03-04T12:30:32.049+0000] {processor.py:161} INFO - Started process (PID=28818) to work on /opt/airflow/dags/generarUsuarios.py
[2024-03-04T12:30:32.052+0000] {processor.py:830} INFO - Processing file /opt/airflow/dags/generarUsuarios.py for tasks to queue
[2024-03-04T12:30:32.063+0000] {logging_mixin.py:188} INFO - [2024-03-04T12:30:32.054+0000] {dagbag.py:538} INFO - Filling up the DagBag from /opt/airflow/dags/generarUsuarios.py
[2024-03-04T12:30:32.075+0000] {logging_mixin.py:188} INFO - [2024-03-04T12:30:32.070+0000] {dagbag.py:348} ERROR - Failed to import: /opt/airflow/dags/generarUsuarios.py
Traceback (most recent call last):
  File "/home/airflow/.local/lib/python3.8/site-packages/airflow/models/dagbag.py", line 344, in parse
    loader.exec_module(new_module)
  File "<frozen importlib._bootstrap_external>", line 843, in exec_module
  File "<frozen importlib._bootstrap>", line 219, in _call_with_frames_removed
  File "/opt/airflow/dags/generarUsuarios.py", line 18, in <module>
    'retry_delay': timedelta(minutes=1),
NameError: name 'timedelta' is not defined
[2024-03-04T12:30:32.076+0000] {processor.py:842} WARNING - No viable dags retrieved from /opt/airflow/dags/generarUsuarios.py
[2024-03-04T12:30:32.157+0000] {processor.py:183} INFO - Processing /opt/airflow/dags/generarUsuarios.py took 0.120 seconds
[2024-03-04T12:31:02.476+0000] {processor.py:161} INFO - Started process (PID=28877) to work on /opt/airflow/dags/generarUsuarios.py
[2024-03-04T12:31:02.478+0000] {processor.py:830} INFO - Processing file /opt/airflow/dags/generarUsuarios.py for tasks to queue
[2024-03-04T12:31:02.480+0000] {logging_mixin.py:188} INFO - [2024-03-04T12:31:02.479+0000] {dagbag.py:538} INFO - Filling up the DagBag from /opt/airflow/dags/generarUsuarios.py
[2024-03-04T12:31:02.486+0000] {logging_mixin.py:188} INFO - [2024-03-04T12:31:02.484+0000] {dagbag.py:348} ERROR - Failed to import: /opt/airflow/dags/generarUsuarios.py
Traceback (most recent call last):
  File "/home/airflow/.local/lib/python3.8/site-packages/airflow/models/dagbag.py", line 344, in parse
    loader.exec_module(new_module)
  File "<frozen importlib._bootstrap_external>", line 843, in exec_module
  File "<frozen importlib._bootstrap>", line 219, in _call_with_frames_removed
  File "/opt/airflow/dags/generarUsuarios.py", line 18, in <module>
    'retry_delay': timedelta(minutes=1),
NameError: name 'timedelta' is not defined
[2024-03-04T12:31:02.487+0000] {processor.py:842} WARNING - No viable dags retrieved from /opt/airflow/dags/generarUsuarios.py
[2024-03-04T12:31:02.557+0000] {processor.py:183} INFO - Processing /opt/airflow/dags/generarUsuarios.py took 0.090 seconds
[2024-03-04T12:31:33.494+0000] {processor.py:161} INFO - Started process (PID=28937) to work on /opt/airflow/dags/generarUsuarios.py
[2024-03-04T12:31:33.501+0000] {processor.py:830} INFO - Processing file /opt/airflow/dags/generarUsuarios.py for tasks to queue
[2024-03-04T12:31:33.505+0000] {logging_mixin.py:188} INFO - [2024-03-04T12:31:33.504+0000] {dagbag.py:538} INFO - Filling up the DagBag from /opt/airflow/dags/generarUsuarios.py
[2024-03-04T12:31:33.524+0000] {logging_mixin.py:188} INFO - [2024-03-04T12:31:33.521+0000] {dagbag.py:348} ERROR - Failed to import: /opt/airflow/dags/generarUsuarios.py
Traceback (most recent call last):
  File "/home/airflow/.local/lib/python3.8/site-packages/airflow/models/dagbag.py", line 344, in parse
    loader.exec_module(new_module)
  File "<frozen importlib._bootstrap_external>", line 843, in exec_module
  File "<frozen importlib._bootstrap>", line 219, in _call_with_frames_removed
  File "/opt/airflow/dags/generarUsuarios.py", line 18, in <module>
    'retry_delay': timedelta(minutes=1),
NameError: name 'timedelta' is not defined
[2024-03-04T12:31:33.526+0000] {processor.py:842} WARNING - No viable dags retrieved from /opt/airflow/dags/generarUsuarios.py
[2024-03-04T12:31:33.606+0000] {processor.py:183} INFO - Processing /opt/airflow/dags/generarUsuarios.py took 0.124 seconds
[2024-03-04T12:32:04.104+0000] {processor.py:161} INFO - Started process (PID=28996) to work on /opt/airflow/dags/generarUsuarios.py
[2024-03-04T12:32:04.106+0000] {processor.py:830} INFO - Processing file /opt/airflow/dags/generarUsuarios.py for tasks to queue
[2024-03-04T12:32:04.109+0000] {logging_mixin.py:188} INFO - [2024-03-04T12:32:04.108+0000] {dagbag.py:538} INFO - Filling up the DagBag from /opt/airflow/dags/generarUsuarios.py
[2024-03-04T12:32:04.116+0000] {logging_mixin.py:188} INFO - [2024-03-04T12:32:04.114+0000] {dagbag.py:348} ERROR - Failed to import: /opt/airflow/dags/generarUsuarios.py
Traceback (most recent call last):
  File "/home/airflow/.local/lib/python3.8/site-packages/airflow/models/dagbag.py", line 344, in parse
    loader.exec_module(new_module)
  File "<frozen importlib._bootstrap_external>", line 843, in exec_module
  File "<frozen importlib._bootstrap>", line 219, in _call_with_frames_removed
  File "/opt/airflow/dags/generarUsuarios.py", line 18, in <module>
    'retry_delay': timedelta(minutes=1),
NameError: name 'timedelta' is not defined
[2024-03-04T12:32:04.117+0000] {processor.py:842} WARNING - No viable dags retrieved from /opt/airflow/dags/generarUsuarios.py
[2024-03-04T12:32:04.170+0000] {processor.py:183} INFO - Processing /opt/airflow/dags/generarUsuarios.py took 0.075 seconds
[2024-03-04T12:32:34.327+0000] {processor.py:161} INFO - Started process (PID=29054) to work on /opt/airflow/dags/generarUsuarios.py
[2024-03-04T12:32:34.330+0000] {processor.py:830} INFO - Processing file /opt/airflow/dags/generarUsuarios.py for tasks to queue
[2024-03-04T12:32:34.331+0000] {logging_mixin.py:188} INFO - [2024-03-04T12:32:34.331+0000] {dagbag.py:538} INFO - Filling up the DagBag from /opt/airflow/dags/generarUsuarios.py
[2024-03-04T12:32:34.337+0000] {logging_mixin.py:188} INFO - [2024-03-04T12:32:34.336+0000] {dagbag.py:348} ERROR - Failed to import: /opt/airflow/dags/generarUsuarios.py
Traceback (most recent call last):
  File "/home/airflow/.local/lib/python3.8/site-packages/airflow/models/dagbag.py", line 344, in parse
    loader.exec_module(new_module)
  File "<frozen importlib._bootstrap_external>", line 843, in exec_module
  File "<frozen importlib._bootstrap>", line 219, in _call_with_frames_removed
  File "/opt/airflow/dags/generarUsuarios.py", line 18, in <module>
    'retry_delay': timedelta(minutes=1),
NameError: name 'timedelta' is not defined
[2024-03-04T12:32:34.338+0000] {processor.py:842} WARNING - No viable dags retrieved from /opt/airflow/dags/generarUsuarios.py
[2024-03-04T12:32:34.385+0000] {processor.py:183} INFO - Processing /opt/airflow/dags/generarUsuarios.py took 0.064 seconds
[2024-03-04T12:33:04.473+0000] {processor.py:161} INFO - Started process (PID=29113) to work on /opt/airflow/dags/generarUsuarios.py
[2024-03-04T12:33:04.474+0000] {processor.py:830} INFO - Processing file /opt/airflow/dags/generarUsuarios.py for tasks to queue
[2024-03-04T12:33:04.476+0000] {logging_mixin.py:188} INFO - [2024-03-04T12:33:04.475+0000] {dagbag.py:538} INFO - Filling up the DagBag from /opt/airflow/dags/generarUsuarios.py
[2024-03-04T12:33:04.482+0000] {logging_mixin.py:188} INFO - [2024-03-04T12:33:04.480+0000] {dagbag.py:348} ERROR - Failed to import: /opt/airflow/dags/generarUsuarios.py
Traceback (most recent call last):
  File "/home/airflow/.local/lib/python3.8/site-packages/airflow/models/dagbag.py", line 344, in parse
    loader.exec_module(new_module)
  File "<frozen importlib._bootstrap_external>", line 843, in exec_module
  File "<frozen importlib._bootstrap>", line 219, in _call_with_frames_removed
  File "/opt/airflow/dags/generarUsuarios.py", line 18, in <module>
    'retry_delay': timedelta(minutes=1),
NameError: name 'timedelta' is not defined
[2024-03-04T12:33:04.483+0000] {processor.py:842} WARNING - No viable dags retrieved from /opt/airflow/dags/generarUsuarios.py
[2024-03-04T12:33:04.522+0000] {processor.py:183} INFO - Processing /opt/airflow/dags/generarUsuarios.py took 0.056 seconds
[2024-03-04T12:33:34.578+0000] {processor.py:161} INFO - Started process (PID=29169) to work on /opt/airflow/dags/generarUsuarios.py
[2024-03-04T12:33:34.581+0000] {processor.py:830} INFO - Processing file /opt/airflow/dags/generarUsuarios.py for tasks to queue
[2024-03-04T12:33:34.583+0000] {logging_mixin.py:188} INFO - [2024-03-04T12:33:34.583+0000] {dagbag.py:538} INFO - Filling up the DagBag from /opt/airflow/dags/generarUsuarios.py
[2024-03-04T12:33:34.591+0000] {logging_mixin.py:188} INFO - [2024-03-04T12:33:34.589+0000] {dagbag.py:348} ERROR - Failed to import: /opt/airflow/dags/generarUsuarios.py
Traceback (most recent call last):
  File "/home/airflow/.local/lib/python3.8/site-packages/airflow/models/dagbag.py", line 344, in parse
    loader.exec_module(new_module)
  File "<frozen importlib._bootstrap_external>", line 843, in exec_module
  File "<frozen importlib._bootstrap>", line 219, in _call_with_frames_removed
  File "/opt/airflow/dags/generarUsuarios.py", line 18, in <module>
    'retry_delay': timedelta(minutes=1),
NameError: name 'timedelta' is not defined
[2024-03-04T12:33:34.592+0000] {processor.py:842} WARNING - No viable dags retrieved from /opt/airflow/dags/generarUsuarios.py
[2024-03-04T12:33:34.641+0000] {processor.py:183} INFO - Processing /opt/airflow/dags/generarUsuarios.py took 0.071 seconds
[2024-03-04T12:34:05.056+0000] {processor.py:161} INFO - Started process (PID=29227) to work on /opt/airflow/dags/generarUsuarios.py
[2024-03-04T12:34:05.058+0000] {processor.py:830} INFO - Processing file /opt/airflow/dags/generarUsuarios.py for tasks to queue
[2024-03-04T12:34:05.060+0000] {logging_mixin.py:188} INFO - [2024-03-04T12:34:05.060+0000] {dagbag.py:538} INFO - Filling up the DagBag from /opt/airflow/dags/generarUsuarios.py
[2024-03-04T12:34:05.066+0000] {logging_mixin.py:188} INFO - [2024-03-04T12:34:05.064+0000] {dagbag.py:348} ERROR - Failed to import: /opt/airflow/dags/generarUsuarios.py
Traceback (most recent call last):
  File "/home/airflow/.local/lib/python3.8/site-packages/airflow/models/dagbag.py", line 344, in parse
    loader.exec_module(new_module)
  File "<frozen importlib._bootstrap_external>", line 843, in exec_module
  File "<frozen importlib._bootstrap>", line 219, in _call_with_frames_removed
  File "/opt/airflow/dags/generarUsuarios.py", line 18, in <module>
    'retry_delay': timedelta(minutes=1),
NameError: name 'timedelta' is not defined
[2024-03-04T12:34:05.067+0000] {processor.py:842} WARNING - No viable dags retrieved from /opt/airflow/dags/generarUsuarios.py
[2024-03-04T12:34:05.111+0000] {processor.py:183} INFO - Processing /opt/airflow/dags/generarUsuarios.py took 0.063 seconds
[2024-03-04T12:34:35.532+0000] {processor.py:161} INFO - Started process (PID=29286) to work on /opt/airflow/dags/generarUsuarios.py
[2024-03-04T12:34:35.536+0000] {processor.py:830} INFO - Processing file /opt/airflow/dags/generarUsuarios.py for tasks to queue
[2024-03-04T12:34:35.538+0000] {logging_mixin.py:188} INFO - [2024-03-04T12:34:35.538+0000] {dagbag.py:538} INFO - Filling up the DagBag from /opt/airflow/dags/generarUsuarios.py
[2024-03-04T12:34:35.546+0000] {logging_mixin.py:188} INFO - [2024-03-04T12:34:35.544+0000] {dagbag.py:348} ERROR - Failed to import: /opt/airflow/dags/generarUsuarios.py
Traceback (most recent call last):
  File "/home/airflow/.local/lib/python3.8/site-packages/airflow/models/dagbag.py", line 344, in parse
    loader.exec_module(new_module)
  File "<frozen importlib._bootstrap_external>", line 843, in exec_module
  File "<frozen importlib._bootstrap>", line 219, in _call_with_frames_removed
  File "/opt/airflow/dags/generarUsuarios.py", line 18, in <module>
    'retry_delay': timedelta(minutes=1),
NameError: name 'timedelta' is not defined
[2024-03-04T12:34:35.547+0000] {processor.py:842} WARNING - No viable dags retrieved from /opt/airflow/dags/generarUsuarios.py
[2024-03-04T12:34:35.590+0000] {processor.py:183} INFO - Processing /opt/airflow/dags/generarUsuarios.py took 0.069 seconds
[2024-03-04T12:35:06.164+0000] {processor.py:161} INFO - Started process (PID=29345) to work on /opt/airflow/dags/generarUsuarios.py
[2024-03-04T12:35:06.167+0000] {processor.py:830} INFO - Processing file /opt/airflow/dags/generarUsuarios.py for tasks to queue
[2024-03-04T12:35:06.170+0000] {logging_mixin.py:188} INFO - [2024-03-04T12:35:06.169+0000] {dagbag.py:538} INFO - Filling up the DagBag from /opt/airflow/dags/generarUsuarios.py
[2024-03-04T12:35:06.177+0000] {logging_mixin.py:188} INFO - [2024-03-04T12:35:06.175+0000] {dagbag.py:348} ERROR - Failed to import: /opt/airflow/dags/generarUsuarios.py
Traceback (most recent call last):
  File "/home/airflow/.local/lib/python3.8/site-packages/airflow/models/dagbag.py", line 344, in parse
    loader.exec_module(new_module)
  File "<frozen importlib._bootstrap_external>", line 843, in exec_module
  File "<frozen importlib._bootstrap>", line 219, in _call_with_frames_removed
  File "/opt/airflow/dags/generarUsuarios.py", line 18, in <module>
    'retry_delay': timedelta(minutes=1),
NameError: name 'timedelta' is not defined
[2024-03-04T12:35:06.179+0000] {processor.py:842} WARNING - No viable dags retrieved from /opt/airflow/dags/generarUsuarios.py
[2024-03-04T12:35:06.231+0000] {processor.py:183} INFO - Processing /opt/airflow/dags/generarUsuarios.py took 0.076 seconds
[2024-03-04T12:35:36.670+0000] {processor.py:161} INFO - Started process (PID=29404) to work on /opt/airflow/dags/generarUsuarios.py
[2024-03-04T12:35:36.683+0000] {processor.py:830} INFO - Processing file /opt/airflow/dags/generarUsuarios.py for tasks to queue
[2024-03-04T12:35:36.697+0000] {logging_mixin.py:188} INFO - [2024-03-04T12:35:36.685+0000] {dagbag.py:538} INFO - Filling up the DagBag from /opt/airflow/dags/generarUsuarios.py
[2024-03-04T12:35:36.704+0000] {logging_mixin.py:188} INFO - [2024-03-04T12:35:36.703+0000] {dagbag.py:348} ERROR - Failed to import: /opt/airflow/dags/generarUsuarios.py
Traceback (most recent call last):
  File "/home/airflow/.local/lib/python3.8/site-packages/airflow/models/dagbag.py", line 344, in parse
    loader.exec_module(new_module)
  File "<frozen importlib._bootstrap_external>", line 843, in exec_module
  File "<frozen importlib._bootstrap>", line 219, in _call_with_frames_removed
  File "/opt/airflow/dags/generarUsuarios.py", line 18, in <module>
    'retry_delay': timedelta(minutes=1),
NameError: name 'timedelta' is not defined
[2024-03-04T12:35:36.705+0000] {processor.py:842} WARNING - No viable dags retrieved from /opt/airflow/dags/generarUsuarios.py
[2024-03-04T12:35:36.840+0000] {processor.py:183} INFO - Processing /opt/airflow/dags/generarUsuarios.py took 0.179 seconds
[2024-03-04T12:36:07.314+0000] {processor.py:161} INFO - Started process (PID=29463) to work on /opt/airflow/dags/generarUsuarios.py
[2024-03-04T12:36:07.317+0000] {processor.py:830} INFO - Processing file /opt/airflow/dags/generarUsuarios.py for tasks to queue
[2024-03-04T12:36:07.319+0000] {logging_mixin.py:188} INFO - [2024-03-04T12:36:07.318+0000] {dagbag.py:538} INFO - Filling up the DagBag from /opt/airflow/dags/generarUsuarios.py
[2024-03-04T12:36:07.324+0000] {logging_mixin.py:188} INFO - [2024-03-04T12:36:07.322+0000] {dagbag.py:348} ERROR - Failed to import: /opt/airflow/dags/generarUsuarios.py
Traceback (most recent call last):
  File "/home/airflow/.local/lib/python3.8/site-packages/airflow/models/dagbag.py", line 344, in parse
    loader.exec_module(new_module)
  File "<frozen importlib._bootstrap_external>", line 843, in exec_module
  File "<frozen importlib._bootstrap>", line 219, in _call_with_frames_removed
  File "/opt/airflow/dags/generarUsuarios.py", line 18, in <module>
    'retry_delay': timedelta(minutes=1),
NameError: name 'timedelta' is not defined
[2024-03-04T12:36:07.324+0000] {processor.py:842} WARNING - No viable dags retrieved from /opt/airflow/dags/generarUsuarios.py
[2024-03-04T12:36:07.366+0000] {processor.py:183} INFO - Processing /opt/airflow/dags/generarUsuarios.py took 0.058 seconds
[2024-03-04T12:36:38.171+0000] {processor.py:161} INFO - Started process (PID=29522) to work on /opt/airflow/dags/generarUsuarios.py
[2024-03-04T12:36:38.178+0000] {processor.py:830} INFO - Processing file /opt/airflow/dags/generarUsuarios.py for tasks to queue
[2024-03-04T12:36:38.180+0000] {logging_mixin.py:188} INFO - [2024-03-04T12:36:38.179+0000] {dagbag.py:538} INFO - Filling up the DagBag from /opt/airflow/dags/generarUsuarios.py
[2024-03-04T12:36:38.196+0000] {logging_mixin.py:188} INFO - [2024-03-04T12:36:38.185+0000] {dagbag.py:348} ERROR - Failed to import: /opt/airflow/dags/generarUsuarios.py
Traceback (most recent call last):
  File "/home/airflow/.local/lib/python3.8/site-packages/airflow/models/dagbag.py", line 344, in parse
    loader.exec_module(new_module)
  File "<frozen importlib._bootstrap_external>", line 843, in exec_module
  File "<frozen importlib._bootstrap>", line 219, in _call_with_frames_removed
  File "/opt/airflow/dags/generarUsuarios.py", line 18, in <module>
    'retry_delay': timedelta(minutes=1),
NameError: name 'timedelta' is not defined
[2024-03-04T12:36:38.197+0000] {processor.py:842} WARNING - No viable dags retrieved from /opt/airflow/dags/generarUsuarios.py
[2024-03-04T12:36:38.270+0000] {processor.py:183} INFO - Processing /opt/airflow/dags/generarUsuarios.py took 0.115 seconds
[2024-03-04T12:37:08.734+0000] {processor.py:161} INFO - Started process (PID=29580) to work on /opt/airflow/dags/generarUsuarios.py
[2024-03-04T12:37:08.737+0000] {processor.py:830} INFO - Processing file /opt/airflow/dags/generarUsuarios.py for tasks to queue
[2024-03-04T12:37:08.740+0000] {logging_mixin.py:188} INFO - [2024-03-04T12:37:08.739+0000] {dagbag.py:538} INFO - Filling up the DagBag from /opt/airflow/dags/generarUsuarios.py
[2024-03-04T12:37:08.750+0000] {logging_mixin.py:188} INFO - [2024-03-04T12:37:08.748+0000] {dagbag.py:348} ERROR - Failed to import: /opt/airflow/dags/generarUsuarios.py
Traceback (most recent call last):
  File "/home/airflow/.local/lib/python3.8/site-packages/airflow/models/dagbag.py", line 344, in parse
    loader.exec_module(new_module)
  File "<frozen importlib._bootstrap_external>", line 843, in exec_module
  File "<frozen importlib._bootstrap>", line 219, in _call_with_frames_removed
  File "/opt/airflow/dags/generarUsuarios.py", line 18, in <module>
    'retry_delay': timedelta(minutes=1),
NameError: name 'timedelta' is not defined
[2024-03-04T12:37:08.751+0000] {processor.py:842} WARNING - No viable dags retrieved from /opt/airflow/dags/generarUsuarios.py
[2024-03-04T12:37:08.802+0000] {processor.py:183} INFO - Processing /opt/airflow/dags/generarUsuarios.py took 0.079 seconds
[2024-03-04T12:37:39.502+0000] {processor.py:161} INFO - Started process (PID=29639) to work on /opt/airflow/dags/generarUsuarios.py
[2024-03-04T12:37:39.504+0000] {processor.py:830} INFO - Processing file /opt/airflow/dags/generarUsuarios.py for tasks to queue
[2024-03-04T12:37:39.507+0000] {logging_mixin.py:188} INFO - [2024-03-04T12:37:39.506+0000] {dagbag.py:538} INFO - Filling up the DagBag from /opt/airflow/dags/generarUsuarios.py
[2024-03-04T12:37:39.513+0000] {logging_mixin.py:188} INFO - [2024-03-04T12:37:39.512+0000] {dagbag.py:348} ERROR - Failed to import: /opt/airflow/dags/generarUsuarios.py
Traceback (most recent call last):
  File "/home/airflow/.local/lib/python3.8/site-packages/airflow/models/dagbag.py", line 344, in parse
    loader.exec_module(new_module)
  File "<frozen importlib._bootstrap_external>", line 843, in exec_module
  File "<frozen importlib._bootstrap>", line 219, in _call_with_frames_removed
  File "/opt/airflow/dags/generarUsuarios.py", line 18, in <module>
    'retry_delay': timedelta(minutes=1),
NameError: name 'timedelta' is not defined
[2024-03-04T12:37:39.514+0000] {processor.py:842} WARNING - No viable dags retrieved from /opt/airflow/dags/generarUsuarios.py
[2024-03-04T12:37:39.557+0000] {processor.py:183} INFO - Processing /opt/airflow/dags/generarUsuarios.py took 0.065 seconds
[2024-03-04T12:38:10.376+0000] {processor.py:161} INFO - Started process (PID=29698) to work on /opt/airflow/dags/generarUsuarios.py
[2024-03-04T12:38:10.378+0000] {processor.py:830} INFO - Processing file /opt/airflow/dags/generarUsuarios.py for tasks to queue
[2024-03-04T12:38:10.381+0000] {logging_mixin.py:188} INFO - [2024-03-04T12:38:10.380+0000] {dagbag.py:538} INFO - Filling up the DagBag from /opt/airflow/dags/generarUsuarios.py
[2024-03-04T12:38:10.389+0000] {logging_mixin.py:188} INFO - [2024-03-04T12:38:10.386+0000] {dagbag.py:348} ERROR - Failed to import: /opt/airflow/dags/generarUsuarios.py
Traceback (most recent call last):
  File "/home/airflow/.local/lib/python3.8/site-packages/airflow/models/dagbag.py", line 344, in parse
    loader.exec_module(new_module)
  File "<frozen importlib._bootstrap_external>", line 843, in exec_module
  File "<frozen importlib._bootstrap>", line 219, in _call_with_frames_removed
  File "/opt/airflow/dags/generarUsuarios.py", line 18, in <module>
    'retry_delay': timedelta(minutes=1),
NameError: name 'timedelta' is not defined
[2024-03-04T12:38:10.390+0000] {processor.py:842} WARNING - No viable dags retrieved from /opt/airflow/dags/generarUsuarios.py
[2024-03-04T12:38:10.437+0000] {processor.py:183} INFO - Processing /opt/airflow/dags/generarUsuarios.py took 0.069 seconds
[2024-03-04T12:38:40.493+0000] {processor.py:161} INFO - Started process (PID=29757) to work on /opt/airflow/dags/generarUsuarios.py
[2024-03-04T12:38:40.495+0000] {processor.py:830} INFO - Processing file /opt/airflow/dags/generarUsuarios.py for tasks to queue
[2024-03-04T12:38:40.497+0000] {logging_mixin.py:188} INFO - [2024-03-04T12:38:40.497+0000] {dagbag.py:538} INFO - Filling up the DagBag from /opt/airflow/dags/generarUsuarios.py
[2024-03-04T12:38:40.503+0000] {logging_mixin.py:188} INFO - [2024-03-04T12:38:40.501+0000] {dagbag.py:348} ERROR - Failed to import: /opt/airflow/dags/generarUsuarios.py
Traceback (most recent call last):
  File "/home/airflow/.local/lib/python3.8/site-packages/airflow/models/dagbag.py", line 344, in parse
    loader.exec_module(new_module)
  File "<frozen importlib._bootstrap_external>", line 843, in exec_module
  File "<frozen importlib._bootstrap>", line 219, in _call_with_frames_removed
  File "/opt/airflow/dags/generarUsuarios.py", line 18, in <module>
    'retry_delay': timedelta(minutes=1),
NameError: name 'timedelta' is not defined
[2024-03-04T12:38:40.503+0000] {processor.py:842} WARNING - No viable dags retrieved from /opt/airflow/dags/generarUsuarios.py
[2024-03-04T12:38:40.540+0000] {processor.py:183} INFO - Processing /opt/airflow/dags/generarUsuarios.py took 0.055 seconds
[2024-03-04T12:39:10.929+0000] {processor.py:161} INFO - Started process (PID=29813) to work on /opt/airflow/dags/generarUsuarios.py
[2024-03-04T12:39:10.931+0000] {processor.py:830} INFO - Processing file /opt/airflow/dags/generarUsuarios.py for tasks to queue
[2024-03-04T12:39:10.934+0000] {logging_mixin.py:188} INFO - [2024-03-04T12:39:10.933+0000] {dagbag.py:538} INFO - Filling up the DagBag from /opt/airflow/dags/generarUsuarios.py
[2024-03-04T12:39:10.940+0000] {logging_mixin.py:188} INFO - [2024-03-04T12:39:10.938+0000] {dagbag.py:348} ERROR - Failed to import: /opt/airflow/dags/generarUsuarios.py
Traceback (most recent call last):
  File "/home/airflow/.local/lib/python3.8/site-packages/airflow/models/dagbag.py", line 344, in parse
    loader.exec_module(new_module)
  File "<frozen importlib._bootstrap_external>", line 843, in exec_module
  File "<frozen importlib._bootstrap>", line 219, in _call_with_frames_removed
  File "/opt/airflow/dags/generarUsuarios.py", line 18, in <module>
    'retry_delay': timedelta(minutes=1),
NameError: name 'timedelta' is not defined
[2024-03-04T12:39:10.941+0000] {processor.py:842} WARNING - No viable dags retrieved from /opt/airflow/dags/generarUsuarios.py
[2024-03-04T12:39:10.986+0000] {processor.py:183} INFO - Processing /opt/airflow/dags/generarUsuarios.py took 0.065 seconds
[2024-03-04T12:39:41.849+0000] {processor.py:161} INFO - Started process (PID=29872) to work on /opt/airflow/dags/generarUsuarios.py
[2024-03-04T12:39:41.861+0000] {processor.py:830} INFO - Processing file /opt/airflow/dags/generarUsuarios.py for tasks to queue
[2024-03-04T12:39:41.863+0000] {logging_mixin.py:188} INFO - [2024-03-04T12:39:41.862+0000] {dagbag.py:538} INFO - Filling up the DagBag from /opt/airflow/dags/generarUsuarios.py
[2024-03-04T12:39:41.869+0000] {logging_mixin.py:188} INFO - [2024-03-04T12:39:41.867+0000] {dagbag.py:348} ERROR - Failed to import: /opt/airflow/dags/generarUsuarios.py
Traceback (most recent call last):
  File "/home/airflow/.local/lib/python3.8/site-packages/airflow/models/dagbag.py", line 344, in parse
    loader.exec_module(new_module)
  File "<frozen importlib._bootstrap_external>", line 843, in exec_module
  File "<frozen importlib._bootstrap>", line 219, in _call_with_frames_removed
  File "/opt/airflow/dags/generarUsuarios.py", line 18, in <module>
    'retry_delay': timedelta(minutes=1),
NameError: name 'timedelta' is not defined
[2024-03-04T12:39:41.869+0000] {processor.py:842} WARNING - No viable dags retrieved from /opt/airflow/dags/generarUsuarios.py
[2024-03-04T12:39:41.904+0000] {processor.py:183} INFO - Processing /opt/airflow/dags/generarUsuarios.py took 0.061 seconds
[2024-03-04T12:40:12.249+0000] {processor.py:161} INFO - Started process (PID=29931) to work on /opt/airflow/dags/generarUsuarios.py
[2024-03-04T12:40:12.252+0000] {processor.py:830} INFO - Processing file /opt/airflow/dags/generarUsuarios.py for tasks to queue
[2024-03-04T12:40:12.254+0000] {logging_mixin.py:188} INFO - [2024-03-04T12:40:12.253+0000] {dagbag.py:538} INFO - Filling up the DagBag from /opt/airflow/dags/generarUsuarios.py
[2024-03-04T12:40:12.261+0000] {logging_mixin.py:188} INFO - [2024-03-04T12:40:12.259+0000] {dagbag.py:348} ERROR - Failed to import: /opt/airflow/dags/generarUsuarios.py
Traceback (most recent call last):
  File "/home/airflow/.local/lib/python3.8/site-packages/airflow/models/dagbag.py", line 344, in parse
    loader.exec_module(new_module)
  File "<frozen importlib._bootstrap_external>", line 843, in exec_module
  File "<frozen importlib._bootstrap>", line 219, in _call_with_frames_removed
  File "/opt/airflow/dags/generarUsuarios.py", line 18, in <module>
    'retry_delay': timedelta(minutes=1),
NameError: name 'timedelta' is not defined
[2024-03-04T12:40:12.262+0000] {processor.py:842} WARNING - No viable dags retrieved from /opt/airflow/dags/generarUsuarios.py
[2024-03-04T12:40:12.332+0000] {processor.py:183} INFO - Processing /opt/airflow/dags/generarUsuarios.py took 0.092 seconds
[2024-03-04T12:40:42.596+0000] {processor.py:161} INFO - Started process (PID=29990) to work on /opt/airflow/dags/generarUsuarios.py
[2024-03-04T12:40:42.598+0000] {processor.py:830} INFO - Processing file /opt/airflow/dags/generarUsuarios.py for tasks to queue
[2024-03-04T12:40:42.599+0000] {logging_mixin.py:188} INFO - [2024-03-04T12:40:42.599+0000] {dagbag.py:538} INFO - Filling up the DagBag from /opt/airflow/dags/generarUsuarios.py
[2024-03-04T12:40:42.607+0000] {logging_mixin.py:188} INFO - [2024-03-04T12:40:42.605+0000] {dagbag.py:348} ERROR - Failed to import: /opt/airflow/dags/generarUsuarios.py
Traceback (most recent call last):
  File "/home/airflow/.local/lib/python3.8/site-packages/airflow/models/dagbag.py", line 344, in parse
    loader.exec_module(new_module)
  File "<frozen importlib._bootstrap_external>", line 843, in exec_module
  File "<frozen importlib._bootstrap>", line 219, in _call_with_frames_removed
  File "/opt/airflow/dags/generarUsuarios.py", line 18, in <module>
    'retry_delay': timedelta(minutes=1),
NameError: name 'timedelta' is not defined
[2024-03-04T12:40:42.608+0000] {processor.py:842} WARNING - No viable dags retrieved from /opt/airflow/dags/generarUsuarios.py
[2024-03-04T12:40:42.648+0000] {processor.py:183} INFO - Processing /opt/airflow/dags/generarUsuarios.py took 0.060 seconds
[2024-03-04T12:41:12.701+0000] {processor.py:161} INFO - Started process (PID=30048) to work on /opt/airflow/dags/generarUsuarios.py
[2024-03-04T12:41:12.703+0000] {processor.py:830} INFO - Processing file /opt/airflow/dags/generarUsuarios.py for tasks to queue
[2024-03-04T12:41:12.705+0000] {logging_mixin.py:188} INFO - [2024-03-04T12:41:12.704+0000] {dagbag.py:538} INFO - Filling up the DagBag from /opt/airflow/dags/generarUsuarios.py
[2024-03-04T12:41:12.710+0000] {logging_mixin.py:188} INFO - [2024-03-04T12:41:12.709+0000] {dagbag.py:348} ERROR - Failed to import: /opt/airflow/dags/generarUsuarios.py
Traceback (most recent call last):
  File "/home/airflow/.local/lib/python3.8/site-packages/airflow/models/dagbag.py", line 344, in parse
    loader.exec_module(new_module)
  File "<frozen importlib._bootstrap_external>", line 843, in exec_module
  File "<frozen importlib._bootstrap>", line 219, in _call_with_frames_removed
  File "/opt/airflow/dags/generarUsuarios.py", line 18, in <module>
    'retry_delay': timedelta(minutes=1),
NameError: name 'timedelta' is not defined
[2024-03-04T12:41:12.711+0000] {processor.py:842} WARNING - No viable dags retrieved from /opt/airflow/dags/generarUsuarios.py
[2024-03-04T12:41:12.756+0000] {processor.py:183} INFO - Processing /opt/airflow/dags/generarUsuarios.py took 0.062 seconds
[2024-03-04T12:41:42.924+0000] {processor.py:161} INFO - Started process (PID=30107) to work on /opt/airflow/dags/generarUsuarios.py
[2024-03-04T12:41:42.929+0000] {processor.py:830} INFO - Processing file /opt/airflow/dags/generarUsuarios.py for tasks to queue
[2024-03-04T12:41:42.931+0000] {logging_mixin.py:188} INFO - [2024-03-04T12:41:42.930+0000] {dagbag.py:538} INFO - Filling up the DagBag from /opt/airflow/dags/generarUsuarios.py
[2024-03-04T12:41:42.942+0000] {logging_mixin.py:188} INFO - [2024-03-04T12:41:42.937+0000] {dagbag.py:348} ERROR - Failed to import: /opt/airflow/dags/generarUsuarios.py
Traceback (most recent call last):
  File "/home/airflow/.local/lib/python3.8/site-packages/airflow/models/dagbag.py", line 344, in parse
    loader.exec_module(new_module)
  File "<frozen importlib._bootstrap_external>", line 843, in exec_module
  File "<frozen importlib._bootstrap>", line 219, in _call_with_frames_removed
  File "/opt/airflow/dags/generarUsuarios.py", line 18, in <module>
    'retry_delay': timedelta(minutes=1),
NameError: name 'timedelta' is not defined
[2024-03-04T12:41:42.945+0000] {processor.py:842} WARNING - No viable dags retrieved from /opt/airflow/dags/generarUsuarios.py
[2024-03-04T12:41:43.001+0000] {processor.py:183} INFO - Processing /opt/airflow/dags/generarUsuarios.py took 0.088 seconds
[2024-03-04T12:42:13.286+0000] {processor.py:161} INFO - Started process (PID=30166) to work on /opt/airflow/dags/generarUsuarios.py
[2024-03-04T12:42:13.289+0000] {processor.py:830} INFO - Processing file /opt/airflow/dags/generarUsuarios.py for tasks to queue
[2024-03-04T12:42:13.292+0000] {logging_mixin.py:188} INFO - [2024-03-04T12:42:13.291+0000] {dagbag.py:538} INFO - Filling up the DagBag from /opt/airflow/dags/generarUsuarios.py
[2024-03-04T12:42:13.299+0000] {logging_mixin.py:188} INFO - [2024-03-04T12:42:13.297+0000] {dagbag.py:348} ERROR - Failed to import: /opt/airflow/dags/generarUsuarios.py
Traceback (most recent call last):
  File "/home/airflow/.local/lib/python3.8/site-packages/airflow/models/dagbag.py", line 344, in parse
    loader.exec_module(new_module)
  File "<frozen importlib._bootstrap_external>", line 843, in exec_module
  File "<frozen importlib._bootstrap>", line 219, in _call_with_frames_removed
  File "/opt/airflow/dags/generarUsuarios.py", line 18, in <module>
    'retry_delay': timedelta(minutes=1),
NameError: name 'timedelta' is not defined
[2024-03-04T12:42:13.300+0000] {processor.py:842} WARNING - No viable dags retrieved from /opt/airflow/dags/generarUsuarios.py
[2024-03-04T12:42:13.345+0000] {processor.py:183} INFO - Processing /opt/airflow/dags/generarUsuarios.py took 0.067 seconds
[2024-03-04T12:42:43.627+0000] {processor.py:161} INFO - Started process (PID=30225) to work on /opt/airflow/dags/generarUsuarios.py
[2024-03-04T12:42:43.629+0000] {processor.py:830} INFO - Processing file /opt/airflow/dags/generarUsuarios.py for tasks to queue
[2024-03-04T12:42:43.631+0000] {logging_mixin.py:188} INFO - [2024-03-04T12:42:43.631+0000] {dagbag.py:538} INFO - Filling up the DagBag from /opt/airflow/dags/generarUsuarios.py
[2024-03-04T12:42:43.637+0000] {logging_mixin.py:188} INFO - [2024-03-04T12:42:43.636+0000] {dagbag.py:348} ERROR - Failed to import: /opt/airflow/dags/generarUsuarios.py
Traceback (most recent call last):
  File "/home/airflow/.local/lib/python3.8/site-packages/airflow/models/dagbag.py", line 344, in parse
    loader.exec_module(new_module)
  File "<frozen importlib._bootstrap_external>", line 843, in exec_module
  File "<frozen importlib._bootstrap>", line 219, in _call_with_frames_removed
  File "/opt/airflow/dags/generarUsuarios.py", line 18, in <module>
    'retry_delay': timedelta(minutes=1),
NameError: name 'timedelta' is not defined
[2024-03-04T12:42:43.638+0000] {processor.py:842} WARNING - No viable dags retrieved from /opt/airflow/dags/generarUsuarios.py
[2024-03-04T12:42:43.687+0000] {processor.py:183} INFO - Processing /opt/airflow/dags/generarUsuarios.py took 0.069 seconds
[2024-03-04T12:43:13.869+0000] {processor.py:161} INFO - Started process (PID=30284) to work on /opt/airflow/dags/generarUsuarios.py
[2024-03-04T12:43:13.875+0000] {processor.py:830} INFO - Processing file /opt/airflow/dags/generarUsuarios.py for tasks to queue
[2024-03-04T12:43:13.877+0000] {logging_mixin.py:188} INFO - [2024-03-04T12:43:13.877+0000] {dagbag.py:538} INFO - Filling up the DagBag from /opt/airflow/dags/generarUsuarios.py
[2024-03-04T12:43:13.884+0000] {logging_mixin.py:188} INFO - [2024-03-04T12:43:13.882+0000] {dagbag.py:348} ERROR - Failed to import: /opt/airflow/dags/generarUsuarios.py
Traceback (most recent call last):
  File "/home/airflow/.local/lib/python3.8/site-packages/airflow/models/dagbag.py", line 344, in parse
    loader.exec_module(new_module)
  File "<frozen importlib._bootstrap_external>", line 843, in exec_module
  File "<frozen importlib._bootstrap>", line 219, in _call_with_frames_removed
  File "/opt/airflow/dags/generarUsuarios.py", line 18, in <module>
    'retry_delay': timedelta(minutes=1),
NameError: name 'timedelta' is not defined
[2024-03-04T12:43:13.884+0000] {processor.py:842} WARNING - No viable dags retrieved from /opt/airflow/dags/generarUsuarios.py
[2024-03-04T12:43:13.942+0000] {processor.py:183} INFO - Processing /opt/airflow/dags/generarUsuarios.py took 0.082 seconds
[2024-03-04T12:43:44.739+0000] {processor.py:161} INFO - Started process (PID=30342) to work on /opt/airflow/dags/generarUsuarios.py
[2024-03-04T12:43:44.741+0000] {processor.py:830} INFO - Processing file /opt/airflow/dags/generarUsuarios.py for tasks to queue
[2024-03-04T12:43:44.743+0000] {logging_mixin.py:188} INFO - [2024-03-04T12:43:44.743+0000] {dagbag.py:538} INFO - Filling up the DagBag from /opt/airflow/dags/generarUsuarios.py
[2024-03-04T12:43:44.751+0000] {logging_mixin.py:188} INFO - [2024-03-04T12:43:44.749+0000] {dagbag.py:348} ERROR - Failed to import: /opt/airflow/dags/generarUsuarios.py
Traceback (most recent call last):
  File "/home/airflow/.local/lib/python3.8/site-packages/airflow/models/dagbag.py", line 344, in parse
    loader.exec_module(new_module)
  File "<frozen importlib._bootstrap_external>", line 843, in exec_module
  File "<frozen importlib._bootstrap>", line 219, in _call_with_frames_removed
  File "/opt/airflow/dags/generarUsuarios.py", line 18, in <module>
    'retry_delay': timedelta(minutes=1),
NameError: name 'timedelta' is not defined
[2024-03-04T12:43:44.752+0000] {processor.py:842} WARNING - No viable dags retrieved from /opt/airflow/dags/generarUsuarios.py
[2024-03-04T12:43:44.794+0000] {processor.py:183} INFO - Processing /opt/airflow/dags/generarUsuarios.py took 0.064 seconds
[2024-03-04T12:44:16.448+0000] {processor.py:161} INFO - Started process (PID=30398) to work on /opt/airflow/dags/generarUsuarios.py
[2024-03-04T12:44:16.451+0000] {processor.py:830} INFO - Processing file /opt/airflow/dags/generarUsuarios.py for tasks to queue
[2024-03-04T12:44:16.453+0000] {logging_mixin.py:188} INFO - [2024-03-04T12:44:16.452+0000] {dagbag.py:538} INFO - Filling up the DagBag from /opt/airflow/dags/generarUsuarios.py
[2024-03-04T12:44:16.462+0000] {logging_mixin.py:188} INFO - [2024-03-04T12:44:16.460+0000] {dagbag.py:348} ERROR - Failed to import: /opt/airflow/dags/generarUsuarios.py
Traceback (most recent call last):
  File "/home/airflow/.local/lib/python3.8/site-packages/airflow/models/dagbag.py", line 344, in parse
    loader.exec_module(new_module)
  File "<frozen importlib._bootstrap_external>", line 843, in exec_module
  File "<frozen importlib._bootstrap>", line 219, in _call_with_frames_removed
  File "/opt/airflow/dags/generarUsuarios.py", line 18, in <module>
    'retry_delay': timedelta(minutes=1),
NameError: name 'timedelta' is not defined
[2024-03-04T12:44:16.463+0000] {processor.py:842} WARNING - No viable dags retrieved from /opt/airflow/dags/generarUsuarios.py
[2024-03-04T12:44:16.515+0000] {processor.py:183} INFO - Processing /opt/airflow/dags/generarUsuarios.py took 0.077 seconds
[2024-03-04T12:44:47.286+0000] {processor.py:161} INFO - Started process (PID=30454) to work on /opt/airflow/dags/generarUsuarios.py
[2024-03-04T12:44:47.288+0000] {processor.py:830} INFO - Processing file /opt/airflow/dags/generarUsuarios.py for tasks to queue
[2024-03-04T12:44:47.290+0000] {logging_mixin.py:188} INFO - [2024-03-04T12:44:47.289+0000] {dagbag.py:538} INFO - Filling up the DagBag from /opt/airflow/dags/generarUsuarios.py
[2024-03-04T12:44:47.301+0000] {logging_mixin.py:188} INFO - [2024-03-04T12:44:47.299+0000] {dagbag.py:348} ERROR - Failed to import: /opt/airflow/dags/generarUsuarios.py
Traceback (most recent call last):
  File "/home/airflow/.local/lib/python3.8/site-packages/airflow/models/dagbag.py", line 344, in parse
    loader.exec_module(new_module)
  File "<frozen importlib._bootstrap_external>", line 843, in exec_module
  File "<frozen importlib._bootstrap>", line 219, in _call_with_frames_removed
  File "/opt/airflow/dags/generarUsuarios.py", line 18, in <module>
    'retry_delay': timedelta(minutes=1),
NameError: name 'timedelta' is not defined
[2024-03-04T12:44:47.302+0000] {processor.py:842} WARNING - No viable dags retrieved from /opt/airflow/dags/generarUsuarios.py
[2024-03-04T12:44:47.430+0000] {processor.py:183} INFO - Processing /opt/airflow/dags/generarUsuarios.py took 0.154 seconds
[2024-03-04T12:45:18.174+0000] {processor.py:161} INFO - Started process (PID=30510) to work on /opt/airflow/dags/generarUsuarios.py
[2024-03-04T12:45:18.177+0000] {processor.py:830} INFO - Processing file /opt/airflow/dags/generarUsuarios.py for tasks to queue
[2024-03-04T12:45:18.179+0000] {logging_mixin.py:188} INFO - [2024-03-04T12:45:18.178+0000] {dagbag.py:538} INFO - Filling up the DagBag from /opt/airflow/dags/generarUsuarios.py
[2024-03-04T12:45:18.187+0000] {logging_mixin.py:188} INFO - [2024-03-04T12:45:18.185+0000] {dagbag.py:348} ERROR - Failed to import: /opt/airflow/dags/generarUsuarios.py
Traceback (most recent call last):
  File "/home/airflow/.local/lib/python3.8/site-packages/airflow/models/dagbag.py", line 344, in parse
    loader.exec_module(new_module)
  File "<frozen importlib._bootstrap_external>", line 843, in exec_module
  File "<frozen importlib._bootstrap>", line 219, in _call_with_frames_removed
  File "/opt/airflow/dags/generarUsuarios.py", line 18, in <module>
    'retry_delay': timedelta(minutes=1),
NameError: name 'timedelta' is not defined
[2024-03-04T12:45:18.188+0000] {processor.py:842} WARNING - No viable dags retrieved from /opt/airflow/dags/generarUsuarios.py
[2024-03-04T12:45:18.233+0000] {processor.py:183} INFO - Processing /opt/airflow/dags/generarUsuarios.py took 0.073 seconds
[2024-03-04T12:45:48.682+0000] {processor.py:161} INFO - Started process (PID=30569) to work on /opt/airflow/dags/generarUsuarios.py
[2024-03-04T12:45:48.685+0000] {processor.py:830} INFO - Processing file /opt/airflow/dags/generarUsuarios.py for tasks to queue
[2024-03-04T12:45:48.689+0000] {logging_mixin.py:188} INFO - [2024-03-04T12:45:48.687+0000] {dagbag.py:538} INFO - Filling up the DagBag from /opt/airflow/dags/generarUsuarios.py
[2024-03-04T12:45:48.702+0000] {logging_mixin.py:188} INFO - [2024-03-04T12:45:48.699+0000] {dagbag.py:348} ERROR - Failed to import: /opt/airflow/dags/generarUsuarios.py
Traceback (most recent call last):
  File "/home/airflow/.local/lib/python3.8/site-packages/airflow/models/dagbag.py", line 344, in parse
    loader.exec_module(new_module)
  File "<frozen importlib._bootstrap_external>", line 843, in exec_module
  File "<frozen importlib._bootstrap>", line 219, in _call_with_frames_removed
  File "/opt/airflow/dags/generarUsuarios.py", line 18, in <module>
    'retry_delay': timedelta(minutes=1),
NameError: name 'timedelta' is not defined
[2024-03-04T12:45:48.703+0000] {processor.py:842} WARNING - No viable dags retrieved from /opt/airflow/dags/generarUsuarios.py
[2024-03-04T12:45:48.757+0000] {processor.py:183} INFO - Processing /opt/airflow/dags/generarUsuarios.py took 0.084 seconds
[2024-03-04T12:46:18.930+0000] {processor.py:161} INFO - Started process (PID=30628) to work on /opt/airflow/dags/generarUsuarios.py
[2024-03-04T12:46:18.933+0000] {processor.py:830} INFO - Processing file /opt/airflow/dags/generarUsuarios.py for tasks to queue
[2024-03-04T12:46:18.935+0000] {logging_mixin.py:188} INFO - [2024-03-04T12:46:18.934+0000] {dagbag.py:538} INFO - Filling up the DagBag from /opt/airflow/dags/generarUsuarios.py
[2024-03-04T12:46:18.943+0000] {logging_mixin.py:188} INFO - [2024-03-04T12:46:18.941+0000] {dagbag.py:348} ERROR - Failed to import: /opt/airflow/dags/generarUsuarios.py
Traceback (most recent call last):
  File "/home/airflow/.local/lib/python3.8/site-packages/airflow/models/dagbag.py", line 344, in parse
    loader.exec_module(new_module)
  File "<frozen importlib._bootstrap_external>", line 843, in exec_module
  File "<frozen importlib._bootstrap>", line 219, in _call_with_frames_removed
  File "/opt/airflow/dags/generarUsuarios.py", line 18, in <module>
    'retry_delay': timedelta(minutes=1),
NameError: name 'timedelta' is not defined
[2024-03-04T12:46:18.944+0000] {processor.py:842} WARNING - No viable dags retrieved from /opt/airflow/dags/generarUsuarios.py
[2024-03-04T12:46:18.986+0000] {processor.py:183} INFO - Processing /opt/airflow/dags/generarUsuarios.py took 0.066 seconds
[2024-03-04T12:46:49.873+0000] {processor.py:161} INFO - Started process (PID=30686) to work on /opt/airflow/dags/generarUsuarios.py
[2024-03-04T12:46:49.875+0000] {processor.py:830} INFO - Processing file /opt/airflow/dags/generarUsuarios.py for tasks to queue
[2024-03-04T12:46:49.877+0000] {logging_mixin.py:188} INFO - [2024-03-04T12:46:49.877+0000] {dagbag.py:538} INFO - Filling up the DagBag from /opt/airflow/dags/generarUsuarios.py
[2024-03-04T12:46:49.885+0000] {logging_mixin.py:188} INFO - [2024-03-04T12:46:49.882+0000] {dagbag.py:348} ERROR - Failed to import: /opt/airflow/dags/generarUsuarios.py
Traceback (most recent call last):
  File "/home/airflow/.local/lib/python3.8/site-packages/airflow/models/dagbag.py", line 344, in parse
    loader.exec_module(new_module)
  File "<frozen importlib._bootstrap_external>", line 843, in exec_module
  File "<frozen importlib._bootstrap>", line 219, in _call_with_frames_removed
  File "/opt/airflow/dags/generarUsuarios.py", line 18, in <module>
    'retry_delay': timedelta(minutes=1),
NameError: name 'timedelta' is not defined
[2024-03-04T12:46:49.886+0000] {processor.py:842} WARNING - No viable dags retrieved from /opt/airflow/dags/generarUsuarios.py
[2024-03-04T12:46:49.958+0000] {processor.py:183} INFO - Processing /opt/airflow/dags/generarUsuarios.py took 0.095 seconds
[2024-03-04T12:47:20.129+0000] {processor.py:161} INFO - Started process (PID=30746) to work on /opt/airflow/dags/generarUsuarios.py
[2024-03-04T12:47:20.132+0000] {processor.py:830} INFO - Processing file /opt/airflow/dags/generarUsuarios.py for tasks to queue
[2024-03-04T12:47:20.134+0000] {logging_mixin.py:188} INFO - [2024-03-04T12:47:20.133+0000] {dagbag.py:538} INFO - Filling up the DagBag from /opt/airflow/dags/generarUsuarios.py
[2024-03-04T12:47:20.141+0000] {logging_mixin.py:188} INFO - [2024-03-04T12:47:20.139+0000] {dagbag.py:348} ERROR - Failed to import: /opt/airflow/dags/generarUsuarios.py
Traceback (most recent call last):
  File "/home/airflow/.local/lib/python3.8/site-packages/airflow/models/dagbag.py", line 344, in parse
    loader.exec_module(new_module)
  File "<frozen importlib._bootstrap_external>", line 843, in exec_module
  File "<frozen importlib._bootstrap>", line 219, in _call_with_frames_removed
  File "/opt/airflow/dags/generarUsuarios.py", line 18, in <module>
    'retry_delay': timedelta(minutes=1),
NameError: name 'timedelta' is not defined
[2024-03-04T12:47:20.141+0000] {processor.py:842} WARNING - No viable dags retrieved from /opt/airflow/dags/generarUsuarios.py
[2024-03-04T12:47:20.193+0000] {processor.py:183} INFO - Processing /opt/airflow/dags/generarUsuarios.py took 0.070 seconds
[2024-03-04T12:47:50.475+0000] {processor.py:161} INFO - Started process (PID=30801) to work on /opt/airflow/dags/generarUsuarios.py
[2024-03-04T12:47:50.479+0000] {processor.py:830} INFO - Processing file /opt/airflow/dags/generarUsuarios.py for tasks to queue
[2024-03-04T12:47:50.493+0000] {logging_mixin.py:188} INFO - [2024-03-04T12:47:50.492+0000] {dagbag.py:538} INFO - Filling up the DagBag from /opt/airflow/dags/generarUsuarios.py
[2024-03-04T12:47:50.512+0000] {logging_mixin.py:188} INFO - [2024-03-04T12:47:50.506+0000] {dagbag.py:348} ERROR - Failed to import: /opt/airflow/dags/generarUsuarios.py
Traceback (most recent call last):
  File "/home/airflow/.local/lib/python3.8/site-packages/airflow/models/dagbag.py", line 344, in parse
    loader.exec_module(new_module)
  File "<frozen importlib._bootstrap_external>", line 843, in exec_module
  File "<frozen importlib._bootstrap>", line 219, in _call_with_frames_removed
  File "/opt/airflow/dags/generarUsuarios.py", line 18, in <module>
    'retry_delay': timedelta(minutes=1),
NameError: name 'timedelta' is not defined
[2024-03-04T12:47:50.513+0000] {processor.py:842} WARNING - No viable dags retrieved from /opt/airflow/dags/generarUsuarios.py
[2024-03-04T12:47:50.605+0000] {processor.py:183} INFO - Processing /opt/airflow/dags/generarUsuarios.py took 0.173 seconds
[2024-03-04T12:48:21.092+0000] {processor.py:161} INFO - Started process (PID=30859) to work on /opt/airflow/dags/generarUsuarios.py
[2024-03-04T12:48:21.096+0000] {processor.py:830} INFO - Processing file /opt/airflow/dags/generarUsuarios.py for tasks to queue
[2024-03-04T12:48:21.099+0000] {logging_mixin.py:188} INFO - [2024-03-04T12:48:21.098+0000] {dagbag.py:538} INFO - Filling up the DagBag from /opt/airflow/dags/generarUsuarios.py
[2024-03-04T12:48:21.111+0000] {logging_mixin.py:188} INFO - [2024-03-04T12:48:21.106+0000] {dagbag.py:348} ERROR - Failed to import: /opt/airflow/dags/generarUsuarios.py
Traceback (most recent call last):
  File "/home/airflow/.local/lib/python3.8/site-packages/airflow/models/dagbag.py", line 344, in parse
    loader.exec_module(new_module)
  File "<frozen importlib._bootstrap_external>", line 843, in exec_module
  File "<frozen importlib._bootstrap>", line 219, in _call_with_frames_removed
  File "/opt/airflow/dags/generarUsuarios.py", line 18, in <module>
    'retry_delay': timedelta(minutes=1),
NameError: name 'timedelta' is not defined
[2024-03-04T12:48:21.113+0000] {processor.py:842} WARNING - No viable dags retrieved from /opt/airflow/dags/generarUsuarios.py
[2024-03-04T12:48:21.182+0000] {processor.py:183} INFO - Processing /opt/airflow/dags/generarUsuarios.py took 0.108 seconds
[2024-03-04T12:48:51.294+0000] {processor.py:161} INFO - Started process (PID=30916) to work on /opt/airflow/dags/generarUsuarios.py
[2024-03-04T12:48:51.295+0000] {processor.py:830} INFO - Processing file /opt/airflow/dags/generarUsuarios.py for tasks to queue
[2024-03-04T12:48:51.298+0000] {logging_mixin.py:188} INFO - [2024-03-04T12:48:51.297+0000] {dagbag.py:538} INFO - Filling up the DagBag from /opt/airflow/dags/generarUsuarios.py
[2024-03-04T12:48:51.306+0000] {logging_mixin.py:188} INFO - [2024-03-04T12:48:51.303+0000] {dagbag.py:348} ERROR - Failed to import: /opt/airflow/dags/generarUsuarios.py
Traceback (most recent call last):
  File "/home/airflow/.local/lib/python3.8/site-packages/airflow/models/dagbag.py", line 344, in parse
    loader.exec_module(new_module)
  File "<frozen importlib._bootstrap_external>", line 843, in exec_module
  File "<frozen importlib._bootstrap>", line 219, in _call_with_frames_removed
  File "/opt/airflow/dags/generarUsuarios.py", line 18, in <module>
    'retry_delay': timedelta(minutes=1),
NameError: name 'timedelta' is not defined
[2024-03-04T12:48:51.307+0000] {processor.py:842} WARNING - No viable dags retrieved from /opt/airflow/dags/generarUsuarios.py
[2024-03-04T12:48:51.360+0000] {processor.py:183} INFO - Processing /opt/airflow/dags/generarUsuarios.py took 0.074 seconds
[2024-03-04T12:49:22.086+0000] {processor.py:161} INFO - Started process (PID=30975) to work on /opt/airflow/dags/generarUsuarios.py
[2024-03-04T12:49:22.091+0000] {processor.py:830} INFO - Processing file /opt/airflow/dags/generarUsuarios.py for tasks to queue
[2024-03-04T12:49:22.094+0000] {logging_mixin.py:188} INFO - [2024-03-04T12:49:22.093+0000] {dagbag.py:538} INFO - Filling up the DagBag from /opt/airflow/dags/generarUsuarios.py
[2024-03-04T12:49:22.125+0000] {logging_mixin.py:188} INFO - [2024-03-04T12:49:22.105+0000] {dagbag.py:348} ERROR - Failed to import: /opt/airflow/dags/generarUsuarios.py
Traceback (most recent call last):
  File "/home/airflow/.local/lib/python3.8/site-packages/airflow/models/dagbag.py", line 344, in parse
    loader.exec_module(new_module)
  File "<frozen importlib._bootstrap_external>", line 843, in exec_module
  File "<frozen importlib._bootstrap>", line 219, in _call_with_frames_removed
  File "/opt/airflow/dags/generarUsuarios.py", line 18, in <module>
    'retry_delay': timedelta(minutes=1),
NameError: name 'timedelta' is not defined
[2024-03-04T12:49:22.138+0000] {processor.py:842} WARNING - No viable dags retrieved from /opt/airflow/dags/generarUsuarios.py
[2024-03-04T12:49:22.296+0000] {processor.py:183} INFO - Processing /opt/airflow/dags/generarUsuarios.py took 0.225 seconds
[2024-03-04T12:49:52.556+0000] {processor.py:161} INFO - Started process (PID=31034) to work on /opt/airflow/dags/generarUsuarios.py
[2024-03-04T12:49:52.560+0000] {processor.py:830} INFO - Processing file /opt/airflow/dags/generarUsuarios.py for tasks to queue
[2024-03-04T12:49:52.564+0000] {logging_mixin.py:188} INFO - [2024-03-04T12:49:52.563+0000] {dagbag.py:538} INFO - Filling up the DagBag from /opt/airflow/dags/generarUsuarios.py
[2024-03-04T12:49:52.579+0000] {logging_mixin.py:188} INFO - [2024-03-04T12:49:52.574+0000] {dagbag.py:348} ERROR - Failed to import: /opt/airflow/dags/generarUsuarios.py
Traceback (most recent call last):
  File "/home/airflow/.local/lib/python3.8/site-packages/airflow/models/dagbag.py", line 344, in parse
    loader.exec_module(new_module)
  File "<frozen importlib._bootstrap_external>", line 843, in exec_module
  File "<frozen importlib._bootstrap>", line 219, in _call_with_frames_removed
  File "/opt/airflow/dags/generarUsuarios.py", line 18, in <module>
    'retry_delay': timedelta(minutes=1),
NameError: name 'timedelta' is not defined
[2024-03-04T12:49:52.580+0000] {processor.py:842} WARNING - No viable dags retrieved from /opt/airflow/dags/generarUsuarios.py
[2024-03-04T12:49:52.670+0000] {processor.py:183} INFO - Processing /opt/airflow/dags/generarUsuarios.py took 0.129 seconds
[2024-03-04T12:50:23.493+0000] {processor.py:161} INFO - Started process (PID=31093) to work on /opt/airflow/dags/generarUsuarios.py
[2024-03-04T12:50:23.496+0000] {processor.py:830} INFO - Processing file /opt/airflow/dags/generarUsuarios.py for tasks to queue
[2024-03-04T12:50:23.498+0000] {logging_mixin.py:188} INFO - [2024-03-04T12:50:23.497+0000] {dagbag.py:538} INFO - Filling up the DagBag from /opt/airflow/dags/generarUsuarios.py
[2024-03-04T12:50:23.506+0000] {logging_mixin.py:188} INFO - [2024-03-04T12:50:23.504+0000] {dagbag.py:348} ERROR - Failed to import: /opt/airflow/dags/generarUsuarios.py
Traceback (most recent call last):
  File "/home/airflow/.local/lib/python3.8/site-packages/airflow/models/dagbag.py", line 344, in parse
    loader.exec_module(new_module)
  File "<frozen importlib._bootstrap_external>", line 843, in exec_module
  File "<frozen importlib._bootstrap>", line 219, in _call_with_frames_removed
  File "/opt/airflow/dags/generarUsuarios.py", line 18, in <module>
    'retry_delay': timedelta(minutes=1),
NameError: name 'timedelta' is not defined
[2024-03-04T12:50:23.506+0000] {processor.py:842} WARNING - No viable dags retrieved from /opt/airflow/dags/generarUsuarios.py
[2024-03-04T12:50:23.540+0000] {processor.py:183} INFO - Processing /opt/airflow/dags/generarUsuarios.py took 0.057 seconds
[2024-03-04T12:50:54.226+0000] {processor.py:161} INFO - Started process (PID=31152) to work on /opt/airflow/dags/generarUsuarios.py
[2024-03-04T12:50:54.229+0000] {processor.py:830} INFO - Processing file /opt/airflow/dags/generarUsuarios.py for tasks to queue
[2024-03-04T12:50:54.241+0000] {logging_mixin.py:188} INFO - [2024-03-04T12:50:54.240+0000] {dagbag.py:538} INFO - Filling up the DagBag from /opt/airflow/dags/generarUsuarios.py
[2024-03-04T12:50:54.249+0000] {logging_mixin.py:188} INFO - [2024-03-04T12:50:54.247+0000] {dagbag.py:348} ERROR - Failed to import: /opt/airflow/dags/generarUsuarios.py
Traceback (most recent call last):
  File "/home/airflow/.local/lib/python3.8/site-packages/airflow/models/dagbag.py", line 344, in parse
    loader.exec_module(new_module)
  File "<frozen importlib._bootstrap_external>", line 843, in exec_module
  File "<frozen importlib._bootstrap>", line 219, in _call_with_frames_removed
  File "/opt/airflow/dags/generarUsuarios.py", line 18, in <module>
    'retry_delay': timedelta(minutes=1),
NameError: name 'timedelta' is not defined
[2024-03-04T12:50:54.251+0000] {processor.py:842} WARNING - No viable dags retrieved from /opt/airflow/dags/generarUsuarios.py
[2024-03-04T12:50:54.343+0000] {processor.py:183} INFO - Processing /opt/airflow/dags/generarUsuarios.py took 0.137 seconds
[2024-03-04T12:51:24.811+0000] {processor.py:161} INFO - Started process (PID=31211) to work on /opt/airflow/dags/generarUsuarios.py
[2024-03-04T12:51:24.813+0000] {processor.py:830} INFO - Processing file /opt/airflow/dags/generarUsuarios.py for tasks to queue
[2024-03-04T12:51:24.815+0000] {logging_mixin.py:188} INFO - [2024-03-04T12:51:24.815+0000] {dagbag.py:538} INFO - Filling up the DagBag from /opt/airflow/dags/generarUsuarios.py
[2024-03-04T12:51:24.823+0000] {logging_mixin.py:188} INFO - [2024-03-04T12:51:24.821+0000] {dagbag.py:348} ERROR - Failed to import: /opt/airflow/dags/generarUsuarios.py
Traceback (most recent call last):
  File "/home/airflow/.local/lib/python3.8/site-packages/airflow/models/dagbag.py", line 344, in parse
    loader.exec_module(new_module)
  File "<frozen importlib._bootstrap_external>", line 843, in exec_module
  File "<frozen importlib._bootstrap>", line 219, in _call_with_frames_removed
  File "/opt/airflow/dags/generarUsuarios.py", line 18, in <module>
    'retry_delay': timedelta(minutes=1),
NameError: name 'timedelta' is not defined
[2024-03-04T12:51:24.824+0000] {processor.py:842} WARNING - No viable dags retrieved from /opt/airflow/dags/generarUsuarios.py
[2024-03-04T12:51:24.868+0000] {processor.py:183} INFO - Processing /opt/airflow/dags/generarUsuarios.py took 0.068 seconds
[2024-03-04T12:51:55.610+0000] {processor.py:161} INFO - Started process (PID=31270) to work on /opt/airflow/dags/generarUsuarios.py
[2024-03-04T12:51:55.617+0000] {processor.py:830} INFO - Processing file /opt/airflow/dags/generarUsuarios.py for tasks to queue
[2024-03-04T12:51:55.645+0000] {logging_mixin.py:188} INFO - [2024-03-04T12:51:55.644+0000] {dagbag.py:538} INFO - Filling up the DagBag from /opt/airflow/dags/generarUsuarios.py
[2024-03-04T12:51:55.668+0000] {logging_mixin.py:188} INFO - [2024-03-04T12:51:55.666+0000] {dagbag.py:348} ERROR - Failed to import: /opt/airflow/dags/generarUsuarios.py
Traceback (most recent call last):
  File "/home/airflow/.local/lib/python3.8/site-packages/airflow/models/dagbag.py", line 344, in parse
    loader.exec_module(new_module)
  File "<frozen importlib._bootstrap_external>", line 843, in exec_module
  File "<frozen importlib._bootstrap>", line 219, in _call_with_frames_removed
  File "/opt/airflow/dags/generarUsuarios.py", line 18, in <module>
    'retry_delay': timedelta(minutes=1),
NameError: name 'timedelta' is not defined
[2024-03-04T12:51:55.671+0000] {processor.py:842} WARNING - No viable dags retrieved from /opt/airflow/dags/generarUsuarios.py
[2024-03-04T12:51:55.803+0000] {processor.py:183} INFO - Processing /opt/airflow/dags/generarUsuarios.py took 0.224 seconds
[2024-03-04T12:52:25.984+0000] {processor.py:161} INFO - Started process (PID=31328) to work on /opt/airflow/dags/generarUsuarios.py
[2024-03-04T12:52:25.986+0000] {processor.py:830} INFO - Processing file /opt/airflow/dags/generarUsuarios.py for tasks to queue
[2024-03-04T12:52:25.988+0000] {logging_mixin.py:188} INFO - [2024-03-04T12:52:25.987+0000] {dagbag.py:538} INFO - Filling up the DagBag from /opt/airflow/dags/generarUsuarios.py
[2024-03-04T12:52:25.994+0000] {logging_mixin.py:188} INFO - [2024-03-04T12:52:25.992+0000] {dagbag.py:348} ERROR - Failed to import: /opt/airflow/dags/generarUsuarios.py
Traceback (most recent call last):
  File "/home/airflow/.local/lib/python3.8/site-packages/airflow/models/dagbag.py", line 344, in parse
    loader.exec_module(new_module)
  File "<frozen importlib._bootstrap_external>", line 843, in exec_module
  File "<frozen importlib._bootstrap>", line 219, in _call_with_frames_removed
  File "/opt/airflow/dags/generarUsuarios.py", line 18, in <module>
    'retry_delay': timedelta(minutes=1),
NameError: name 'timedelta' is not defined
[2024-03-04T12:52:25.995+0000] {processor.py:842} WARNING - No viable dags retrieved from /opt/airflow/dags/generarUsuarios.py
[2024-03-04T12:52:26.042+0000] {processor.py:183} INFO - Processing /opt/airflow/dags/generarUsuarios.py took 0.066 seconds
[2024-03-04T12:52:56.502+0000] {processor.py:161} INFO - Started process (PID=31386) to work on /opt/airflow/dags/generarUsuarios.py
[2024-03-04T12:52:56.504+0000] {processor.py:830} INFO - Processing file /opt/airflow/dags/generarUsuarios.py for tasks to queue
[2024-03-04T12:52:56.506+0000] {logging_mixin.py:188} INFO - [2024-03-04T12:52:56.505+0000] {dagbag.py:538} INFO - Filling up the DagBag from /opt/airflow/dags/generarUsuarios.py
[2024-03-04T12:52:56.512+0000] {logging_mixin.py:188} INFO - [2024-03-04T12:52:56.510+0000] {dagbag.py:348} ERROR - Failed to import: /opt/airflow/dags/generarUsuarios.py
Traceback (most recent call last):
  File "/home/airflow/.local/lib/python3.8/site-packages/airflow/models/dagbag.py", line 344, in parse
    loader.exec_module(new_module)
  File "<frozen importlib._bootstrap_external>", line 843, in exec_module
  File "<frozen importlib._bootstrap>", line 219, in _call_with_frames_removed
  File "/opt/airflow/dags/generarUsuarios.py", line 18, in <module>
    'retry_delay': timedelta(minutes=1),
NameError: name 'timedelta' is not defined
[2024-03-04T12:52:56.513+0000] {processor.py:842} WARNING - No viable dags retrieved from /opt/airflow/dags/generarUsuarios.py
[2024-03-04T12:52:56.548+0000] {processor.py:183} INFO - Processing /opt/airflow/dags/generarUsuarios.py took 0.057 seconds
[2024-03-04T12:53:27.192+0000] {processor.py:161} INFO - Started process (PID=31451) to work on /opt/airflow/dags/generarUsuarios.py
[2024-03-04T12:53:27.216+0000] {processor.py:830} INFO - Processing file /opt/airflow/dags/generarUsuarios.py for tasks to queue
[2024-03-04T12:53:27.219+0000] {logging_mixin.py:188} INFO - [2024-03-04T12:53:27.218+0000] {dagbag.py:538} INFO - Filling up the DagBag from /opt/airflow/dags/generarUsuarios.py
[2024-03-04T12:53:27.241+0000] {logging_mixin.py:188} INFO - [2024-03-04T12:53:27.225+0000] {dagbag.py:348} ERROR - Failed to import: /opt/airflow/dags/generarUsuarios.py
Traceback (most recent call last):
  File "/home/airflow/.local/lib/python3.8/site-packages/airflow/models/dagbag.py", line 344, in parse
    loader.exec_module(new_module)
  File "<frozen importlib._bootstrap_external>", line 843, in exec_module
  File "<frozen importlib._bootstrap>", line 219, in _call_with_frames_removed
  File "/opt/airflow/dags/generarUsuarios.py", line 18, in <module>
    'retry_delay': timedelta(minutes=1),
NameError: name 'timedelta' is not defined
[2024-03-04T12:53:27.242+0000] {processor.py:842} WARNING - No viable dags retrieved from /opt/airflow/dags/generarUsuarios.py
[2024-03-04T12:53:27.326+0000] {processor.py:183} INFO - Processing /opt/airflow/dags/generarUsuarios.py took 0.146 seconds
[2024-03-04T12:53:57.972+0000] {processor.py:161} INFO - Started process (PID=31510) to work on /opt/airflow/dags/generarUsuarios.py
[2024-03-04T12:53:57.974+0000] {processor.py:830} INFO - Processing file /opt/airflow/dags/generarUsuarios.py for tasks to queue
[2024-03-04T12:53:57.975+0000] {logging_mixin.py:188} INFO - [2024-03-04T12:53:57.975+0000] {dagbag.py:538} INFO - Filling up the DagBag from /opt/airflow/dags/generarUsuarios.py
[2024-03-04T12:53:57.981+0000] {logging_mixin.py:188} INFO - [2024-03-04T12:53:57.980+0000] {dagbag.py:348} ERROR - Failed to import: /opt/airflow/dags/generarUsuarios.py
Traceback (most recent call last):
  File "/home/airflow/.local/lib/python3.8/site-packages/airflow/models/dagbag.py", line 344, in parse
    loader.exec_module(new_module)
  File "<frozen importlib._bootstrap_external>", line 843, in exec_module
  File "<frozen importlib._bootstrap>", line 219, in _call_with_frames_removed
  File "/opt/airflow/dags/generarUsuarios.py", line 18, in <module>
    'retry_delay': timedelta(minutes=1),
NameError: name 'timedelta' is not defined
[2024-03-04T12:53:57.982+0000] {processor.py:842} WARNING - No viable dags retrieved from /opt/airflow/dags/generarUsuarios.py
[2024-03-04T12:53:58.016+0000] {processor.py:183} INFO - Processing /opt/airflow/dags/generarUsuarios.py took 0.051 seconds
[2024-03-04T12:54:28.874+0000] {processor.py:161} INFO - Started process (PID=31570) to work on /opt/airflow/dags/generarUsuarios.py
[2024-03-04T12:54:28.877+0000] {processor.py:830} INFO - Processing file /opt/airflow/dags/generarUsuarios.py for tasks to queue
[2024-03-04T12:54:28.879+0000] {logging_mixin.py:188} INFO - [2024-03-04T12:54:28.878+0000] {dagbag.py:538} INFO - Filling up the DagBag from /opt/airflow/dags/generarUsuarios.py
[2024-03-04T12:54:28.884+0000] {logging_mixin.py:188} INFO - [2024-03-04T12:54:28.882+0000] {dagbag.py:348} ERROR - Failed to import: /opt/airflow/dags/generarUsuarios.py
Traceback (most recent call last):
  File "/home/airflow/.local/lib/python3.8/site-packages/airflow/models/dagbag.py", line 344, in parse
    loader.exec_module(new_module)
  File "<frozen importlib._bootstrap_external>", line 843, in exec_module
  File "<frozen importlib._bootstrap>", line 219, in _call_with_frames_removed
  File "/opt/airflow/dags/generarUsuarios.py", line 18, in <module>
    'retry_delay': timedelta(minutes=1),
NameError: name 'timedelta' is not defined
[2024-03-04T12:54:28.885+0000] {processor.py:842} WARNING - No viable dags retrieved from /opt/airflow/dags/generarUsuarios.py
[2024-03-04T12:54:28.928+0000] {processor.py:183} INFO - Processing /opt/airflow/dags/generarUsuarios.py took 0.068 seconds
[2024-03-04T12:54:59.073+0000] {processor.py:161} INFO - Started process (PID=31629) to work on /opt/airflow/dags/generarUsuarios.py
[2024-03-04T12:54:59.076+0000] {processor.py:830} INFO - Processing file /opt/airflow/dags/generarUsuarios.py for tasks to queue
[2024-03-04T12:54:59.079+0000] {logging_mixin.py:188} INFO - [2024-03-04T12:54:59.078+0000] {dagbag.py:538} INFO - Filling up the DagBag from /opt/airflow/dags/generarUsuarios.py
[2024-03-04T12:54:59.087+0000] {logging_mixin.py:188} INFO - [2024-03-04T12:54:59.084+0000] {dagbag.py:348} ERROR - Failed to import: /opt/airflow/dags/generarUsuarios.py
Traceback (most recent call last):
  File "/home/airflow/.local/lib/python3.8/site-packages/airflow/models/dagbag.py", line 344, in parse
    loader.exec_module(new_module)
  File "<frozen importlib._bootstrap_external>", line 843, in exec_module
  File "<frozen importlib._bootstrap>", line 219, in _call_with_frames_removed
  File "/opt/airflow/dags/generarUsuarios.py", line 18, in <module>
    'retry_delay': timedelta(minutes=1),
NameError: name 'timedelta' is not defined
[2024-03-04T12:54:59.088+0000] {processor.py:842} WARNING - No viable dags retrieved from /opt/airflow/dags/generarUsuarios.py
[2024-03-04T12:54:59.134+0000] {processor.py:183} INFO - Processing /opt/airflow/dags/generarUsuarios.py took 0.070 seconds
[2024-03-04T12:55:29.542+0000] {processor.py:161} INFO - Started process (PID=31688) to work on /opt/airflow/dags/generarUsuarios.py
[2024-03-04T12:55:29.543+0000] {processor.py:830} INFO - Processing file /opt/airflow/dags/generarUsuarios.py for tasks to queue
[2024-03-04T12:55:29.546+0000] {logging_mixin.py:188} INFO - [2024-03-04T12:55:29.545+0000] {dagbag.py:538} INFO - Filling up the DagBag from /opt/airflow/dags/generarUsuarios.py
[2024-03-04T12:55:29.552+0000] {logging_mixin.py:188} INFO - [2024-03-04T12:55:29.550+0000] {dagbag.py:348} ERROR - Failed to import: /opt/airflow/dags/generarUsuarios.py
Traceback (most recent call last):
  File "/home/airflow/.local/lib/python3.8/site-packages/airflow/models/dagbag.py", line 344, in parse
    loader.exec_module(new_module)
  File "<frozen importlib._bootstrap_external>", line 843, in exec_module
  File "<frozen importlib._bootstrap>", line 219, in _call_with_frames_removed
  File "/opt/airflow/dags/generarUsuarios.py", line 18, in <module>
    'retry_delay': timedelta(minutes=1),
NameError: name 'timedelta' is not defined
[2024-03-04T12:55:29.553+0000] {processor.py:842} WARNING - No viable dags retrieved from /opt/airflow/dags/generarUsuarios.py
[2024-03-04T12:55:29.593+0000] {processor.py:183} INFO - Processing /opt/airflow/dags/generarUsuarios.py took 0.058 seconds
[2024-03-04T12:56:00.394+0000] {processor.py:161} INFO - Started process (PID=31747) to work on /opt/airflow/dags/generarUsuarios.py
[2024-03-04T12:56:00.411+0000] {processor.py:830} INFO - Processing file /opt/airflow/dags/generarUsuarios.py for tasks to queue
[2024-03-04T12:56:00.414+0000] {logging_mixin.py:188} INFO - [2024-03-04T12:56:00.413+0000] {dagbag.py:538} INFO - Filling up the DagBag from /opt/airflow/dags/generarUsuarios.py
[2024-03-04T12:56:00.420+0000] {logging_mixin.py:188} INFO - [2024-03-04T12:56:00.419+0000] {dagbag.py:348} ERROR - Failed to import: /opt/airflow/dags/generarUsuarios.py
Traceback (most recent call last):
  File "/home/airflow/.local/lib/python3.8/site-packages/airflow/models/dagbag.py", line 344, in parse
    loader.exec_module(new_module)
  File "<frozen importlib._bootstrap_external>", line 843, in exec_module
  File "<frozen importlib._bootstrap>", line 219, in _call_with_frames_removed
  File "/opt/airflow/dags/generarUsuarios.py", line 18, in <module>
    'retry_delay': timedelta(minutes=1),
NameError: name 'timedelta' is not defined
[2024-03-04T12:56:00.422+0000] {processor.py:842} WARNING - No viable dags retrieved from /opt/airflow/dags/generarUsuarios.py
[2024-03-04T12:56:00.469+0000] {processor.py:183} INFO - Processing /opt/airflow/dags/generarUsuarios.py took 0.084 seconds
[2024-03-04T12:56:31.205+0000] {processor.py:161} INFO - Started process (PID=31804) to work on /opt/airflow/dags/generarUsuarios.py
[2024-03-04T12:56:31.206+0000] {processor.py:830} INFO - Processing file /opt/airflow/dags/generarUsuarios.py for tasks to queue
[2024-03-04T12:56:31.208+0000] {logging_mixin.py:188} INFO - [2024-03-04T12:56:31.207+0000] {dagbag.py:538} INFO - Filling up the DagBag from /opt/airflow/dags/generarUsuarios.py
[2024-03-04T12:56:31.213+0000] {logging_mixin.py:188} INFO - [2024-03-04T12:56:31.212+0000] {dagbag.py:348} ERROR - Failed to import: /opt/airflow/dags/generarUsuarios.py
Traceback (most recent call last):
  File "/home/airflow/.local/lib/python3.8/site-packages/airflow/models/dagbag.py", line 344, in parse
    loader.exec_module(new_module)
  File "<frozen importlib._bootstrap_external>", line 843, in exec_module
  File "<frozen importlib._bootstrap>", line 219, in _call_with_frames_removed
  File "/opt/airflow/dags/generarUsuarios.py", line 18, in <module>
    'retry_delay': timedelta(minutes=1),
NameError: name 'timedelta' is not defined
[2024-03-04T12:56:31.214+0000] {processor.py:842} WARNING - No viable dags retrieved from /opt/airflow/dags/generarUsuarios.py
[2024-03-04T12:56:31.272+0000] {processor.py:183} INFO - Processing /opt/airflow/dags/generarUsuarios.py took 0.076 seconds
[2024-03-04T12:57:01.624+0000] {processor.py:161} INFO - Started process (PID=31864) to work on /opt/airflow/dags/generarUsuarios.py
[2024-03-04T12:57:01.627+0000] {processor.py:830} INFO - Processing file /opt/airflow/dags/generarUsuarios.py for tasks to queue
[2024-03-04T12:57:01.628+0000] {logging_mixin.py:188} INFO - [2024-03-04T12:57:01.628+0000] {dagbag.py:538} INFO - Filling up the DagBag from /opt/airflow/dags/generarUsuarios.py
[2024-03-04T12:57:01.634+0000] {logging_mixin.py:188} INFO - [2024-03-04T12:57:01.633+0000] {dagbag.py:348} ERROR - Failed to import: /opt/airflow/dags/generarUsuarios.py
Traceback (most recent call last):
  File "/home/airflow/.local/lib/python3.8/site-packages/airflow/models/dagbag.py", line 344, in parse
    loader.exec_module(new_module)
  File "<frozen importlib._bootstrap_external>", line 843, in exec_module
  File "<frozen importlib._bootstrap>", line 219, in _call_with_frames_removed
  File "/opt/airflow/dags/generarUsuarios.py", line 18, in <module>
    'retry_delay': timedelta(minutes=1),
NameError: name 'timedelta' is not defined
[2024-03-04T12:57:01.635+0000] {processor.py:842} WARNING - No viable dags retrieved from /opt/airflow/dags/generarUsuarios.py
[2024-03-04T12:57:01.686+0000] {processor.py:183} INFO - Processing /opt/airflow/dags/generarUsuarios.py took 0.068 seconds
[2024-03-04T12:57:31.885+0000] {processor.py:161} INFO - Started process (PID=31923) to work on /opt/airflow/dags/generarUsuarios.py
[2024-03-04T12:57:31.887+0000] {processor.py:830} INFO - Processing file /opt/airflow/dags/generarUsuarios.py for tasks to queue
[2024-03-04T12:57:31.890+0000] {logging_mixin.py:188} INFO - [2024-03-04T12:57:31.889+0000] {dagbag.py:538} INFO - Filling up the DagBag from /opt/airflow/dags/generarUsuarios.py
[2024-03-04T12:57:31.901+0000] {logging_mixin.py:188} INFO - [2024-03-04T12:57:31.896+0000] {dagbag.py:348} ERROR - Failed to import: /opt/airflow/dags/generarUsuarios.py
Traceback (most recent call last):
  File "/home/airflow/.local/lib/python3.8/site-packages/airflow/models/dagbag.py", line 344, in parse
    loader.exec_module(new_module)
  File "<frozen importlib._bootstrap_external>", line 843, in exec_module
  File "<frozen importlib._bootstrap>", line 219, in _call_with_frames_removed
  File "/opt/airflow/dags/generarUsuarios.py", line 18, in <module>
    'retry_delay': timedelta(minutes=1),
NameError: name 'timedelta' is not defined
[2024-03-04T12:57:31.902+0000] {processor.py:842} WARNING - No viable dags retrieved from /opt/airflow/dags/generarUsuarios.py
[2024-03-04T12:57:31.936+0000] {processor.py:183} INFO - Processing /opt/airflow/dags/generarUsuarios.py took 0.060 seconds
[2024-03-04T12:58:02.260+0000] {processor.py:161} INFO - Started process (PID=31983) to work on /opt/airflow/dags/generarUsuarios.py
[2024-03-04T12:58:02.263+0000] {processor.py:830} INFO - Processing file /opt/airflow/dags/generarUsuarios.py for tasks to queue
[2024-03-04T12:58:02.264+0000] {logging_mixin.py:188} INFO - [2024-03-04T12:58:02.264+0000] {dagbag.py:538} INFO - Filling up the DagBag from /opt/airflow/dags/generarUsuarios.py
[2024-03-04T12:58:02.271+0000] {logging_mixin.py:188} INFO - [2024-03-04T12:58:02.269+0000] {dagbag.py:348} ERROR - Failed to import: /opt/airflow/dags/generarUsuarios.py
Traceback (most recent call last):
  File "/home/airflow/.local/lib/python3.8/site-packages/airflow/models/dagbag.py", line 344, in parse
    loader.exec_module(new_module)
  File "<frozen importlib._bootstrap_external>", line 843, in exec_module
  File "<frozen importlib._bootstrap>", line 219, in _call_with_frames_removed
  File "/opt/airflow/dags/generarUsuarios.py", line 18, in <module>
    'retry_delay': timedelta(minutes=1),
NameError: name 'timedelta' is not defined
[2024-03-04T12:58:02.271+0000] {processor.py:842} WARNING - No viable dags retrieved from /opt/airflow/dags/generarUsuarios.py
[2024-03-04T12:58:02.311+0000] {processor.py:183} INFO - Processing /opt/airflow/dags/generarUsuarios.py took 0.059 seconds
[2024-03-04T12:58:32.542+0000] {processor.py:161} INFO - Started process (PID=32042) to work on /opt/airflow/dags/generarUsuarios.py
[2024-03-04T12:58:32.544+0000] {processor.py:830} INFO - Processing file /opt/airflow/dags/generarUsuarios.py for tasks to queue
[2024-03-04T12:58:32.545+0000] {logging_mixin.py:188} INFO - [2024-03-04T12:58:32.545+0000] {dagbag.py:538} INFO - Filling up the DagBag from /opt/airflow/dags/generarUsuarios.py
[2024-03-04T12:58:32.550+0000] {logging_mixin.py:188} INFO - [2024-03-04T12:58:32.549+0000] {dagbag.py:348} ERROR - Failed to import: /opt/airflow/dags/generarUsuarios.py
Traceback (most recent call last):
  File "/home/airflow/.local/lib/python3.8/site-packages/airflow/models/dagbag.py", line 344, in parse
    loader.exec_module(new_module)
  File "<frozen importlib._bootstrap_external>", line 843, in exec_module
  File "<frozen importlib._bootstrap>", line 219, in _call_with_frames_removed
  File "/opt/airflow/dags/generarUsuarios.py", line 18, in <module>
    'retry_delay': timedelta(minutes=1),
NameError: name 'timedelta' is not defined
[2024-03-04T12:58:32.551+0000] {processor.py:842} WARNING - No viable dags retrieved from /opt/airflow/dags/generarUsuarios.py
[2024-03-04T12:58:32.612+0000] {processor.py:183} INFO - Processing /opt/airflow/dags/generarUsuarios.py took 0.077 seconds
[2024-03-04T12:59:03.516+0000] {processor.py:161} INFO - Started process (PID=32101) to work on /opt/airflow/dags/generarUsuarios.py
[2024-03-04T12:59:03.519+0000] {processor.py:830} INFO - Processing file /opt/airflow/dags/generarUsuarios.py for tasks to queue
[2024-03-04T12:59:03.521+0000] {logging_mixin.py:188} INFO - [2024-03-04T12:59:03.520+0000] {dagbag.py:538} INFO - Filling up the DagBag from /opt/airflow/dags/generarUsuarios.py
[2024-03-04T12:59:03.527+0000] {logging_mixin.py:188} INFO - [2024-03-04T12:59:03.526+0000] {dagbag.py:348} ERROR - Failed to import: /opt/airflow/dags/generarUsuarios.py
Traceback (most recent call last):
  File "/home/airflow/.local/lib/python3.8/site-packages/airflow/models/dagbag.py", line 344, in parse
    loader.exec_module(new_module)
  File "<frozen importlib._bootstrap_external>", line 843, in exec_module
  File "<frozen importlib._bootstrap>", line 219, in _call_with_frames_removed
  File "/opt/airflow/dags/generarUsuarios.py", line 18, in <module>
    'retry_delay': timedelta(minutes=1),
NameError: name 'timedelta' is not defined
[2024-03-04T12:59:03.528+0000] {processor.py:842} WARNING - No viable dags retrieved from /opt/airflow/dags/generarUsuarios.py
[2024-03-04T12:59:03.573+0000] {processor.py:183} INFO - Processing /opt/airflow/dags/generarUsuarios.py took 0.066 seconds
[2024-03-04T12:59:33.944+0000] {processor.py:161} INFO - Started process (PID=32160) to work on /opt/airflow/dags/generarUsuarios.py
[2024-03-04T12:59:33.946+0000] {processor.py:830} INFO - Processing file /opt/airflow/dags/generarUsuarios.py for tasks to queue
[2024-03-04T12:59:33.948+0000] {logging_mixin.py:188} INFO - [2024-03-04T12:59:33.947+0000] {dagbag.py:538} INFO - Filling up the DagBag from /opt/airflow/dags/generarUsuarios.py
[2024-03-04T12:59:33.956+0000] {logging_mixin.py:188} INFO - [2024-03-04T12:59:33.954+0000] {dagbag.py:348} ERROR - Failed to import: /opt/airflow/dags/generarUsuarios.py
Traceback (most recent call last):
  File "/home/airflow/.local/lib/python3.8/site-packages/airflow/models/dagbag.py", line 344, in parse
    loader.exec_module(new_module)
  File "<frozen importlib._bootstrap_external>", line 843, in exec_module
  File "<frozen importlib._bootstrap>", line 219, in _call_with_frames_removed
  File "/opt/airflow/dags/generarUsuarios.py", line 18, in <module>
    'retry_delay': timedelta(minutes=1),
NameError: name 'timedelta' is not defined
[2024-03-04T12:59:33.956+0000] {processor.py:842} WARNING - No viable dags retrieved from /opt/airflow/dags/generarUsuarios.py
[2024-03-04T12:59:33.990+0000] {processor.py:183} INFO - Processing /opt/airflow/dags/generarUsuarios.py took 0.054 seconds
[2024-03-04T13:00:04.918+0000] {processor.py:161} INFO - Started process (PID=32218) to work on /opt/airflow/dags/generarUsuarios.py
[2024-03-04T13:00:04.928+0000] {processor.py:830} INFO - Processing file /opt/airflow/dags/generarUsuarios.py for tasks to queue
[2024-03-04T13:00:04.931+0000] {logging_mixin.py:188} INFO - [2024-03-04T13:00:04.930+0000] {dagbag.py:538} INFO - Filling up the DagBag from /opt/airflow/dags/generarUsuarios.py
[2024-03-04T13:00:04.943+0000] {logging_mixin.py:188} INFO - [2024-03-04T13:00:04.941+0000] {dagbag.py:348} ERROR - Failed to import: /opt/airflow/dags/generarUsuarios.py
Traceback (most recent call last):
  File "/home/airflow/.local/lib/python3.8/site-packages/airflow/models/dagbag.py", line 344, in parse
    loader.exec_module(new_module)
  File "<frozen importlib._bootstrap_external>", line 843, in exec_module
  File "<frozen importlib._bootstrap>", line 219, in _call_with_frames_removed
  File "/opt/airflow/dags/generarUsuarios.py", line 18, in <module>
    'retry_delay': timedelta(minutes=1),
NameError: name 'timedelta' is not defined
[2024-03-04T13:00:04.944+0000] {processor.py:842} WARNING - No viable dags retrieved from /opt/airflow/dags/generarUsuarios.py
[2024-03-04T13:00:05.015+0000] {processor.py:183} INFO - Processing /opt/airflow/dags/generarUsuarios.py took 0.108 seconds
[2024-03-04T13:00:35.555+0000] {processor.py:161} INFO - Started process (PID=32277) to work on /opt/airflow/dags/generarUsuarios.py
[2024-03-04T13:00:35.558+0000] {processor.py:830} INFO - Processing file /opt/airflow/dags/generarUsuarios.py for tasks to queue
[2024-03-04T13:00:35.560+0000] {logging_mixin.py:188} INFO - [2024-03-04T13:00:35.559+0000] {dagbag.py:538} INFO - Filling up the DagBag from /opt/airflow/dags/generarUsuarios.py
[2024-03-04T13:00:35.565+0000] {logging_mixin.py:188} INFO - [2024-03-04T13:00:35.564+0000] {dagbag.py:348} ERROR - Failed to import: /opt/airflow/dags/generarUsuarios.py
Traceback (most recent call last):
  File "/home/airflow/.local/lib/python3.8/site-packages/airflow/models/dagbag.py", line 344, in parse
    loader.exec_module(new_module)
  File "<frozen importlib._bootstrap_external>", line 843, in exec_module
  File "<frozen importlib._bootstrap>", line 219, in _call_with_frames_removed
  File "/opt/airflow/dags/generarUsuarios.py", line 18, in <module>
    'retry_delay': timedelta(minutes=1),
NameError: name 'timedelta' is not defined
[2024-03-04T13:00:35.566+0000] {processor.py:842} WARNING - No viable dags retrieved from /opt/airflow/dags/generarUsuarios.py
[2024-03-04T13:00:35.613+0000] {processor.py:183} INFO - Processing /opt/airflow/dags/generarUsuarios.py took 0.067 seconds
[2024-03-04T13:01:07.701+0000] {processor.py:161} INFO - Started process (PID=32328) to work on /opt/airflow/dags/generarUsuarios.py
[2024-03-04T13:01:07.703+0000] {processor.py:830} INFO - Processing file /opt/airflow/dags/generarUsuarios.py for tasks to queue
[2024-03-04T13:01:07.705+0000] {logging_mixin.py:188} INFO - [2024-03-04T13:01:07.704+0000] {dagbag.py:538} INFO - Filling up the DagBag from /opt/airflow/dags/generarUsuarios.py
[2024-03-04T13:01:07.729+0000] {processor.py:840} INFO - DAG(s) 'registro_usuarios_dag' retrieved from /opt/airflow/dags/generarUsuarios.py
[2024-03-04T13:01:08.227+0000] {logging_mixin.py:188} INFO - [2024-03-04T13:01:08.225+0000] {override.py:1769} INFO - Created Permission View: can edit on DAG:registro_usuarios_dag
[2024-03-04T13:01:08.271+0000] {logging_mixin.py:188} INFO - [2024-03-04T13:01:08.270+0000] {override.py:1769} INFO - Created Permission View: can read on DAG:registro_usuarios_dag
[2024-03-04T13:01:08.297+0000] {logging_mixin.py:188} INFO - [2024-03-04T13:01:08.296+0000] {override.py:1769} INFO - Created Permission View: can delete on DAG:registro_usuarios_dag
[2024-03-04T13:01:08.298+0000] {logging_mixin.py:188} INFO - [2024-03-04T13:01:08.297+0000] {dag.py:3036} INFO - Sync 1 DAGs
[2024-03-04T13:01:08.362+0000] {logging_mixin.py:188} INFO - [2024-03-04T13:01:08.359+0000] {dag.py:3058} INFO - Creating ORM DAG for registro_usuarios_dag
[2024-03-04T13:01:08.399+0000] {logging_mixin.py:188} INFO - [2024-03-04T13:01:08.398+0000] {dag.py:3823} INFO - Setting next_dagrun for registro_usuarios_dag to 2024-02-28 12:00:00+00:00, run_after=2024-02-29 12:00:00+00:00
[2024-03-04T13:01:08.454+0000] {processor.py:183} INFO - Processing /opt/airflow/dags/generarUsuarios.py took 0.763 seconds
