[2024-03-04T12:02:03.707+0000] {processor.py:161} INFO - Started process (PID=25555) to work on /opt/airflow/dags/generarUsuarios.py
[2024-03-04T12:02:03.710+0000] {processor.py:830} INFO - Processing file /opt/airflow/dags/generarUsuarios.py for tasks to queue
[2024-03-04T12:02:03.715+0000] {logging_mixin.py:188} INFO - [2024-03-04T12:02:03.714+0000] {dagbag.py:538} INFO - Filling up the DagBag from /opt/airflow/dags/generarUsuarios.py
[2024-03-04T12:02:03.739+0000] {logging_mixin.py:188} INFO - [2024-03-04T12:02:03.725+0000] {dagbag.py:348} ERROR - Failed to import: /opt/airflow/dags/generarUsuarios.py
Traceback (most recent call last):
  File "/home/airflow/.local/lib/python3.8/site-packages/airflow/models/dagbag.py", line 344, in parse
    loader.exec_module(new_module)
  File "<frozen importlib._bootstrap_external>", line 843, in exec_module
  File "<frozen importlib._bootstrap>", line 219, in _call_with_frames_removed
  File "/opt/airflow/dags/generarUsuarios.py", line 13, in <module>
    'retry_delay': timedelta(minutes=1),
NameError: name 'timedelta' is not defined
[2024-03-04T12:02:03.741+0000] {processor.py:842} WARNING - No viable dags retrieved from /opt/airflow/dags/generarUsuarios.py
[2024-03-04T12:02:03.814+0000] {processor.py:183} INFO - Processing /opt/airflow/dags/generarUsuarios.py took 0.118 seconds
[2024-03-04T12:02:33.895+0000] {processor.py:161} INFO - Started process (PID=25613) to work on /opt/airflow/dags/generarUsuarios.py
[2024-03-04T12:02:33.897+0000] {processor.py:830} INFO - Processing file /opt/airflow/dags/generarUsuarios.py for tasks to queue
[2024-03-04T12:02:33.907+0000] {logging_mixin.py:188} INFO - [2024-03-04T12:02:33.901+0000] {dagbag.py:538} INFO - Filling up the DagBag from /opt/airflow/dags/generarUsuarios.py
[2024-03-04T12:02:33.918+0000] {logging_mixin.py:188} INFO - [2024-03-04T12:02:33.915+0000] {dagbag.py:348} ERROR - Failed to import: /opt/airflow/dags/generarUsuarios.py
Traceback (most recent call last):
  File "/home/airflow/.local/lib/python3.8/site-packages/airflow/models/dagbag.py", line 344, in parse
    loader.exec_module(new_module)
  File "<frozen importlib._bootstrap_external>", line 843, in exec_module
  File "<frozen importlib._bootstrap>", line 219, in _call_with_frames_removed
  File "/opt/airflow/dags/generarUsuarios.py", line 13, in <module>
    'retry_delay': timedelta(minutes=1),
NameError: name 'timedelta' is not defined
[2024-03-04T12:02:33.919+0000] {processor.py:842} WARNING - No viable dags retrieved from /opt/airflow/dags/generarUsuarios.py
[2024-03-04T12:02:33.976+0000] {processor.py:183} INFO - Processing /opt/airflow/dags/generarUsuarios.py took 0.092 seconds
[2024-03-04T12:03:04.149+0000] {processor.py:161} INFO - Started process (PID=25671) to work on /opt/airflow/dags/generarUsuarios.py
[2024-03-04T12:03:04.153+0000] {processor.py:830} INFO - Processing file /opt/airflow/dags/generarUsuarios.py for tasks to queue
[2024-03-04T12:03:04.161+0000] {logging_mixin.py:188} INFO - [2024-03-04T12:03:04.158+0000] {dagbag.py:538} INFO - Filling up the DagBag from /opt/airflow/dags/generarUsuarios.py
[2024-03-04T12:03:04.171+0000] {logging_mixin.py:188} INFO - [2024-03-04T12:03:04.168+0000] {dagbag.py:348} ERROR - Failed to import: /opt/airflow/dags/generarUsuarios.py
Traceback (most recent call last):
  File "/home/airflow/.local/lib/python3.8/site-packages/airflow/models/dagbag.py", line 344, in parse
    loader.exec_module(new_module)
  File "<frozen importlib._bootstrap_external>", line 843, in exec_module
  File "<frozen importlib._bootstrap>", line 219, in _call_with_frames_removed
  File "/opt/airflow/dags/generarUsuarios.py", line 13, in <module>
    'retry_delay': timedelta(minutes=1),
NameError: name 'timedelta' is not defined
[2024-03-04T12:03:04.172+0000] {processor.py:842} WARNING - No viable dags retrieved from /opt/airflow/dags/generarUsuarios.py
[2024-03-04T12:03:04.250+0000] {processor.py:183} INFO - Processing /opt/airflow/dags/generarUsuarios.py took 0.110 seconds
[2024-03-04T12:03:34.864+0000] {processor.py:161} INFO - Started process (PID=25729) to work on /opt/airflow/dags/generarUsuarios.py
[2024-03-04T12:03:34.866+0000] {processor.py:830} INFO - Processing file /opt/airflow/dags/generarUsuarios.py for tasks to queue
[2024-03-04T12:03:34.883+0000] {logging_mixin.py:188} INFO - [2024-03-04T12:03:34.881+0000] {dagbag.py:538} INFO - Filling up the DagBag from /opt/airflow/dags/generarUsuarios.py
[2024-03-04T12:03:34.906+0000] {logging_mixin.py:188} INFO - [2024-03-04T12:03:34.902+0000] {dagbag.py:348} ERROR - Failed to import: /opt/airflow/dags/generarUsuarios.py
Traceback (most recent call last):
  File "/home/airflow/.local/lib/python3.8/site-packages/airflow/models/dagbag.py", line 344, in parse
    loader.exec_module(new_module)
  File "<frozen importlib._bootstrap_external>", line 843, in exec_module
  File "<frozen importlib._bootstrap>", line 219, in _call_with_frames_removed
  File "/opt/airflow/dags/generarUsuarios.py", line 18, in <module>
    'retry_delay': timedelta(minutes=1),
NameError: name 'timedelta' is not defined
[2024-03-04T12:03:34.914+0000] {processor.py:842} WARNING - No viable dags retrieved from /opt/airflow/dags/generarUsuarios.py
[2024-03-04T12:03:35.020+0000] {processor.py:183} INFO - Processing /opt/airflow/dags/generarUsuarios.py took 0.189 seconds
[2024-03-04T12:04:05.493+0000] {processor.py:161} INFO - Started process (PID=25787) to work on /opt/airflow/dags/generarUsuarios.py
[2024-03-04T12:04:05.495+0000] {processor.py:830} INFO - Processing file /opt/airflow/dags/generarUsuarios.py for tasks to queue
[2024-03-04T12:04:05.498+0000] {logging_mixin.py:188} INFO - [2024-03-04T12:04:05.498+0000] {dagbag.py:538} INFO - Filling up the DagBag from /opt/airflow/dags/generarUsuarios.py
[2024-03-04T12:04:05.504+0000] {logging_mixin.py:188} INFO - [2024-03-04T12:04:05.503+0000] {dagbag.py:348} ERROR - Failed to import: /opt/airflow/dags/generarUsuarios.py
Traceback (most recent call last):
  File "/home/airflow/.local/lib/python3.8/site-packages/airflow/models/dagbag.py", line 344, in parse
    loader.exec_module(new_module)
  File "<frozen importlib._bootstrap_external>", line 843, in exec_module
  File "<frozen importlib._bootstrap>", line 219, in _call_with_frames_removed
  File "/opt/airflow/dags/generarUsuarios.py", line 18, in <module>
    'retry_delay': timedelta(minutes=1),
NameError: name 'timedelta' is not defined
[2024-03-04T12:04:05.505+0000] {processor.py:842} WARNING - No viable dags retrieved from /opt/airflow/dags/generarUsuarios.py
[2024-03-04T12:04:05.542+0000] {processor.py:183} INFO - Processing /opt/airflow/dags/generarUsuarios.py took 0.064 seconds
[2024-03-04T12:04:35.698+0000] {processor.py:161} INFO - Started process (PID=25846) to work on /opt/airflow/dags/generarUsuarios.py
[2024-03-04T12:04:35.707+0000] {processor.py:830} INFO - Processing file /opt/airflow/dags/generarUsuarios.py for tasks to queue
[2024-03-04T12:04:35.711+0000] {logging_mixin.py:188} INFO - [2024-03-04T12:04:35.710+0000] {dagbag.py:538} INFO - Filling up the DagBag from /opt/airflow/dags/generarUsuarios.py
[2024-03-04T12:04:35.720+0000] {logging_mixin.py:188} INFO - [2024-03-04T12:04:35.717+0000] {dagbag.py:348} ERROR - Failed to import: /opt/airflow/dags/generarUsuarios.py
Traceback (most recent call last):
  File "/home/airflow/.local/lib/python3.8/site-packages/airflow/models/dagbag.py", line 344, in parse
    loader.exec_module(new_module)
  File "<frozen importlib._bootstrap_external>", line 843, in exec_module
  File "<frozen importlib._bootstrap>", line 219, in _call_with_frames_removed
  File "/opt/airflow/dags/generarUsuarios.py", line 18, in <module>
    'retry_delay': timedelta(minutes=1),
NameError: name 'timedelta' is not defined
[2024-03-04T12:04:35.721+0000] {processor.py:842} WARNING - No viable dags retrieved from /opt/airflow/dags/generarUsuarios.py
[2024-03-04T12:04:35.773+0000] {processor.py:183} INFO - Processing /opt/airflow/dags/generarUsuarios.py took 0.092 seconds
[2024-03-04T12:05:06.025+0000] {processor.py:161} INFO - Started process (PID=25902) to work on /opt/airflow/dags/generarUsuarios.py
[2024-03-04T12:05:06.073+0000] {processor.py:830} INFO - Processing file /opt/airflow/dags/generarUsuarios.py for tasks to queue
[2024-03-04T12:05:06.089+0000] {logging_mixin.py:188} INFO - [2024-03-04T12:05:06.088+0000] {dagbag.py:538} INFO - Filling up the DagBag from /opt/airflow/dags/generarUsuarios.py
[2024-03-04T12:05:06.111+0000] {logging_mixin.py:188} INFO - [2024-03-04T12:05:06.097+0000] {dagbag.py:348} ERROR - Failed to import: /opt/airflow/dags/generarUsuarios.py
Traceback (most recent call last):
  File "/home/airflow/.local/lib/python3.8/site-packages/airflow/models/dagbag.py", line 344, in parse
    loader.exec_module(new_module)
  File "<frozen importlib._bootstrap_external>", line 843, in exec_module
  File "<frozen importlib._bootstrap>", line 219, in _call_with_frames_removed
  File "/opt/airflow/dags/generarUsuarios.py", line 18, in <module>
    'retry_delay': timedelta(minutes=1),
NameError: name 'timedelta' is not defined
[2024-03-04T12:05:06.112+0000] {processor.py:842} WARNING - No viable dags retrieved from /opt/airflow/dags/generarUsuarios.py
[2024-03-04T12:05:06.196+0000] {processor.py:183} INFO - Processing /opt/airflow/dags/generarUsuarios.py took 0.192 seconds
[2024-03-04T12:05:36.631+0000] {processor.py:161} INFO - Started process (PID=25960) to work on /opt/airflow/dags/generarUsuarios.py
[2024-03-04T12:05:36.635+0000] {processor.py:830} INFO - Processing file /opt/airflow/dags/generarUsuarios.py for tasks to queue
[2024-03-04T12:05:36.640+0000] {logging_mixin.py:188} INFO - [2024-03-04T12:05:36.639+0000] {dagbag.py:538} INFO - Filling up the DagBag from /opt/airflow/dags/generarUsuarios.py
[2024-03-04T12:05:36.654+0000] {logging_mixin.py:188} INFO - [2024-03-04T12:05:36.650+0000] {dagbag.py:348} ERROR - Failed to import: /opt/airflow/dags/generarUsuarios.py
Traceback (most recent call last):
  File "/home/airflow/.local/lib/python3.8/site-packages/airflow/models/dagbag.py", line 344, in parse
    loader.exec_module(new_module)
  File "<frozen importlib._bootstrap_external>", line 843, in exec_module
  File "<frozen importlib._bootstrap>", line 219, in _call_with_frames_removed
  File "/opt/airflow/dags/generarUsuarios.py", line 18, in <module>
    'retry_delay': timedelta(minutes=1),
NameError: name 'timedelta' is not defined
[2024-03-04T12:05:36.655+0000] {processor.py:842} WARNING - No viable dags retrieved from /opt/airflow/dags/generarUsuarios.py
[2024-03-04T12:05:36.758+0000] {processor.py:183} INFO - Processing /opt/airflow/dags/generarUsuarios.py took 0.140 seconds
[2024-03-04T12:06:06.881+0000] {processor.py:161} INFO - Started process (PID=26018) to work on /opt/airflow/dags/generarUsuarios.py
[2024-03-04T12:06:06.884+0000] {processor.py:830} INFO - Processing file /opt/airflow/dags/generarUsuarios.py for tasks to queue
[2024-03-04T12:06:06.899+0000] {logging_mixin.py:188} INFO - [2024-03-04T12:06:06.898+0000] {dagbag.py:538} INFO - Filling up the DagBag from /opt/airflow/dags/generarUsuarios.py
[2024-03-04T12:06:06.929+0000] {logging_mixin.py:188} INFO - [2024-03-04T12:06:06.916+0000] {dagbag.py:348} ERROR - Failed to import: /opt/airflow/dags/generarUsuarios.py
Traceback (most recent call last):
  File "/home/airflow/.local/lib/python3.8/site-packages/airflow/models/dagbag.py", line 344, in parse
    loader.exec_module(new_module)
  File "<frozen importlib._bootstrap_external>", line 843, in exec_module
  File "<frozen importlib._bootstrap>", line 219, in _call_with_frames_removed
  File "/opt/airflow/dags/generarUsuarios.py", line 18, in <module>
    'retry_delay': timedelta(minutes=1),
NameError: name 'timedelta' is not defined
[2024-03-04T12:06:06.930+0000] {processor.py:842} WARNING - No viable dags retrieved from /opt/airflow/dags/generarUsuarios.py
[2024-03-04T12:06:07.038+0000] {processor.py:183} INFO - Processing /opt/airflow/dags/generarUsuarios.py took 0.185 seconds
[2024-03-04T12:06:37.203+0000] {processor.py:161} INFO - Started process (PID=26075) to work on /opt/airflow/dags/generarUsuarios.py
[2024-03-04T12:06:37.205+0000] {processor.py:830} INFO - Processing file /opt/airflow/dags/generarUsuarios.py for tasks to queue
[2024-03-04T12:06:37.210+0000] {logging_mixin.py:188} INFO - [2024-03-04T12:06:37.209+0000] {dagbag.py:538} INFO - Filling up the DagBag from /opt/airflow/dags/generarUsuarios.py
[2024-03-04T12:06:37.218+0000] {logging_mixin.py:188} INFO - [2024-03-04T12:06:37.215+0000] {dagbag.py:348} ERROR - Failed to import: /opt/airflow/dags/generarUsuarios.py
Traceback (most recent call last):
  File "/home/airflow/.local/lib/python3.8/site-packages/airflow/models/dagbag.py", line 344, in parse
    loader.exec_module(new_module)
  File "<frozen importlib._bootstrap_external>", line 843, in exec_module
  File "<frozen importlib._bootstrap>", line 219, in _call_with_frames_removed
  File "/opt/airflow/dags/generarUsuarios.py", line 18, in <module>
    'retry_delay': timedelta(minutes=1),
NameError: name 'timedelta' is not defined
[2024-03-04T12:06:37.219+0000] {processor.py:842} WARNING - No viable dags retrieved from /opt/airflow/dags/generarUsuarios.py
[2024-03-04T12:06:37.313+0000] {processor.py:183} INFO - Processing /opt/airflow/dags/generarUsuarios.py took 0.118 seconds
[2024-03-04T12:07:07.473+0000] {processor.py:161} INFO - Started process (PID=26133) to work on /opt/airflow/dags/generarUsuarios.py
[2024-03-04T12:07:07.474+0000] {processor.py:830} INFO - Processing file /opt/airflow/dags/generarUsuarios.py for tasks to queue
[2024-03-04T12:07:07.479+0000] {logging_mixin.py:188} INFO - [2024-03-04T12:07:07.478+0000] {dagbag.py:538} INFO - Filling up the DagBag from /opt/airflow/dags/generarUsuarios.py
[2024-03-04T12:07:07.487+0000] {logging_mixin.py:188} INFO - [2024-03-04T12:07:07.484+0000] {dagbag.py:348} ERROR - Failed to import: /opt/airflow/dags/generarUsuarios.py
Traceback (most recent call last):
  File "/home/airflow/.local/lib/python3.8/site-packages/airflow/models/dagbag.py", line 344, in parse
    loader.exec_module(new_module)
  File "<frozen importlib._bootstrap_external>", line 843, in exec_module
  File "<frozen importlib._bootstrap>", line 219, in _call_with_frames_removed
  File "/opt/airflow/dags/generarUsuarios.py", line 18, in <module>
    'retry_delay': timedelta(minutes=1),
NameError: name 'timedelta' is not defined
[2024-03-04T12:07:07.488+0000] {processor.py:842} WARNING - No viable dags retrieved from /opt/airflow/dags/generarUsuarios.py
[2024-03-04T12:07:07.524+0000] {processor.py:183} INFO - Processing /opt/airflow/dags/generarUsuarios.py took 0.058 seconds
[2024-03-04T12:07:37.806+0000] {processor.py:161} INFO - Started process (PID=26191) to work on /opt/airflow/dags/generarUsuarios.py
[2024-03-04T12:07:37.809+0000] {processor.py:830} INFO - Processing file /opt/airflow/dags/generarUsuarios.py for tasks to queue
[2024-03-04T12:07:37.814+0000] {logging_mixin.py:188} INFO - [2024-03-04T12:07:37.813+0000] {dagbag.py:538} INFO - Filling up the DagBag from /opt/airflow/dags/generarUsuarios.py
[2024-03-04T12:07:37.820+0000] {logging_mixin.py:188} INFO - [2024-03-04T12:07:37.819+0000] {dagbag.py:348} ERROR - Failed to import: /opt/airflow/dags/generarUsuarios.py
Traceback (most recent call last):
  File "/home/airflow/.local/lib/python3.8/site-packages/airflow/models/dagbag.py", line 344, in parse
    loader.exec_module(new_module)
  File "<frozen importlib._bootstrap_external>", line 843, in exec_module
  File "<frozen importlib._bootstrap>", line 219, in _call_with_frames_removed
  File "/opt/airflow/dags/generarUsuarios.py", line 18, in <module>
    'retry_delay': timedelta(minutes=1),
NameError: name 'timedelta' is not defined
[2024-03-04T12:07:37.821+0000] {processor.py:842} WARNING - No viable dags retrieved from /opt/airflow/dags/generarUsuarios.py
[2024-03-04T12:07:37.862+0000] {processor.py:183} INFO - Processing /opt/airflow/dags/generarUsuarios.py took 0.063 seconds
[2024-03-04T12:08:08.372+0000] {processor.py:161} INFO - Started process (PID=26248) to work on /opt/airflow/dags/generarUsuarios.py
[2024-03-04T12:08:08.376+0000] {processor.py:830} INFO - Processing file /opt/airflow/dags/generarUsuarios.py for tasks to queue
[2024-03-04T12:08:08.380+0000] {logging_mixin.py:188} INFO - [2024-03-04T12:08:08.379+0000] {dagbag.py:538} INFO - Filling up the DagBag from /opt/airflow/dags/generarUsuarios.py
[2024-03-04T12:08:08.387+0000] {logging_mixin.py:188} INFO - [2024-03-04T12:08:08.385+0000] {dagbag.py:348} ERROR - Failed to import: /opt/airflow/dags/generarUsuarios.py
Traceback (most recent call last):
  File "/home/airflow/.local/lib/python3.8/site-packages/airflow/models/dagbag.py", line 344, in parse
    loader.exec_module(new_module)
  File "<frozen importlib._bootstrap_external>", line 843, in exec_module
  File "<frozen importlib._bootstrap>", line 219, in _call_with_frames_removed
  File "/opt/airflow/dags/generarUsuarios.py", line 18, in <module>
    'retry_delay': timedelta(minutes=1),
NameError: name 'timedelta' is not defined
[2024-03-04T12:08:08.387+0000] {processor.py:842} WARNING - No viable dags retrieved from /opt/airflow/dags/generarUsuarios.py
[2024-03-04T12:08:08.438+0000] {processor.py:183} INFO - Processing /opt/airflow/dags/generarUsuarios.py took 0.074 seconds
[2024-03-04T12:08:38.746+0000] {processor.py:161} INFO - Started process (PID=26306) to work on /opt/airflow/dags/generarUsuarios.py
[2024-03-04T12:08:38.749+0000] {processor.py:830} INFO - Processing file /opt/airflow/dags/generarUsuarios.py for tasks to queue
[2024-03-04T12:08:38.754+0000] {logging_mixin.py:188} INFO - [2024-03-04T12:08:38.753+0000] {dagbag.py:538} INFO - Filling up the DagBag from /opt/airflow/dags/generarUsuarios.py
[2024-03-04T12:08:38.760+0000] {logging_mixin.py:188} INFO - [2024-03-04T12:08:38.759+0000] {dagbag.py:348} ERROR - Failed to import: /opt/airflow/dags/generarUsuarios.py
Traceback (most recent call last):
  File "/home/airflow/.local/lib/python3.8/site-packages/airflow/models/dagbag.py", line 344, in parse
    loader.exec_module(new_module)
  File "<frozen importlib._bootstrap_external>", line 843, in exec_module
  File "<frozen importlib._bootstrap>", line 219, in _call_with_frames_removed
  File "/opt/airflow/dags/generarUsuarios.py", line 18, in <module>
    'retry_delay': timedelta(minutes=1),
NameError: name 'timedelta' is not defined
[2024-03-04T12:08:38.761+0000] {processor.py:842} WARNING - No viable dags retrieved from /opt/airflow/dags/generarUsuarios.py
[2024-03-04T12:08:38.833+0000] {processor.py:183} INFO - Processing /opt/airflow/dags/generarUsuarios.py took 0.097 seconds
[2024-03-04T12:09:09.662+0000] {processor.py:161} INFO - Started process (PID=26364) to work on /opt/airflow/dags/generarUsuarios.py
[2024-03-04T12:09:09.676+0000] {processor.py:830} INFO - Processing file /opt/airflow/dags/generarUsuarios.py for tasks to queue
[2024-03-04T12:09:09.684+0000] {logging_mixin.py:188} INFO - [2024-03-04T12:09:09.682+0000] {dagbag.py:538} INFO - Filling up the DagBag from /opt/airflow/dags/generarUsuarios.py
[2024-03-04T12:09:09.695+0000] {logging_mixin.py:188} INFO - [2024-03-04T12:09:09.690+0000] {dagbag.py:348} ERROR - Failed to import: /opt/airflow/dags/generarUsuarios.py
Traceback (most recent call last):
  File "/home/airflow/.local/lib/python3.8/site-packages/airflow/models/dagbag.py", line 344, in parse
    loader.exec_module(new_module)
  File "<frozen importlib._bootstrap_external>", line 843, in exec_module
  File "<frozen importlib._bootstrap>", line 219, in _call_with_frames_removed
  File "/opt/airflow/dags/generarUsuarios.py", line 18, in <module>
    'retry_delay': timedelta(minutes=1),
NameError: name 'timedelta' is not defined
[2024-03-04T12:09:09.696+0000] {processor.py:842} WARNING - No viable dags retrieved from /opt/airflow/dags/generarUsuarios.py
[2024-03-04T12:09:09.758+0000] {processor.py:183} INFO - Processing /opt/airflow/dags/generarUsuarios.py took 0.105 seconds
[2024-03-04T12:09:40.193+0000] {processor.py:161} INFO - Started process (PID=26422) to work on /opt/airflow/dags/generarUsuarios.py
[2024-03-04T12:09:40.195+0000] {processor.py:830} INFO - Processing file /opt/airflow/dags/generarUsuarios.py for tasks to queue
[2024-03-04T12:09:40.200+0000] {logging_mixin.py:188} INFO - [2024-03-04T12:09:40.199+0000] {dagbag.py:538} INFO - Filling up the DagBag from /opt/airflow/dags/generarUsuarios.py
[2024-03-04T12:09:40.208+0000] {logging_mixin.py:188} INFO - [2024-03-04T12:09:40.205+0000] {dagbag.py:348} ERROR - Failed to import: /opt/airflow/dags/generarUsuarios.py
Traceback (most recent call last):
  File "/home/airflow/.local/lib/python3.8/site-packages/airflow/models/dagbag.py", line 344, in parse
    loader.exec_module(new_module)
  File "<frozen importlib._bootstrap_external>", line 843, in exec_module
  File "<frozen importlib._bootstrap>", line 219, in _call_with_frames_removed
  File "/opt/airflow/dags/generarUsuarios.py", line 18, in <module>
    'retry_delay': timedelta(minutes=1),
NameError: name 'timedelta' is not defined
[2024-03-04T12:09:40.209+0000] {processor.py:842} WARNING - No viable dags retrieved from /opt/airflow/dags/generarUsuarios.py
[2024-03-04T12:09:40.260+0000] {processor.py:183} INFO - Processing /opt/airflow/dags/generarUsuarios.py took 0.074 seconds
[2024-03-04T12:10:10.497+0000] {processor.py:161} INFO - Started process (PID=26480) to work on /opt/airflow/dags/generarUsuarios.py
[2024-03-04T12:10:10.499+0000] {processor.py:830} INFO - Processing file /opt/airflow/dags/generarUsuarios.py for tasks to queue
[2024-03-04T12:10:10.503+0000] {logging_mixin.py:188} INFO - [2024-03-04T12:10:10.503+0000] {dagbag.py:538} INFO - Filling up the DagBag from /opt/airflow/dags/generarUsuarios.py
[2024-03-04T12:10:10.510+0000] {logging_mixin.py:188} INFO - [2024-03-04T12:10:10.508+0000] {dagbag.py:348} ERROR - Failed to import: /opt/airflow/dags/generarUsuarios.py
Traceback (most recent call last):
  File "/home/airflow/.local/lib/python3.8/site-packages/airflow/models/dagbag.py", line 344, in parse
    loader.exec_module(new_module)
  File "<frozen importlib._bootstrap_external>", line 843, in exec_module
  File "<frozen importlib._bootstrap>", line 219, in _call_with_frames_removed
  File "/opt/airflow/dags/generarUsuarios.py", line 18, in <module>
    'retry_delay': timedelta(minutes=1),
NameError: name 'timedelta' is not defined
[2024-03-04T12:10:10.510+0000] {processor.py:842} WARNING - No viable dags retrieved from /opt/airflow/dags/generarUsuarios.py
[2024-03-04T12:10:10.550+0000] {processor.py:183} INFO - Processing /opt/airflow/dags/generarUsuarios.py took 0.063 seconds
[2024-03-04T12:10:41.260+0000] {processor.py:161} INFO - Started process (PID=26538) to work on /opt/airflow/dags/generarUsuarios.py
[2024-03-04T12:10:41.263+0000] {processor.py:830} INFO - Processing file /opt/airflow/dags/generarUsuarios.py for tasks to queue
[2024-03-04T12:10:41.267+0000] {logging_mixin.py:188} INFO - [2024-03-04T12:10:41.267+0000] {dagbag.py:538} INFO - Filling up the DagBag from /opt/airflow/dags/generarUsuarios.py
[2024-03-04T12:10:41.274+0000] {logging_mixin.py:188} INFO - [2024-03-04T12:10:41.273+0000] {dagbag.py:348} ERROR - Failed to import: /opt/airflow/dags/generarUsuarios.py
Traceback (most recent call last):
  File "/home/airflow/.local/lib/python3.8/site-packages/airflow/models/dagbag.py", line 344, in parse
    loader.exec_module(new_module)
  File "<frozen importlib._bootstrap_external>", line 843, in exec_module
  File "<frozen importlib._bootstrap>", line 219, in _call_with_frames_removed
  File "/opt/airflow/dags/generarUsuarios.py", line 18, in <module>
    'retry_delay': timedelta(minutes=1),
NameError: name 'timedelta' is not defined
[2024-03-04T12:10:41.275+0000] {processor.py:842} WARNING - No viable dags retrieved from /opt/airflow/dags/generarUsuarios.py
[2024-03-04T12:10:41.311+0000] {processor.py:183} INFO - Processing /opt/airflow/dags/generarUsuarios.py took 0.058 seconds
[2024-03-04T12:11:11.845+0000] {processor.py:161} INFO - Started process (PID=26596) to work on /opt/airflow/dags/generarUsuarios.py
[2024-03-04T12:11:11.847+0000] {processor.py:830} INFO - Processing file /opt/airflow/dags/generarUsuarios.py for tasks to queue
[2024-03-04T12:11:11.851+0000] {logging_mixin.py:188} INFO - [2024-03-04T12:11:11.850+0000] {dagbag.py:538} INFO - Filling up the DagBag from /opt/airflow/dags/generarUsuarios.py
[2024-03-04T12:11:11.858+0000] {logging_mixin.py:188} INFO - [2024-03-04T12:11:11.856+0000] {dagbag.py:348} ERROR - Failed to import: /opt/airflow/dags/generarUsuarios.py
Traceback (most recent call last):
  File "/home/airflow/.local/lib/python3.8/site-packages/airflow/models/dagbag.py", line 344, in parse
    loader.exec_module(new_module)
  File "<frozen importlib._bootstrap_external>", line 843, in exec_module
  File "<frozen importlib._bootstrap>", line 219, in _call_with_frames_removed
  File "/opt/airflow/dags/generarUsuarios.py", line 18, in <module>
    'retry_delay': timedelta(minutes=1),
NameError: name 'timedelta' is not defined
[2024-03-04T12:11:11.859+0000] {processor.py:842} WARNING - No viable dags retrieved from /opt/airflow/dags/generarUsuarios.py
[2024-03-04T12:11:11.904+0000] {processor.py:183} INFO - Processing /opt/airflow/dags/generarUsuarios.py took 0.068 seconds
[2024-03-04T12:11:42.497+0000] {processor.py:161} INFO - Started process (PID=26655) to work on /opt/airflow/dags/generarUsuarios.py
[2024-03-04T12:11:42.507+0000] {processor.py:830} INFO - Processing file /opt/airflow/dags/generarUsuarios.py for tasks to queue
[2024-03-04T12:11:42.517+0000] {logging_mixin.py:188} INFO - [2024-03-04T12:11:42.516+0000] {dagbag.py:538} INFO - Filling up the DagBag from /opt/airflow/dags/generarUsuarios.py
[2024-03-04T12:11:42.525+0000] {logging_mixin.py:188} INFO - [2024-03-04T12:11:42.523+0000] {dagbag.py:348} ERROR - Failed to import: /opt/airflow/dags/generarUsuarios.py
Traceback (most recent call last):
  File "/home/airflow/.local/lib/python3.8/site-packages/airflow/models/dagbag.py", line 344, in parse
    loader.exec_module(new_module)
  File "<frozen importlib._bootstrap_external>", line 843, in exec_module
  File "<frozen importlib._bootstrap>", line 219, in _call_with_frames_removed
  File "/opt/airflow/dags/generarUsuarios.py", line 18, in <module>
    'retry_delay': timedelta(minutes=1),
NameError: name 'timedelta' is not defined
[2024-03-04T12:11:42.527+0000] {processor.py:842} WARNING - No viable dags retrieved from /opt/airflow/dags/generarUsuarios.py
[2024-03-04T12:11:42.625+0000] {processor.py:183} INFO - Processing /opt/airflow/dags/generarUsuarios.py took 0.151 seconds
[2024-03-04T12:12:13.054+0000] {processor.py:161} INFO - Started process (PID=26715) to work on /opt/airflow/dags/generarUsuarios.py
[2024-03-04T12:12:13.056+0000] {processor.py:830} INFO - Processing file /opt/airflow/dags/generarUsuarios.py for tasks to queue
[2024-03-04T12:12:13.059+0000] {logging_mixin.py:188} INFO - [2024-03-04T12:12:13.059+0000] {dagbag.py:538} INFO - Filling up the DagBag from /opt/airflow/dags/generarUsuarios.py
[2024-03-04T12:12:13.065+0000] {logging_mixin.py:188} INFO - [2024-03-04T12:12:13.063+0000] {dagbag.py:348} ERROR - Failed to import: /opt/airflow/dags/generarUsuarios.py
Traceback (most recent call last):
  File "/home/airflow/.local/lib/python3.8/site-packages/airflow/models/dagbag.py", line 344, in parse
    loader.exec_module(new_module)
  File "<frozen importlib._bootstrap_external>", line 843, in exec_module
  File "<frozen importlib._bootstrap>", line 219, in _call_with_frames_removed
  File "/opt/airflow/dags/generarUsuarios.py", line 18, in <module>
    'retry_delay': timedelta(minutes=1),
NameError: name 'timedelta' is not defined
[2024-03-04T12:12:13.065+0000] {processor.py:842} WARNING - No viable dags retrieved from /opt/airflow/dags/generarUsuarios.py
[2024-03-04T12:12:13.101+0000] {processor.py:183} INFO - Processing /opt/airflow/dags/generarUsuarios.py took 0.055 seconds
[2024-03-04T12:12:43.302+0000] {processor.py:161} INFO - Started process (PID=26774) to work on /opt/airflow/dags/generarUsuarios.py
[2024-03-04T12:12:43.318+0000] {processor.py:830} INFO - Processing file /opt/airflow/dags/generarUsuarios.py for tasks to queue
[2024-03-04T12:12:43.382+0000] {logging_mixin.py:188} INFO - [2024-03-04T12:12:43.380+0000] {dagbag.py:538} INFO - Filling up the DagBag from /opt/airflow/dags/generarUsuarios.py
[2024-03-04T12:12:43.427+0000] {logging_mixin.py:188} INFO - [2024-03-04T12:12:43.413+0000] {dagbag.py:348} ERROR - Failed to import: /opt/airflow/dags/generarUsuarios.py
Traceback (most recent call last):
  File "/home/airflow/.local/lib/python3.8/site-packages/airflow/models/dagbag.py", line 344, in parse
    loader.exec_module(new_module)
  File "<frozen importlib._bootstrap_external>", line 843, in exec_module
  File "<frozen importlib._bootstrap>", line 219, in _call_with_frames_removed
  File "/opt/airflow/dags/generarUsuarios.py", line 18, in <module>
    'retry_delay': timedelta(minutes=1),
NameError: name 'timedelta' is not defined
[2024-03-04T12:12:43.428+0000] {processor.py:842} WARNING - No viable dags retrieved from /opt/airflow/dags/generarUsuarios.py
[2024-03-04T12:12:43.594+0000] {processor.py:183} INFO - Processing /opt/airflow/dags/generarUsuarios.py took 0.354 seconds
[2024-03-04T12:13:14.452+0000] {processor.py:161} INFO - Started process (PID=26832) to work on /opt/airflow/dags/generarUsuarios.py
[2024-03-04T12:13:14.466+0000] {processor.py:830} INFO - Processing file /opt/airflow/dags/generarUsuarios.py for tasks to queue
[2024-03-04T12:13:14.471+0000] {logging_mixin.py:188} INFO - [2024-03-04T12:13:14.470+0000] {dagbag.py:538} INFO - Filling up the DagBag from /opt/airflow/dags/generarUsuarios.py
[2024-03-04T12:13:14.478+0000] {logging_mixin.py:188} INFO - [2024-03-04T12:13:14.476+0000] {dagbag.py:348} ERROR - Failed to import: /opt/airflow/dags/generarUsuarios.py
Traceback (most recent call last):
  File "/home/airflow/.local/lib/python3.8/site-packages/airflow/models/dagbag.py", line 344, in parse
    loader.exec_module(new_module)
  File "<frozen importlib._bootstrap_external>", line 843, in exec_module
  File "<frozen importlib._bootstrap>", line 219, in _call_with_frames_removed
  File "/opt/airflow/dags/generarUsuarios.py", line 18, in <module>
    'retry_delay': timedelta(minutes=1),
NameError: name 'timedelta' is not defined
[2024-03-04T12:13:14.479+0000] {processor.py:842} WARNING - No viable dags retrieved from /opt/airflow/dags/generarUsuarios.py
[2024-03-04T12:13:14.541+0000] {processor.py:183} INFO - Processing /opt/airflow/dags/generarUsuarios.py took 0.099 seconds
[2024-03-04T12:13:44.792+0000] {processor.py:161} INFO - Started process (PID=26897) to work on /opt/airflow/dags/generarUsuarios.py
[2024-03-04T12:13:44.795+0000] {processor.py:830} INFO - Processing file /opt/airflow/dags/generarUsuarios.py for tasks to queue
[2024-03-04T12:13:44.799+0000] {logging_mixin.py:188} INFO - [2024-03-04T12:13:44.798+0000] {dagbag.py:538} INFO - Filling up the DagBag from /opt/airflow/dags/generarUsuarios.py
[2024-03-04T12:13:44.806+0000] {logging_mixin.py:188} INFO - [2024-03-04T12:13:44.804+0000] {dagbag.py:348} ERROR - Failed to import: /opt/airflow/dags/generarUsuarios.py
Traceback (most recent call last):
  File "/home/airflow/.local/lib/python3.8/site-packages/airflow/models/dagbag.py", line 344, in parse
    loader.exec_module(new_module)
  File "<frozen importlib._bootstrap_external>", line 843, in exec_module
  File "<frozen importlib._bootstrap>", line 219, in _call_with_frames_removed
  File "/opt/airflow/dags/generarUsuarios.py", line 18, in <module>
    'retry_delay': timedelta(minutes=1),
NameError: name 'timedelta' is not defined
[2024-03-04T12:13:44.807+0000] {processor.py:842} WARNING - No viable dags retrieved from /opt/airflow/dags/generarUsuarios.py
[2024-03-04T12:13:44.845+0000] {processor.py:183} INFO - Processing /opt/airflow/dags/generarUsuarios.py took 0.060 seconds
[2024-03-04T12:14:15.080+0000] {processor.py:161} INFO - Started process (PID=26955) to work on /opt/airflow/dags/generarUsuarios.py
[2024-03-04T12:14:15.083+0000] {processor.py:830} INFO - Processing file /opt/airflow/dags/generarUsuarios.py for tasks to queue
[2024-03-04T12:14:15.086+0000] {logging_mixin.py:188} INFO - [2024-03-04T12:14:15.086+0000] {dagbag.py:538} INFO - Filling up the DagBag from /opt/airflow/dags/generarUsuarios.py
[2024-03-04T12:14:15.094+0000] {logging_mixin.py:188} INFO - [2024-03-04T12:14:15.092+0000] {dagbag.py:348} ERROR - Failed to import: /opt/airflow/dags/generarUsuarios.py
Traceback (most recent call last):
  File "/home/airflow/.local/lib/python3.8/site-packages/airflow/models/dagbag.py", line 344, in parse
    loader.exec_module(new_module)
  File "<frozen importlib._bootstrap_external>", line 843, in exec_module
  File "<frozen importlib._bootstrap>", line 219, in _call_with_frames_removed
  File "/opt/airflow/dags/generarUsuarios.py", line 18, in <module>
    'retry_delay': timedelta(minutes=1),
NameError: name 'timedelta' is not defined
[2024-03-04T12:14:15.095+0000] {processor.py:842} WARNING - No viable dags retrieved from /opt/airflow/dags/generarUsuarios.py
[2024-03-04T12:14:15.208+0000] {processor.py:183} INFO - Processing /opt/airflow/dags/generarUsuarios.py took 0.137 seconds
[2024-03-04T12:14:45.318+0000] {processor.py:161} INFO - Started process (PID=27014) to work on /opt/airflow/dags/generarUsuarios.py
[2024-03-04T12:14:45.321+0000] {processor.py:830} INFO - Processing file /opt/airflow/dags/generarUsuarios.py for tasks to queue
[2024-03-04T12:14:45.323+0000] {logging_mixin.py:188} INFO - [2024-03-04T12:14:45.322+0000] {dagbag.py:538} INFO - Filling up the DagBag from /opt/airflow/dags/generarUsuarios.py
[2024-03-04T12:14:45.331+0000] {logging_mixin.py:188} INFO - [2024-03-04T12:14:45.329+0000] {dagbag.py:348} ERROR - Failed to import: /opt/airflow/dags/generarUsuarios.py
Traceback (most recent call last):
  File "/home/airflow/.local/lib/python3.8/site-packages/airflow/models/dagbag.py", line 344, in parse
    loader.exec_module(new_module)
  File "<frozen importlib._bootstrap_external>", line 843, in exec_module
  File "<frozen importlib._bootstrap>", line 219, in _call_with_frames_removed
  File "/opt/airflow/dags/generarUsuarios.py", line 18, in <module>
    'retry_delay': timedelta(minutes=1),
NameError: name 'timedelta' is not defined
[2024-03-04T12:14:45.332+0000] {processor.py:842} WARNING - No viable dags retrieved from /opt/airflow/dags/generarUsuarios.py
[2024-03-04T12:14:45.434+0000] {processor.py:183} INFO - Processing /opt/airflow/dags/generarUsuarios.py took 0.125 seconds
[2024-03-04T12:15:15.866+0000] {processor.py:161} INFO - Started process (PID=27073) to work on /opt/airflow/dags/generarUsuarios.py
[2024-03-04T12:15:15.868+0000] {processor.py:830} INFO - Processing file /opt/airflow/dags/generarUsuarios.py for tasks to queue
[2024-03-04T12:15:15.871+0000] {logging_mixin.py:188} INFO - [2024-03-04T12:15:15.870+0000] {dagbag.py:538} INFO - Filling up the DagBag from /opt/airflow/dags/generarUsuarios.py
[2024-03-04T12:15:15.880+0000] {logging_mixin.py:188} INFO - [2024-03-04T12:15:15.876+0000] {dagbag.py:348} ERROR - Failed to import: /opt/airflow/dags/generarUsuarios.py
Traceback (most recent call last):
  File "/home/airflow/.local/lib/python3.8/site-packages/airflow/models/dagbag.py", line 344, in parse
    loader.exec_module(new_module)
  File "<frozen importlib._bootstrap_external>", line 843, in exec_module
  File "<frozen importlib._bootstrap>", line 219, in _call_with_frames_removed
  File "/opt/airflow/dags/generarUsuarios.py", line 18, in <module>
    'retry_delay': timedelta(minutes=1),
NameError: name 'timedelta' is not defined
[2024-03-04T12:15:15.881+0000] {processor.py:842} WARNING - No viable dags retrieved from /opt/airflow/dags/generarUsuarios.py
[2024-03-04T12:15:15.945+0000] {processor.py:183} INFO - Processing /opt/airflow/dags/generarUsuarios.py took 0.090 seconds
[2024-03-04T12:15:46.048+0000] {processor.py:161} INFO - Started process (PID=27129) to work on /opt/airflow/dags/generarUsuarios.py
[2024-03-04T12:15:46.062+0000] {processor.py:830} INFO - Processing file /opt/airflow/dags/generarUsuarios.py for tasks to queue
[2024-03-04T12:15:46.065+0000] {logging_mixin.py:188} INFO - [2024-03-04T12:15:46.063+0000] {dagbag.py:538} INFO - Filling up the DagBag from /opt/airflow/dags/generarUsuarios.py
[2024-03-04T12:15:46.085+0000] {logging_mixin.py:188} INFO - [2024-03-04T12:15:46.082+0000] {dagbag.py:348} ERROR - Failed to import: /opt/airflow/dags/generarUsuarios.py
Traceback (most recent call last):
  File "/home/airflow/.local/lib/python3.8/site-packages/airflow/models/dagbag.py", line 344, in parse
    loader.exec_module(new_module)
  File "<frozen importlib._bootstrap_external>", line 843, in exec_module
  File "<frozen importlib._bootstrap>", line 219, in _call_with_frames_removed
  File "/opt/airflow/dags/generarUsuarios.py", line 18, in <module>
    'retry_delay': timedelta(minutes=1),
NameError: name 'timedelta' is not defined
[2024-03-04T12:15:46.093+0000] {processor.py:842} WARNING - No viable dags retrieved from /opt/airflow/dags/generarUsuarios.py
[2024-03-04T12:15:46.186+0000] {processor.py:183} INFO - Processing /opt/airflow/dags/generarUsuarios.py took 0.147 seconds
[2024-03-04T12:16:16.991+0000] {processor.py:161} INFO - Started process (PID=27189) to work on /opt/airflow/dags/generarUsuarios.py
[2024-03-04T12:16:16.992+0000] {processor.py:830} INFO - Processing file /opt/airflow/dags/generarUsuarios.py for tasks to queue
[2024-03-04T12:16:16.994+0000] {logging_mixin.py:188} INFO - [2024-03-04T12:16:16.993+0000] {dagbag.py:538} INFO - Filling up the DagBag from /opt/airflow/dags/generarUsuarios.py
[2024-03-04T12:16:16.999+0000] {logging_mixin.py:188} INFO - [2024-03-04T12:16:16.998+0000] {dagbag.py:348} ERROR - Failed to import: /opt/airflow/dags/generarUsuarios.py
Traceback (most recent call last):
  File "/home/airflow/.local/lib/python3.8/site-packages/airflow/models/dagbag.py", line 344, in parse
    loader.exec_module(new_module)
  File "<frozen importlib._bootstrap_external>", line 843, in exec_module
  File "<frozen importlib._bootstrap>", line 219, in _call_with_frames_removed
  File "/opt/airflow/dags/generarUsuarios.py", line 18, in <module>
    'retry_delay': timedelta(minutes=1),
NameError: name 'timedelta' is not defined
[2024-03-04T12:16:17.000+0000] {processor.py:842} WARNING - No viable dags retrieved from /opt/airflow/dags/generarUsuarios.py
[2024-03-04T12:16:17.040+0000] {processor.py:183} INFO - Processing /opt/airflow/dags/generarUsuarios.py took 0.057 seconds
[2024-03-04T12:16:47.400+0000] {processor.py:161} INFO - Started process (PID=27244) to work on /opt/airflow/dags/generarUsuarios.py
[2024-03-04T12:16:47.409+0000] {processor.py:830} INFO - Processing file /opt/airflow/dags/generarUsuarios.py for tasks to queue
[2024-03-04T12:16:47.411+0000] {logging_mixin.py:188} INFO - [2024-03-04T12:16:47.410+0000] {dagbag.py:538} INFO - Filling up the DagBag from /opt/airflow/dags/generarUsuarios.py
[2024-03-04T12:16:47.427+0000] {logging_mixin.py:188} INFO - [2024-03-04T12:16:47.424+0000] {dagbag.py:348} ERROR - Failed to import: /opt/airflow/dags/generarUsuarios.py
Traceback (most recent call last):
  File "/home/airflow/.local/lib/python3.8/site-packages/airflow/models/dagbag.py", line 344, in parse
    loader.exec_module(new_module)
  File "<frozen importlib._bootstrap_external>", line 843, in exec_module
  File "<frozen importlib._bootstrap>", line 219, in _call_with_frames_removed
  File "/opt/airflow/dags/generarUsuarios.py", line 18, in <module>
    'retry_delay': timedelta(minutes=1),
NameError: name 'timedelta' is not defined
[2024-03-04T12:16:47.428+0000] {processor.py:842} WARNING - No viable dags retrieved from /opt/airflow/dags/generarUsuarios.py
[2024-03-04T12:16:47.497+0000] {processor.py:183} INFO - Processing /opt/airflow/dags/generarUsuarios.py took 0.111 seconds
[2024-03-04T12:17:17.793+0000] {processor.py:161} INFO - Started process (PID=27302) to work on /opt/airflow/dags/generarUsuarios.py
[2024-03-04T12:17:17.807+0000] {processor.py:830} INFO - Processing file /opt/airflow/dags/generarUsuarios.py for tasks to queue
[2024-03-04T12:17:17.809+0000] {logging_mixin.py:188} INFO - [2024-03-04T12:17:17.808+0000] {dagbag.py:538} INFO - Filling up the DagBag from /opt/airflow/dags/generarUsuarios.py
[2024-03-04T12:17:17.816+0000] {logging_mixin.py:188} INFO - [2024-03-04T12:17:17.814+0000] {dagbag.py:348} ERROR - Failed to import: /opt/airflow/dags/generarUsuarios.py
Traceback (most recent call last):
  File "/home/airflow/.local/lib/python3.8/site-packages/airflow/models/dagbag.py", line 344, in parse
    loader.exec_module(new_module)
  File "<frozen importlib._bootstrap_external>", line 843, in exec_module
  File "<frozen importlib._bootstrap>", line 219, in _call_with_frames_removed
  File "/opt/airflow/dags/generarUsuarios.py", line 18, in <module>
    'retry_delay': timedelta(minutes=1),
NameError: name 'timedelta' is not defined
[2024-03-04T12:17:17.817+0000] {processor.py:842} WARNING - No viable dags retrieved from /opt/airflow/dags/generarUsuarios.py
[2024-03-04T12:17:17.858+0000] {processor.py:183} INFO - Processing /opt/airflow/dags/generarUsuarios.py took 0.072 seconds
[2024-03-04T12:17:48.689+0000] {processor.py:161} INFO - Started process (PID=27360) to work on /opt/airflow/dags/generarUsuarios.py
[2024-03-04T12:17:48.694+0000] {processor.py:830} INFO - Processing file /opt/airflow/dags/generarUsuarios.py for tasks to queue
[2024-03-04T12:17:48.698+0000] {logging_mixin.py:188} INFO - [2024-03-04T12:17:48.697+0000] {dagbag.py:538} INFO - Filling up the DagBag from /opt/airflow/dags/generarUsuarios.py
[2024-03-04T12:17:48.709+0000] {logging_mixin.py:188} INFO - [2024-03-04T12:17:48.705+0000] {dagbag.py:348} ERROR - Failed to import: /opt/airflow/dags/generarUsuarios.py
Traceback (most recent call last):
  File "/home/airflow/.local/lib/python3.8/site-packages/airflow/models/dagbag.py", line 344, in parse
    loader.exec_module(new_module)
  File "<frozen importlib._bootstrap_external>", line 843, in exec_module
  File "<frozen importlib._bootstrap>", line 219, in _call_with_frames_removed
  File "/opt/airflow/dags/generarUsuarios.py", line 18, in <module>
    'retry_delay': timedelta(minutes=1),
NameError: name 'timedelta' is not defined
[2024-03-04T12:17:48.710+0000] {processor.py:842} WARNING - No viable dags retrieved from /opt/airflow/dags/generarUsuarios.py
[2024-03-04T12:17:48.763+0000] {processor.py:183} INFO - Processing /opt/airflow/dags/generarUsuarios.py took 0.085 seconds
[2024-03-04T12:18:18.855+0000] {processor.py:161} INFO - Started process (PID=27419) to work on /opt/airflow/dags/generarUsuarios.py
[2024-03-04T12:18:18.858+0000] {processor.py:830} INFO - Processing file /opt/airflow/dags/generarUsuarios.py for tasks to queue
[2024-03-04T12:18:18.860+0000] {logging_mixin.py:188} INFO - [2024-03-04T12:18:18.859+0000] {dagbag.py:538} INFO - Filling up the DagBag from /opt/airflow/dags/generarUsuarios.py
[2024-03-04T12:18:18.868+0000] {logging_mixin.py:188} INFO - [2024-03-04T12:18:18.865+0000] {dagbag.py:348} ERROR - Failed to import: /opt/airflow/dags/generarUsuarios.py
Traceback (most recent call last):
  File "/home/airflow/.local/lib/python3.8/site-packages/airflow/models/dagbag.py", line 344, in parse
    loader.exec_module(new_module)
  File "<frozen importlib._bootstrap_external>", line 843, in exec_module
  File "<frozen importlib._bootstrap>", line 219, in _call_with_frames_removed
  File "/opt/airflow/dags/generarUsuarios.py", line 18, in <module>
    'retry_delay': timedelta(minutes=1),
NameError: name 'timedelta' is not defined
[2024-03-04T12:18:18.869+0000] {processor.py:842} WARNING - No viable dags retrieved from /opt/airflow/dags/generarUsuarios.py
[2024-03-04T12:18:18.997+0000] {processor.py:183} INFO - Processing /opt/airflow/dags/generarUsuarios.py took 0.153 seconds
[2024-03-04T12:18:49.413+0000] {processor.py:161} INFO - Started process (PID=27474) to work on /opt/airflow/dags/generarUsuarios.py
[2024-03-04T12:18:49.418+0000] {processor.py:830} INFO - Processing file /opt/airflow/dags/generarUsuarios.py for tasks to queue
[2024-03-04T12:18:49.420+0000] {logging_mixin.py:188} INFO - [2024-03-04T12:18:49.420+0000] {dagbag.py:538} INFO - Filling up the DagBag from /opt/airflow/dags/generarUsuarios.py
[2024-03-04T12:18:49.427+0000] {logging_mixin.py:188} INFO - [2024-03-04T12:18:49.424+0000] {dagbag.py:348} ERROR - Failed to import: /opt/airflow/dags/generarUsuarios.py
Traceback (most recent call last):
  File "/home/airflow/.local/lib/python3.8/site-packages/airflow/models/dagbag.py", line 344, in parse
    loader.exec_module(new_module)
  File "<frozen importlib._bootstrap_external>", line 843, in exec_module
  File "<frozen importlib._bootstrap>", line 219, in _call_with_frames_removed
  File "/opt/airflow/dags/generarUsuarios.py", line 18, in <module>
    'retry_delay': timedelta(minutes=1),
NameError: name 'timedelta' is not defined
[2024-03-04T12:18:49.428+0000] {processor.py:842} WARNING - No viable dags retrieved from /opt/airflow/dags/generarUsuarios.py
[2024-03-04T12:18:49.474+0000] {processor.py:183} INFO - Processing /opt/airflow/dags/generarUsuarios.py took 0.077 seconds
[2024-03-04T12:19:19.661+0000] {processor.py:161} INFO - Started process (PID=27533) to work on /opt/airflow/dags/generarUsuarios.py
[2024-03-04T12:19:19.663+0000] {processor.py:830} INFO - Processing file /opt/airflow/dags/generarUsuarios.py for tasks to queue
[2024-03-04T12:19:19.665+0000] {logging_mixin.py:188} INFO - [2024-03-04T12:19:19.665+0000] {dagbag.py:538} INFO - Filling up the DagBag from /opt/airflow/dags/generarUsuarios.py
[2024-03-04T12:19:19.674+0000] {logging_mixin.py:188} INFO - [2024-03-04T12:19:19.671+0000] {dagbag.py:348} ERROR - Failed to import: /opt/airflow/dags/generarUsuarios.py
Traceback (most recent call last):
  File "/home/airflow/.local/lib/python3.8/site-packages/airflow/models/dagbag.py", line 344, in parse
    loader.exec_module(new_module)
  File "<frozen importlib._bootstrap_external>", line 843, in exec_module
  File "<frozen importlib._bootstrap>", line 219, in _call_with_frames_removed
  File "/opt/airflow/dags/generarUsuarios.py", line 18, in <module>
    'retry_delay': timedelta(minutes=1),
NameError: name 'timedelta' is not defined
[2024-03-04T12:19:19.675+0000] {processor.py:842} WARNING - No viable dags retrieved from /opt/airflow/dags/generarUsuarios.py
[2024-03-04T12:19:19.761+0000] {processor.py:183} INFO - Processing /opt/airflow/dags/generarUsuarios.py took 0.114 seconds
[2024-03-04T12:19:49.903+0000] {processor.py:161} INFO - Started process (PID=27589) to work on /opt/airflow/dags/generarUsuarios.py
[2024-03-04T12:19:49.909+0000] {processor.py:830} INFO - Processing file /opt/airflow/dags/generarUsuarios.py for tasks to queue
[2024-03-04T12:19:49.911+0000] {logging_mixin.py:188} INFO - [2024-03-04T12:19:49.911+0000] {dagbag.py:538} INFO - Filling up the DagBag from /opt/airflow/dags/generarUsuarios.py
[2024-03-04T12:19:49.923+0000] {logging_mixin.py:188} INFO - [2024-03-04T12:19:49.919+0000] {dagbag.py:348} ERROR - Failed to import: /opt/airflow/dags/generarUsuarios.py
Traceback (most recent call last):
  File "/home/airflow/.local/lib/python3.8/site-packages/airflow/models/dagbag.py", line 344, in parse
    loader.exec_module(new_module)
  File "<frozen importlib._bootstrap_external>", line 843, in exec_module
  File "<frozen importlib._bootstrap>", line 219, in _call_with_frames_removed
  File "/opt/airflow/dags/generarUsuarios.py", line 18, in <module>
    'retry_delay': timedelta(minutes=1),
NameError: name 'timedelta' is not defined
[2024-03-04T12:19:49.923+0000] {processor.py:842} WARNING - No viable dags retrieved from /opt/airflow/dags/generarUsuarios.py
[2024-03-04T12:19:49.967+0000] {processor.py:183} INFO - Processing /opt/airflow/dags/generarUsuarios.py took 0.072 seconds
[2024-03-04T12:20:20.608+0000] {processor.py:161} INFO - Started process (PID=27648) to work on /opt/airflow/dags/generarUsuarios.py
[2024-03-04T12:20:20.611+0000] {processor.py:830} INFO - Processing file /opt/airflow/dags/generarUsuarios.py for tasks to queue
[2024-03-04T12:20:20.614+0000] {logging_mixin.py:188} INFO - [2024-03-04T12:20:20.613+0000] {dagbag.py:538} INFO - Filling up the DagBag from /opt/airflow/dags/generarUsuarios.py
[2024-03-04T12:20:20.626+0000] {logging_mixin.py:188} INFO - [2024-03-04T12:20:20.624+0000] {dagbag.py:348} ERROR - Failed to import: /opt/airflow/dags/generarUsuarios.py
Traceback (most recent call last):
  File "/home/airflow/.local/lib/python3.8/site-packages/airflow/models/dagbag.py", line 344, in parse
    loader.exec_module(new_module)
  File "<frozen importlib._bootstrap_external>", line 843, in exec_module
  File "<frozen importlib._bootstrap>", line 219, in _call_with_frames_removed
  File "/opt/airflow/dags/generarUsuarios.py", line 18, in <module>
    'retry_delay': timedelta(minutes=1),
NameError: name 'timedelta' is not defined
[2024-03-04T12:20:20.627+0000] {processor.py:842} WARNING - No viable dags retrieved from /opt/airflow/dags/generarUsuarios.py
[2024-03-04T12:20:20.714+0000] {processor.py:183} INFO - Processing /opt/airflow/dags/generarUsuarios.py took 0.118 seconds
[2024-03-04T12:20:51.346+0000] {processor.py:161} INFO - Started process (PID=27705) to work on /opt/airflow/dags/generarUsuarios.py
[2024-03-04T12:20:51.348+0000] {processor.py:830} INFO - Processing file /opt/airflow/dags/generarUsuarios.py for tasks to queue
[2024-03-04T12:20:51.353+0000] {logging_mixin.py:188} INFO - [2024-03-04T12:20:51.352+0000] {dagbag.py:538} INFO - Filling up the DagBag from /opt/airflow/dags/generarUsuarios.py
[2024-03-04T12:20:51.362+0000] {logging_mixin.py:188} INFO - [2024-03-04T12:20:51.360+0000] {dagbag.py:348} ERROR - Failed to import: /opt/airflow/dags/generarUsuarios.py
Traceback (most recent call last):
  File "/home/airflow/.local/lib/python3.8/site-packages/airflow/models/dagbag.py", line 344, in parse
    loader.exec_module(new_module)
  File "<frozen importlib._bootstrap_external>", line 843, in exec_module
  File "<frozen importlib._bootstrap>", line 219, in _call_with_frames_removed
  File "/opt/airflow/dags/generarUsuarios.py", line 18, in <module>
    'retry_delay': timedelta(minutes=1),
NameError: name 'timedelta' is not defined
[2024-03-04T12:20:51.363+0000] {processor.py:842} WARNING - No viable dags retrieved from /opt/airflow/dags/generarUsuarios.py
[2024-03-04T12:20:51.419+0000] {processor.py:183} INFO - Processing /opt/airflow/dags/generarUsuarios.py took 0.087 seconds
[2024-03-04T12:21:21.628+0000] {processor.py:161} INFO - Started process (PID=27763) to work on /opt/airflow/dags/generarUsuarios.py
[2024-03-04T12:21:21.631+0000] {processor.py:830} INFO - Processing file /opt/airflow/dags/generarUsuarios.py for tasks to queue
[2024-03-04T12:21:21.634+0000] {logging_mixin.py:188} INFO - [2024-03-04T12:21:21.633+0000] {dagbag.py:538} INFO - Filling up the DagBag from /opt/airflow/dags/generarUsuarios.py
[2024-03-04T12:21:21.643+0000] {logging_mixin.py:188} INFO - [2024-03-04T12:21:21.640+0000] {dagbag.py:348} ERROR - Failed to import: /opt/airflow/dags/generarUsuarios.py
Traceback (most recent call last):
  File "/home/airflow/.local/lib/python3.8/site-packages/airflow/models/dagbag.py", line 344, in parse
    loader.exec_module(new_module)
  File "<frozen importlib._bootstrap_external>", line 843, in exec_module
  File "<frozen importlib._bootstrap>", line 219, in _call_with_frames_removed
  File "/opt/airflow/dags/generarUsuarios.py", line 18, in <module>
    'retry_delay': timedelta(minutes=1),
NameError: name 'timedelta' is not defined
[2024-03-04T12:21:21.645+0000] {processor.py:842} WARNING - No viable dags retrieved from /opt/airflow/dags/generarUsuarios.py
[2024-03-04T12:21:21.717+0000] {processor.py:183} INFO - Processing /opt/airflow/dags/generarUsuarios.py took 0.100 seconds
[2024-03-04T12:21:52.558+0000] {processor.py:161} INFO - Started process (PID=27820) to work on /opt/airflow/dags/generarUsuarios.py
[2024-03-04T12:21:52.561+0000] {processor.py:830} INFO - Processing file /opt/airflow/dags/generarUsuarios.py for tasks to queue
[2024-03-04T12:21:52.564+0000] {logging_mixin.py:188} INFO - [2024-03-04T12:21:52.563+0000] {dagbag.py:538} INFO - Filling up the DagBag from /opt/airflow/dags/generarUsuarios.py
[2024-03-04T12:21:52.581+0000] {logging_mixin.py:188} INFO - [2024-03-04T12:21:52.579+0000] {dagbag.py:348} ERROR - Failed to import: /opt/airflow/dags/generarUsuarios.py
Traceback (most recent call last):
  File "/home/airflow/.local/lib/python3.8/site-packages/airflow/models/dagbag.py", line 344, in parse
    loader.exec_module(new_module)
  File "<frozen importlib._bootstrap_external>", line 843, in exec_module
  File "<frozen importlib._bootstrap>", line 219, in _call_with_frames_removed
  File "/opt/airflow/dags/generarUsuarios.py", line 18, in <module>
    'retry_delay': timedelta(minutes=1),
NameError: name 'timedelta' is not defined
[2024-03-04T12:21:52.582+0000] {processor.py:842} WARNING - No viable dags retrieved from /opt/airflow/dags/generarUsuarios.py
[2024-03-04T12:21:52.709+0000] {processor.py:183} INFO - Processing /opt/airflow/dags/generarUsuarios.py took 0.166 seconds
[2024-03-04T12:22:23.298+0000] {processor.py:161} INFO - Started process (PID=27878) to work on /opt/airflow/dags/generarUsuarios.py
[2024-03-04T12:22:23.300+0000] {processor.py:830} INFO - Processing file /opt/airflow/dags/generarUsuarios.py for tasks to queue
[2024-03-04T12:22:23.303+0000] {logging_mixin.py:188} INFO - [2024-03-04T12:22:23.302+0000] {dagbag.py:538} INFO - Filling up the DagBag from /opt/airflow/dags/generarUsuarios.py
[2024-03-04T12:22:23.309+0000] {logging_mixin.py:188} INFO - [2024-03-04T12:22:23.308+0000] {dagbag.py:348} ERROR - Failed to import: /opt/airflow/dags/generarUsuarios.py
Traceback (most recent call last):
  File "/home/airflow/.local/lib/python3.8/site-packages/airflow/models/dagbag.py", line 344, in parse
    loader.exec_module(new_module)
  File "<frozen importlib._bootstrap_external>", line 843, in exec_module
  File "<frozen importlib._bootstrap>", line 219, in _call_with_frames_removed
  File "/opt/airflow/dags/generarUsuarios.py", line 18, in <module>
    'retry_delay': timedelta(minutes=1),
NameError: name 'timedelta' is not defined
[2024-03-04T12:22:23.310+0000] {processor.py:842} WARNING - No viable dags retrieved from /opt/airflow/dags/generarUsuarios.py
[2024-03-04T12:22:23.350+0000] {processor.py:183} INFO - Processing /opt/airflow/dags/generarUsuarios.py took 0.060 seconds
[2024-03-04T12:22:53.954+0000] {processor.py:161} INFO - Started process (PID=27937) to work on /opt/airflow/dags/generarUsuarios.py
[2024-03-04T12:22:53.956+0000] {processor.py:830} INFO - Processing file /opt/airflow/dags/generarUsuarios.py for tasks to queue
[2024-03-04T12:22:53.971+0000] {logging_mixin.py:188} INFO - [2024-03-04T12:22:53.970+0000] {dagbag.py:538} INFO - Filling up the DagBag from /opt/airflow/dags/generarUsuarios.py
[2024-03-04T12:22:54.004+0000] {logging_mixin.py:188} INFO - [2024-03-04T12:22:53.990+0000] {dagbag.py:348} ERROR - Failed to import: /opt/airflow/dags/generarUsuarios.py
Traceback (most recent call last):
  File "/home/airflow/.local/lib/python3.8/site-packages/airflow/models/dagbag.py", line 344, in parse
    loader.exec_module(new_module)
  File "<frozen importlib._bootstrap_external>", line 843, in exec_module
  File "<frozen importlib._bootstrap>", line 219, in _call_with_frames_removed
  File "/opt/airflow/dags/generarUsuarios.py", line 18, in <module>
    'retry_delay': timedelta(minutes=1),
NameError: name 'timedelta' is not defined
[2024-03-04T12:22:54.005+0000] {processor.py:842} WARNING - No viable dags retrieved from /opt/airflow/dags/generarUsuarios.py
[2024-03-04T12:22:54.157+0000] {processor.py:183} INFO - Processing /opt/airflow/dags/generarUsuarios.py took 0.235 seconds
